Workbook
Name Absorbed: #REF!
Name Absorbed: #REF!
Name Approx_RI: #REF!
Name Approx_RI: #REF!
Name AR_: #REF!
Name AR_: #REF!
Name AreaF1: #REF!
Name AreaF2: #REF!
Name B: #REF!
Name Bond_R: #REF!
Name c_: #REF!
Name Calculated_thickness_µm: #REF!
Name CB: #REF!
Name Chemicals: [1]!Tabla1[#Data]
Name Chemicals: Tabla1[]
Name Chi: #REF!
Name CK: #REF!
Name CR: #REF!
Name d: #REF!
Name dD: 'HSP 2 Spheres'!$C$3
Name dD: 'HSP Solvent Blends and Chi'!$C$3
Name dD: 'HSP 1 Sphere'!$C$3
Name Deflection: #REF!
Name Density: #REF!
Name dH: 'HSP 2 Spheres'!$E$3
Name dH: 'HSP Solvent Blends and Chi'!$E$3
Name dH: 'HSP 1 Sphere'!$E$3
Name Distance: '[1]HSP Solvent Blends and Chi'!$R$20
Name Distance: 'HSP Solvent Blends and Chi'!$R$20
Name divStep: #REF!
Name DLVODensity: #REF!
Name dMax: #REF!
Name dMin: #REF!
Name dP: 'HSP 2 Spheres'!$D$3
Name dP: 'HSP Solvent Blends and Chi'!$D$3
Name dP: 'HSP 1 Sphere'!$D$3
Name e: #REF!
Name e0: #REF!
Name Ea: #REF!
Name Failure_Value: #REF!
Name FCa: #REF!
Name FDensity: #REF!
Name FGravity: #REF!
Name firstLabel: #REF!
Name firstZ: #REF!
Name FRadius: #REF!
Name FSurften: #REF!
Name fThick: #REF!
Name FudgeFactor: #REF!
Name FVelocity: #REF!
Name FViscosity: #REF!
Name g: #REF!
Name Gravity: #REF!
Name h: #REF!
Name h0: #REF!
Name Hamaker: #REF!
Name Hardness: #REF!
Name HHardness: #REF!
Name Higher_wavelength: #REF!
Name HModulus: #REF!

Sheet HSP Calcs
B2: These two workbooks are provided by www.hansen-solubility.com as a convenient introduction to some of the basic HSP methods
B4: They are Copyright © 2013 Prof Steven Abbott
B6: If you find bugs/issues or would like extra functionality, please email Steven Abbott
B7: steven@stevenabbott.co.uk

Sheet Chemicals
A1: CAS | B1: Chemical | C1: dD | D1: dP | E1: dH | F1: Vmol | G1: Distance | H1: Radius | L1: Solvents | M1: dD | N1: dP | O1: dH | P1: MVol
A2: 630-20-6 | B2: 1,1,1,2-Tetrachloroethane | C2: 18 | D2: 4.4 | E2: 4.2 | F2: =IFERROR(VLOOKUP(B2,Tabla2[],5,FALSE),"") | G2: =SQRT(4*(Tabla1[[#This Row],[dD]]-'Find a similar substance'!$D$5)^2+('Find a similar substance'!$E$5-Tabla1[[#This Row],[dP]])^2+(Tabla1[[#This Row],[dH]]-'Find a similar substance'!$F$5)^2) -> 5.1932649 | L2: Acetone | M2: 15.5 | N2: 10.4 | O2: 7 | P2: 73.8
A3: 71-55-6 | B3: 1,1,1-Trichloroethane | C3: 16.8 | D3: 4.3 | E3: 2 | F3: =IFERROR(VLOOKUP(B3,Tabla2[],5,FALSE),"") | G3: =SQRT(4*(Tabla1[[#This Row],[dD]]-'Find a similar substance'!$D$5)^2+('Find a similar substance'!$E$5-Tabla1[[#This Row],[dP]])^2+(Tabla1[[#This Row],[dH]]-'Find a similar substance'!$F$5)^2) -> 5.340412 | L3: Acetonitrile | M3: 15.3 | N3: 18 | O3: 6.1 | P3: 52.9
A4: 420-46-2 | B4: 1,1,1-Trifluoroethane | C4: 14.6 | D4: 10 | E4: 0 | F4: =IFERROR(VLOOKUP(B4,Tabla2[],5,FALSE),"") | G4: =SQRT(4*(Tabla1[[#This Row],[dD]]-'Find a similar substance'!$D$5)^2+('Find a similar substance'!$E$5-Tabla1[[#This Row],[dP]])^2+(Tabla1[[#This Row],[dH]]-'Find a similar substance'!$F$5)^2) -> 6.5337585 | L4: n-Amyl Acetate | M4: 15.8 | N4: 3.3 | O4: 6.1 | P4: 148
A5: 79-27-6 | B5: 1,1,2,2-Tetrabromoethane | C5: 21 | D5: 7 | E5: 8.2 | F5: =IFERROR(VLOOKUP(B5,Tabla2[],5,FALSE),"") | G5: =SQRT(4*(Tabla1[[#This Row],[dD]]-'Find a similar substance'!$D$5)^2+('Find a similar substance'!$E$5-Tabla1[[#This Row],[dP]])^2+(Tabla1[[#This Row],[dH]]-'Find a similar substance'!$F$5)^2) -> 9.5168272 | L5: n-Amyl Alcohol | M5: 15.9 | N5: 5.9 | O5: 13.9 | P5: 108.6
A6: 79-34-5 | B6: 1,1,2,2-Tetrachloroethane | C6: 18.8 | D6: 5.1 | E6: 5.3 | F6: =IFERROR(VLOOKUP(B6,Tabla2[],5,FALSE),"") | G6: =SQRT(4*(Tabla1[[#This Row],[dD]]-'Find a similar substance'!$D$5)^2+('Find a similar substance'!$E$5-Tabla1[[#This Row],[dP]])^2+(Tabla1[[#This Row],[dH]]-'Find a similar substance'!$F$5)^2) -> 5.6929781 | L6: Benzene | M6: 18.4 | N6: 0 | O6: 2 | P6: 52.9
A7: 13116-60-4 | B7: 1,1,2,2-Tetrachloropropane | C7: 17.9 | D7: 6.7 | E7: 3.3 | F7: =IFERROR(VLOOKUP(B7,Tabla2[],5,FALSE),"") | G7: =SQRT(4*(Tabla1[[#This Row],[dD]]-'Find a similar substance'!$D$5)^2+('Find a similar substance'!$E$5-Tabla1[[#This Row],[dP]])^2+(Tabla1[[#This Row],[dH]]-'Find a similar substance'!$F$5)^2) -> 3.6945906 | L7: Benzyl Alcohol | M7: 18.4 | N7: 6.3 | O7: 13.7 | P7: 103.8
A8: 598-16-3 | B8: 1,1,2-Tribromo Ethylene | C8: 18.3 | D8: 9.4 | E8: 8 | F8: =IFERROR(VLOOKUP(B8,Tabla2[],5,FALSE),"") | G8: =SQRT(4*(Tabla1[[#This Row],[dD]]-'Find a similar substance'!$D$5)^2+('Find a similar substance'!$E$5-Tabla1[[#This Row],[dP]])^2+(Tabla1[[#This Row],[dH]]-'Find a similar substance'!$F$5)^2) -> 4.5880279 | L8: Benzyl Benzoate | M8: 20 | N8: 5.1 | O8: 5.2 | P8: 190.3
A9: 21400-25-9 | B9: 1,1,2-Trichloro Propene | C9: 17.7 | D9: 15.7 | E9: 3.4 | F9: =IFERROR(VLOOKUP(B9,Tabla2[],5,FALSE),"") | G9: =SQRT(4*(Tabla1[[#This Row],[dD]]-'Find a similar substance'!$D$5)^2+('Find a similar substance'!$E$5-Tabla1[[#This Row],[dP]])^2+(Tabla1[[#This Row],[dH]]-'Find a similar substance'!$F$5)^2) -> 7.5099933 | L9: 1-Butanol | M9: 16 | N9: 5.7 | O9: 15.8 | P9: 92
A10: 79-00-5 | B10: 1,1,2-Trichloroethane | C10: 18.2 | D10: 5.3 | E10: 6.8 | F10: =IFERROR(VLOOKUP(B10,Tabla2[],5,FALSE),"") | G10: =SQRT(4*(Tabla1[[#This Row],[dD]]-'Find a similar substance'!$D$5)^2+('Find a similar substance'!$E$5-Tabla1[[#This Row],[dP]])^2+(Tabla1[[#This Row],[dH]]-'Find a similar substance'!$F$5)^2) -> 5.0039984 | L10: 2-Butanol | M10: 15.8 | N10: 5.7 | O10: 14.5 | P10: 92
A11: 76-13-1 | B11: 1,1,2-Trichlorotrifluoroethane (Freon113) | C11: 14.7 | D11: 1.6 | E11: 0 | F11: =IFERROR(VLOOKUP(B11,Tabla2[],5,FALSE),"") | G11: =SQRT(4*(Tabla1[[#This Row],[dD]]-'Find a similar substance'!$D$5)^2+('Find a similar substance'!$E$5-Tabla1[[#This Row],[dP]])^2+(Tabla1[[#This Row],[dH]]-'Find a similar substance'!$F$5)^2) -> 9.478924 | L11: n-Butyl Acetate | M11: 15.8 | N11: 3.7 | O11: 6.3 | P11: 132.6
A12: 102-52-3 | B12: 1,1,3,3-Tetramethoxypropane | C12: 15 | D12: 7.1 | E12: 6.8 | F12: =IFERROR(VLOOKUP(B12,Tabla2[],5,FALSE),"") | G12: =SQRT(4*(Tabla1[[#This Row],[dD]]-'Find a similar substance'!$D$5)^2+('Find a similar substance'!$E$5-Tabla1[[#This Row],[dP]])^2+(Tabla1[[#This Row],[dH]]-'Find a similar substance'!$F$5)^2) -> 4.0049969 | L12: t-Butyl Acetate | M12: 15 | N12: 3.7 | O12: 6 | P12: 134.8
A13: 20682-69-3 | B13: 1,1-Diallyloxyethane | C13: 15.4 | D13: 5.1 | E13: 4.8 | F13: =IFERROR(VLOOKUP(B13,Tabla2[],5,FALSE),"") | G13: =SQRT(4*(Tabla1[[#This Row],[dD]]-'Find a similar substance'!$D$5)^2+('Find a similar substance'!$E$5-Tabla1[[#This Row],[dP]])^2+(Tabla1[[#This Row],[dH]]-'Find a similar substance'!$F$5)^2) -> 4.3312816 | L13: t-Butyl Alcohol | M13: 15.2 | N13: 5.1 | O13: 14.7 | P13: 96
... A36: 590-19-2 | B36: 1,2-Butadiene | C36: 15 | D36: 1.7 | E36: 6.2 | F36: =IFERROR(VLOOKUP(B36,Tabla2[],5,FALSE),"") | G36: =SQRT(4*(Tabla1[[#This Row],[dD]]-'Find a similar substance'!$D$5)^2+('Find a similar substance'!$E$5-Tabla1[[#This Row],[dP]])^2+(Tabla1[[#This Row],[dH]]-'Find a similar substance'!$F$5)^2) -> 7.7897368 | L36: Ethyl Acetate | M36: 15.8 | N36: 5.3 | O36: 7.2 | P36: 98.6
A37: 408590 | B37: 1,2-Chlorobromoethylene | C37: 17.2 | D37: 6.6 | E37: 2.3 | F37: =IFERROR(VLOOKUP(B37,Tabla2[],5,FALSE),"") | G37: =SQRT(4*(Tabla1[[#This Row],[dD]]-'Find a similar substance'!$D$5)^2+('Find a similar substance'!$E$5-Tabla1[[#This Row],[dP]])^2+(Tabla1[[#This Row],[dH]]-'Find a similar substance'!$F$5)^2) -> 3.6249138 | L37: Ethyl Benzene | M37: 17.8 | N37: 0.6 | O37: 1.4 | P37: 122.8
A38: 931-17-9 | B38: 1,2-Cyclohexanediol | C38: 17.4 | D38: 9.8 | E38: 18.3 | F38: =IFERROR(VLOOKUP(B38,Tabla2[],5,FALSE),"") | G38: =SQRT(4*(Tabla1[[#This Row],[dD]]-'Find a similar substance'!$D$5)^2+('Find a similar substance'!$E$5-Tabla1[[#This Row],[dP]])^2+(Tabla1[[#This Row],[dH]]-'Find a similar substance'!$F$5)^2) -> 13.440982 | L38: Ethyl Lactate | M38: 16 | N38: 7.6 | O38: 12.5 | P38: 115
A39: 765-87-7 | B39: 1,2-Cyclohexanedione | C39: 18.6 | D39: 10.3 | E39: 8 | F39: =IFERROR(VLOOKUP(B39,Tabla2[],5,FALSE),"") | G39: =SQRT(4*(Tabla1[[#This Row],[dD]]-'Find a similar substance'!$D$5)^2+('Find a similar substance'!$E$5-Tabla1[[#This Row],[dP]])^2+(Tabla1[[#This Row],[dH]]-'Find a similar substance'!$F$5)^2) -> 5.2497619 | L39: Ethylene Carbonate | M39: 18 | N39: 21.7 | O39: 5.1 | P39: 66
A40: 540-49-8 | B40: 1,2-Dibromoethylene | C40: 17 | D40: 4.9 | E40: 3 | F40: =IFERROR(VLOOKUP(B40,Tabla2[],5,FALSE),"") | G40: =SQRT(4*(Tabla1[[#This Row],[dD]]-'Find a similar substance'!$D$5)^2+('Find a similar substance'!$E$5-Tabla1[[#This Row],[dP]])^2+(Tabla1[[#This Row],[dH]]-'Find a similar substance'!$F$5)^2) -> 4.3680659 | L40: Ethylene Glycol | M40: 17 | N40: 11 | O40: 26 | P40: 55.9
A41: 156-59-2 | B41: 1,2-Dichloroethylene (Cis) | C41: 17 | D41: 8 | E41: 3.2 | F41: =IFERROR(VLOOKUP(B41,Tabla2[],5,FALSE),"") | G41: =SQRT(4*(Tabla1[[#This Row],[dD]]-'Find a similar substance'!$D$5)^2+('Find a similar substance'!$E$5-Tabla1[[#This Row],[dP]])^2+(Tabla1[[#This Row],[dH]]-'Find a similar substance'!$F$5)^2) -> 2.0904545 | L41: Ethylene Glycol Monobutyl Ether | M41: 16 | N41: 5.1 | O41: 12.3 | P41: 132
A42: 78-87-5 | B42: 1,2-Dichloropropane | C42: 17.3 | D42: 7.1 | E42: 2.9 | F42: =IFERROR(VLOOKUP(B42,Tabla2[],5,FALSE),"") | G42: =SQRT(4*(Tabla1[[#This Row],[dD]]-'Find a similar substance'!$D$5)^2+('Find a similar substance'!$E$5-Tabla1[[#This Row],[dP]])^2+(Tabla1[[#This Row],[dH]]-'Find a similar substance'!$F$5)^2) -> 2.9883106 | L42: Ethylene Glycol Monomethyl Ether | M42: 16 | N42: 8.2 | O42: 15 | P42: 79.3
A43: 6923-20-2 | B43: 1,2-Dichloropropene (Cis) | C43: 17 | D43: 8.5 | E43: 2.9 | F43: =IFERROR(VLOOKUP(B43,Tabla2[],5,FALSE),"") | G43: =SQRT(4*(Tabla1[[#This Row],[dD]]-'Find a similar substance'!$D$5)^2+('Find a similar substance'!$E$5-Tabla1[[#This Row],[dP]])^2+(Tabla1[[#This Row],[dH]]-'Find a similar substance'!$F$5)^2) -> 2.2561028 | L43: gamma-Butyrolactone (GBL) | M43: 18 | N43: 16.6 | O43: 7.4 | P43: 76.5
A44: 76-14-2 | B44: 1,2-Dichlorotetrafluoroethane (Freon 114) | C44: 12.6 | D44: 1.8 | E44: 0 | F44: =IFERROR(VLOOKUP(B44,Tabla2[],5,FALSE),"") | G44: =SQRT(4*(Tabla1[[#This Row],[dD]]-'Find a similar substance'!$D$5)^2+('Find a similar substance'!$E$5-Tabla1[[#This Row],[dP]])^2+(Tabla1[[#This Row],[dH]]-'Find a similar substance'!$F$5)^2) -> 11.688028 | L44: Glycerol Carbonate | M44: 17.9 | N44: 25.5 | O44: 17.4 | P44: 83.2
A45: 42345-82-4 | B45: 1,2-Dichlorovinyl Ethyl Ether | C45: 16.9 | D45: 10.5 | E45: 6 | F45: =IFERROR(VLOOKUP(B45,Tabla2[],5,FALSE),"") | G45: =SQRT(4*(Tabla1[[#This Row],[dD]]-'Find a similar substance'!$D$5)^2+('Find a similar substance'!$E$5-Tabla1[[#This Row],[dP]])^2+(Tabla1[[#This Row],[dH]]-'Find a similar substance'!$F$5)^2) -> 2.1447611 | L45: Heptane | M45: 15.3 | N45: 0 | O45: 0 | P45: 147
A46: 135-01-3 | B46: 1,2-Diethyl Benzene | C46: 17.7 | D46: 0.1 | E46: 1 | F46: =IFERROR(VLOOKUP(B46,Tabla2[],5,FALSE),"") | G46: =SQRT(4*(Tabla1[[#This Row],[dD]]-'Find a similar substance'!$D$5)^2+('Find a similar substance'!$E$5-Tabla1[[#This Row],[dP]])^2+(Tabla1[[#This Row],[dH]]-'Find a similar substance'!$F$5)^2) -> 9.7365292 | L46: Hexane | M46: 14.9 | N46: 0 | O46: 0 | P46: 131.4
A47: 120-80-9 | B47: 1,2-Dihydroxybenzene (Catechol) | C47: 20 | D47: 11.3 | E47: 21.8 | F47: =IFERROR(VLOOKUP(B47,Tabla2[],5,FALSE),"") | G47: =SQRT(4*(Tabla1[[#This Row],[dD]]-'Find a similar substance'!$D$5)^2+('Find a similar substance'!$E$5-Tabla1[[#This Row],[dP]])^2+(Tabla1[[#This Row],[dH]]-'Find a similar substance'!$F$5)^2) -> 18.30956 | L47: Iso-Butanol | M47: 15.1 | N47: 5.7 | O47: 15.9 | P47: 92.9
A48: 91-16-7 | B48: 1,2-Dimethoxybenzene | C48: 19.2 | D48: 4.4 | E48: 9.4 | F48: =IFERROR(VLOOKUP(B48,Tabla2[],5,FALSE),"") | G48: =SQRT(4*(Tabla1[[#This Row],[dD]]-'Find a similar substance'!$D$5)^2+('Find a similar substance'!$E$5-Tabla1[[#This Row],[dP]])^2+(Tabla1[[#This Row],[dH]]-'Find a similar substance'!$F$5)^2) -> 8.0554329 | L48: Iso-Butyl Isobutyrate | M48: 15.1 | N48: 2.8 | O48: 5.8 | P48: 169.8
A49: 528-29-0 | B49: 1,2-Dinitrobenzene | C49: 20.6 | D49: 11.6 | E49: 3.9 | F49: =IFERROR(VLOOKUP(B49,Tabla2[],5,FALSE),"") | G49: =SQRT(4*(Tabla1[[#This Row],[dD]]-'Find a similar substance'!$D$5)^2+('Find a similar substance'!$E$5-Tabla1[[#This Row],[dP]])^2+(Tabla1[[#This Row],[dH]]-'Find a similar substance'!$F$5)^2) -> 8.5802098 | L49: Iso-Pentyl Acetate | M49: 15.3 | N49: 3.1 | O49: 7 | P49: 150.2
... A62: 926-57-8 | B62: 1,3-Dichloro-2-Butene | C62: 16.9 | D62: 7.8 | E62: 2.7 | F62: =IFERROR(VLOOKUP(B62,Tabla2[],5,FALSE),"") | G62: =SQRT(4*(Tabla1[[#This Row],[dD]]-'Find a similar substance'!$D$5)^2+('Find a similar substance'!$E$5-Tabla1[[#This Row],[dP]])^2+(Tabla1[[#This Row],[dH]]-'Find a similar substance'!$F$5)^2) -> 2.541653 | L62: Methyl iso-Butyl Carbinol | M62: 15.4 | N62: 3.3 | O62: 12.3 | P62: 127.2
A63: 134536 | B63: 1,3-Dichloro-2-Fluorobenzene | C63: 19.4 | D63: 9.1 | E63: 2.7 | F63: =IFERROR(VLOOKUP(B63,Tabla2[],5,FALSE),"") | G63: =SQRT(4*(Tabla1[[#This Row],[dD]]-'Find a similar substance'!$D$5)^2+('Find a similar substance'!$E$5-Tabla1[[#This Row],[dP]])^2+(Tabla1[[#This Row],[dH]]-'Find a similar substance'!$F$5)^2) -> 6.0671245 | L63: Methyl Iso-Butyl Ketone (MIBK) | M63: 15.3 | N63: 6.1 | O63: 4.1 | P63: 125.8
A64: 96-23-1 | B64: 1,3-Dichloro-2-Propanol | C64: 17.5 | D64: 9.9 | E64: 14.6 | F64: =IFERROR(VLOOKUP(B64,Tabla2[],5,FALSE),"") | G64: =SQRT(4*(Tabla1[[#This Row],[dD]]-'Find a similar substance'!$D$5)^2+('Find a similar substance'!$E$5-Tabla1[[#This Row],[dP]])^2+(Tabla1[[#This Row],[dH]]-'Find a similar substance'!$F$5)^2) -> 9.8407317 | L64: Methyl Oleate | M64: 16.2 | N64: 3.8 | O64: 4.5 | P64: 340.7
A65: 10143-66-5 | B65: 1,3-Dimethoxy Butane | C65: 15.6 | D65: 5.5 | E65: 5.2 | F65: =IFERROR(VLOOKUP(B65,Tabla2[],5,FALSE),"") | G65: =SQRT(4*(Tabla1[[#This Row],[dD]]-'Find a similar substance'!$D$5)^2+('Find a similar substance'!$E$5-Tabla1[[#This Row],[dP]])^2+(Tabla1[[#This Row],[dH]]-'Find a similar substance'!$F$5)^2) -> 3.7788887 | L65: Methyl Propyl Ketone | M65: 16 | N65: 7.6 | O65: 4.7 | P65: 107.3
A66: 646-06-0 | B66: 1,3-Dioxolane | C66: 18.1 | D66: 6.6 | E66: 9.3 | F66: =IFERROR(VLOOKUP(B66,Tabla2[],5,FALSE),"") -> 69.9 | G66: =SQRT(4*(Tabla1[[#This Row],[dD]]-'Find a similar substance'!$D$5)^2+('Find a similar substance'!$E$5-Tabla1[[#This Row],[dP]])^2+(Tabla1[[#This Row],[dH]]-'Find a similar substance'!$F$5)^2) -> 5.6480085 | L66: N-Methyl-2-Pyrrolidone (NMP) | M66: 18 | N66: 12.3 | O66: 7.2 | P66: 96.6
A67: 2004-70-8 | B67: 1,3-Pentadiene (Trans) | C67: 15 | D67: 2.5 | E67: 4 | F67: =IFERROR(VLOOKUP(B67,Tabla2[],5,FALSE),"") | G67: =SQRT(4*(Tabla1[[#This Row],[dD]]-'Find a similar substance'!$D$5)^2+('Find a similar substance'!$E$5-Tabla1[[#This Row],[dP]])^2+(Tabla1[[#This Row],[dH]]-'Find a similar substance'!$F$5)^2) -> 7.0484041 | L67: Methylene Chloride | M67: 17 | N67: 7.3 | O67: 7.1 | P67: 64.4
A68: 1120-71-4 | B68: 1,3-Propane Sultone | C68: 18.4 | D68: 16 | E68: 9 | F68: =IFERROR(VLOOKUP(B68,Tabla2[],5,FALSE),"") | G68: =SQRT(4*(Tabla1[[#This Row],[dD]]-'Find a similar substance'!$D$5)^2+('Find a similar substance'!$E$5-Tabla1[[#This Row],[dP]])^2+(Tabla1[[#This Row],[dH]]-'Find a similar substance'!$F$5)^2) -> 9.0691786 | L68: N,N-Dimethyl Acetamide | M68: 16.8 | N68: 11.5 | O68: 10.2 | P68: 93
A69: 504-63-2 | B69: 1,3-Propanediol (Trimethyleneglycol) | C69: 16.8 | D69: 13.5 | E69: 23.2 | F69: =IFERROR(VLOOKUP(B69,Tabla2[],5,FALSE),"") | G69: =SQRT(4*(Tabla1[[#This Row],[dD]]-'Find a similar substance'!$D$5)^2+('Find a similar substance'!$E$5-Tabla1[[#This Row],[dP]])^2+(Tabla1[[#This Row],[dH]]-'Find a similar substance'!$F$5)^2) -> 18.826577 | L69: N,N-Dimethyl Formamide (DMF) | M69: 17.4 | N69: 13.7 | O69: 11.3 | P69: 77.4
A70: 1070-70-8 | B70: 1,4-Butandiol Diacrylate | C70: 16.8 | D70: 9.1 | E70: 4.2 | F70: =IFERROR(VLOOKUP(B70,Tabla2[],5,FALSE),"") | G70: =SQRT(4*(Tabla1[[#This Row],[dD]]-'Find a similar substance'!$D$5)^2+('Find a similar substance'!$E$5-Tabla1[[#This Row],[dP]])^2+(Tabla1[[#This Row],[dH]]-'Find a similar substance'!$F$5)^2) -> 0.9797959 | L70: 1-Nitropropane | M70: 16.6 | N70: 12.3 | O70: 5.5 | P70: 89.5
A71: 110-63-4 | B71: 1,4-Butanediol | C71: 16.6 | D71: 11 | E71: 20.9 | F71: =IFERROR(VLOOKUP(B71,Tabla2[],5,FALSE),"") | G71: =SQRT(4*(Tabla1[[#This Row],[dD]]-'Find a similar substance'!$D$5)^2+('Find a similar substance'!$E$5-Tabla1[[#This Row],[dP]])^2+(Tabla1[[#This Row],[dH]]-'Find a similar substance'!$F$5)^2) -> 16.065491 | L71: 2-Phenoxy Ethanol | M71: 17.8 | N71: 5.7 | O71: 14.3 | P71: 124.7
A72: 764-41-0 | B72: 1,4-Dichloro-2-Butene | C72: 17.8 | D72: 7.6 | E72: 2 | F72: =IFERROR(VLOOKUP(B72,Tabla2[],5,FALSE),"") | G72: =SQRT(4*(Tabla1[[#This Row],[dD]]-'Find a similar substance'!$D$5)^2+('Find a similar substance'!$E$5-Tabla1[[#This Row],[dP]])^2+(Tabla1[[#This Row],[dH]]-'Find a similar substance'!$F$5)^2) -> 3.9962482 | L72: 2-Propanol | M72: 15.8 | N72: 6.1 | O72: 16.4 | P72: 76.9
A73: 110-56-5 | B73: 1,4-Dichlorobutane | C73: 18.3 | D73: 7.7 | E73: 2.8 | F73: =IFERROR(VLOOKUP(B73,Tabla2[],5,FALSE),"") | G73: =SQRT(4*(Tabla1[[#This Row],[dD]]-'Find a similar substance'!$D$5)^2+('Find a similar substance'!$E$5-Tabla1[[#This Row],[dP]])^2+(Tabla1[[#This Row],[dH]]-'Find a similar substance'!$F$5)^2) -> 4.1713307 | L73: 1-Propanol | M73: 16 | N73: 6.8 | O73: 17.4 | P73: 75.1
A74: 123-31-9 | B74: 1,4-Dihydroxybenzene (1,4-Benzenediol) | C74: 21 | D74: 10.2 | E74: 27.2 | F74: =IFERROR(VLOOKUP(B74,Tabla2[],5,FALSE),"") | G74: =SQRT(4*(Tabla1[[#This Row],[dD]]-'Find a similar substance'!$D$5)^2+('Find a similar substance'!$E$5-Tabla1[[#This Row],[dP]])^2+(Tabla1[[#This Row],[dH]]-'Find a similar substance'!$F$5)^2) -> 23.927599 | L74: n-Propyl Acetate | M74: 15.3 | N74: 4.3 | O74: 7.6 | P74: 115.8
...

Sheet HSP 1 Sphere
D1: HSP Sphere | H1: Solvents tested | K1: Scaling | L1: 1000000 | O1: Good | P1: =COUNTIF(L16:L110,1) -> 11 | BA1: Outliers | BF1: Good Solv | BK1: Bad Solv
C2: dD | D2: dP | E2: dH | F2: R | H2: =COUNT(L16:L101) -> 22 | K2: Fit | L2: =L1*N102 -> 1000000 | O2: Bad | P2: =COUNTIF(L16:L110,0) -> 11 | AT2: Angle º | AU2: Rad | AV2: dD (y) | AW2: dP (x) | AX2: dH (y) | AY2: dD (x) | BB2: dD | BC2: dP | BD2: dH | BG2: dD | BH2: dP | BI2: dH | BL2: dD | BM2: dP | BN2: dH
C3: 17.82654 | D3: 9.7595643 | E3: 8.0681076 | F3: 7.0686209 | K3: Fit % | L3: =L2/L1 -> 1 | O3: Total | P3: =P1+P2 -> 22 | AT3: 0 | AU3: =RADIANS(Tabla9[[#This Row],[Angle º]]) -> 0 | AV3: =$F$3*SIN(AU3)+ dD -> 17.82654 | AW3: =$F$3*COS(AU3)+ dP -> 16.828185 | AX3: =$F$3*SIN(AU3)+ dH -> 8.0681076 | AY3: =$F$3*COS(AU3)+ dD -> 24.895161 | BA3: {=_xlfn._xlws.FILTER(Tabla4[[Solvents]:[dH]],Tabla4[AUX], "NO OUTLIERS")} -> NO OUTLIERS | BF3: {=_xlfn._xlws.FILTER(Tabla4[[Solvents]:[dH]],Tabla4[AUX2]=1)} -> Acetone | BG3: 15.5 | BH3: 10.4 | BI3: 7 | BK3: {=_xlfn._xlws.FILTER(Tabla4[[Solvents]:[dH]],Tabla4[AUX2]=0)} -> Acetonitrile | BL3: 15.3 | BM3: 18 | BN3: 6.1
B4: Test Value | AT4: 5 | AU4: =RADIANS(Tabla9[[#This Row],[Angle º]]) -> 0.087266463 | AV4: =$F$3*SIN(AU4)+ dD -> 18.442611 | AW4: =$F$3*COS(AU4)+ dP -> 16.801287 | AX4: =$F$3*SIN(AU4)+ dH -> 8.6841785 | AY4: =$F$3*COS(AU4)+ dD -> 24.868263 | BF4: Chloroform | BG4: 17.8 | BH4: 3.1 | BI4: 5.7 | BK4: Benzene | BL4: 18.4 | BM4: 0 | BN4: 2
B5: Delta | C5: =dD-C4 -> 17.82654 | D5: =dP-D4 -> 9.7595643 | E5: =dH-E4 -> 8.0681076 | K5: Use Excel Solver to Maximise K6 | O5: Wrong Out | P5: =COUNTIF(Tabla4[WI / WO],"WO") -> 0 | AT5: 10 | AU5: =RADIANS(Tabla9[[#This Row],[Angle º]]) -> 0.17453293 | AV5: =$F$3*SIN(AU5)+ dD -> 19.053993 | AW5: =$F$3*COS(AU5)+ dP -> 16.720797 | AX5: =$F$3*SIN(AU5)+ dH -> 9.2955608 | AY5: =$F$3*COS(AU5)+ dD -> 24.787773 | BF5: m-Cresol | BG5: 18.5 | BH5: 6.5 | BI5: 13.7 | BK5: Cyclohexane | BL5: 16.8 | BM5: 0 | BN5: 0.2
C6: Distance | D6: =SQRT(4*(C4-dD)^2+(D4-dP)^2+(E4-dH)^2) -> 37.834978 | E6: RED | F6: =D6/R_ -> 5.3525262 | K6: Function | L6: =(R_^(-1/$H$2)*$N$102) -> 0.91494266 | O6: Wrong In | P6: =COUNTIF(Tabla4[WI / WO],"WI") -> 0 | AT6: 15 | AU6: =RADIANS(Tabla9[[#This Row],[Angle º]]) -> 0.26179939 | AV6: =$F$3*SIN(AU6)+ dD -> 19.656034 | AW6: =$F$3*COS(AU6)+ dP -> 16.587328 | AX6: =$F$3*SIN(AU6)+ dH -> 9.8976013 | AY6: =$F$3*COS(AU6)+ dD -> 24.654304 | BF6: Dimethyl Sulfoxide (DMSO) | BG6: 18.4 | BH6: 16.4 | BI6: 10.2 | BK6: Diethyl Ether | BL6: 14.5 | BM6: 2.9 | BN6: 4.6
AT7: 20 | AU7: =RADIANS(Tabla9[[#This Row],[Angle º]]) -> 0.34906585 | AV7: =$F$3*SIN(AU7)+ dD -> 20.244151 | AW7: =$F$3*COS(AU7)+ dP -> 16.401895 | AX7: =$F$3*SIN(AU7)+ dH -> 10.485718 | AY7: =$F$3*COS(AU7)+ dD -> 24.468871 | BF7: 1,3-Dioxolane | BG7: 18.1 | BH7: 6.6 | BI7: 9.3 | BK7: 1,4-Dioxane | BL7: 17.5 | BM7: 1.8 | BN7: 9
B8: Solvents | C8: dD | D8: dP | E8: dH | L8: Score | AT8: 25 | AU8: =RADIANS(Tabla9[[#This Row],[Angle º]]) -> 0.43633231 | AV8: =$F$3*SIN(AU8)+ dD -> 20.813868 | AW8: =$F$3*COS(AU8)+ dP -> 16.16591 | AX8: =$F$3*SIN(AU8)+ dH -> 11.055436 | AY8: =$F$3*COS(AU8)+ dD -> 24.232886 | BF8: Ethyl Acetate | BG8: 15.8 | BH8: 5.3 | BI8: 7.2 | BK8: Ethanol | BL8: 15.8 | BM8: 8.8 | BN8: 19.4
L9: 1 | AT9: 30 | AU9: =RADIANS(Tabla9[[#This Row],[Angle º]]) -> 0.52359878 | AV9: =$F$3*SIN(AU9)+ dD -> 21.360851 | AW9: =$F$3*COS(AU9)+ dP -> 15.88117 | AX9: =$F$3*SIN(AU9)+ dH -> 11.602418 | AY9: =$F$3*COS(AU9)+ dD -> 23.948145 | BF9: Methyl Ethyl Ketone (MEK) | BG9: 16 | BH9: 9 | BI9: 5.1 | BK9: Hexane | BL9: 14.9 | BM9: 0 | BN9: 0
B10: Max | C10: =DMAX(A15:L101,"dD",$B$8:$L$9) -> 18.5 | D10: =DMAX(A15:L101,"dP",$B$8:$L$9) -> 16.4 | E10: =DMAX(A15:L101,"dH",$B$8:$L$9) -> 13.7 | AT10: 35 | AU10: =RADIANS(Tabla9[[#This Row],[Angle º]]) -> 0.61086524 | AV10: =$F$3*SIN(AU10)+ dD -> 21.880935 | AW10: =$F$3*COS(AU10)+ dP -> 15.54984 | AX10: =$F$3*SIN(AU10)+ dH -> 12.122502 | AY10: =$F$3*COS(AU10)+ dD -> 23.616815 | BF10: N-Methyl-2-Pyrrolidone (NMP) | BG10: 18 | BH10: 12.3 | BI10: 7.2 | BK10: Isopropyl Ether | BL10: 15.1 | BM10: 3.2 | BN10: 3.2
B11: Min | C11: =DMIN(A15:L101,"dD",$B$8:$L$9) -> 15.5 | D11: =DMIN(A15:L101,"dD",$B$8:$L$9) -> 15.5 | E11: =DMIN(A15:L101,"dD",$B$8:$L$9) -> 15.5 | AT11: 40 | AU11: =RADIANS(Tabla9[[#This Row],[Angle º]]) -> 0.6981317 | AV11: =$F$3*SIN(AU11)+ dD -> 22.370162 | AW11: =$F$3*COS(AU11)+ dP -> 15.174442 | AX11: =$F$3*SIN(AU11)+ dH -> 12.61173 | AY11: =$F$3*COS(AU11)+ dD -> 23.241418 | BF11: Methylene Dichloride (Dichloromethane) | BG11: 17 | BH11: 7.3 | BI11: 7.1 | BK11: Methanol | BL11: 14.7 | BM11: 12.3 | BN11: 22.3
B12: Delta | C12: =C10-C11 -> 3 | D12: =D10-D11 -> 0.9 | E12: =E10-E11 -> -1.8 | AT12: 45 | AU12: =RADIANS(Tabla9[[#This Row],[Angle º]]) -> 0.78539816 | AV12: =$F$3*SIN(AU12)+ dD -> 22.82481 | AW12: =$F$3*COS(AU12)+ dP -> 14.757834 | AX12: =$F$3*SIN(AU12)+ dH -> 13.066377 | AY12: =$F$3*COS(AU12)+ dD -> 22.82481 | BF12: Dimethyl Formamide (DMF) | BG12: 17.4 | BH12: 13.7 | BI12: 11.3 | BK12: Toluene | BL12: 18 | BM12: 1.4 | BN12: 2
B13: Substance Coordinates | C13: =C10-C12/2 -> 17 | D13: =D10-D12/2 -> 15.95 | E13: =E10-E12/2 -> 14.6 | AT13: 50 | AU13: =RADIANS(Tabla9[[#This Row],[Angle º]]) -> 0.87266463 | AV13: =$F$3*SIN(AU13)+ dD -> 23.241418 | AW13: =$F$3*COS(AU13)+ dP -> 14.303186 | AX13: =$F$3*SIN(AU13)+ dH -> 13.482985 | AY13: =$F$3*COS(AU13)+ dD -> 22.370162 | BF13: Tetrahydrofuran (THF) | BG13: 16.8 | BH13: 5.7 | BI13: 8 | BK13: Xylene | BL13: 17.8 | BM13: 1 | BN13: 3.1
AT14: 55 | AU14: =RADIANS(Tabla9[[#This Row],[Angle º]]) -> 0.95993109 | AV14: =$F$3*SIN(AU14)+ dD -> 23.616815 | AW14: =$F$3*COS(AU14)+ dP -> 13.813959 | AX14: =$F$3*SIN(AU14)+ dH -> 13.858383 | AY14: =$F$3*COS(AU14)+ dD -> 21.880935
A15: CAS | B15: Solvents | C15: dD | D15: dP | E15: dH | F15: MVol | G15: WI / WO | H15: AUX | I15: AUX2 | J15: RED | L15: Score | M15: Distance | N15: Error | O15: Ra Good Solv | AT15: 60 | AU15: =RADIANS(Tabla9[[#This Row],[Angle º]]) -> 1.0471976 | AV15: =$F$3*SIN(AU15)+ dD -> 23.948145 | AW15: =$F$3*COS(AU15)+ dP -> 13.293875 | AX15: =$F$3*SIN(AU15)+ dH -> 14.189713 | AY15: =$F$3*COS(AU15)+ dD -> 21.360851
A16: 67-64-1 | B16: =VLOOKUP(Tabla4[[#This Row],[CAS]],Tabla1[],2,FALSE) -> Acetone | C16: =VLOOKUP(Tabla4[[#This Row],[CAS]],Tabla1[],3,FALSE) -> 15.5 | D16: =VLOOKUP(Tabla4[[#This Row],[CAS]],Tabla1[],4,FALSE) -> 10.4 | E16: =VLOOKUP(Tabla4[[#This Row],[CAS]],Tabla1[],5,FALSE) -> 7 | F16: =VLOOKUP(Tabla4[[#This Row],[CAS]],Tabla1[],6,FALSE) -> 73.8 | G16: =IF(L16=1,IF(J16<=1,"","WO"),IF(L16<>"",IF(J16>1,"","WI"),"")) | H16: =ISNUMBER(SEARCH("w",Tabla4[[#This Row],[WI / WO]])) -> FALSE | I16: =L16 -> 1 | J16: =IF(L16<>"",M16/R_,"") -> 0.68144309 | L16: 1 | M16: =IF(L16<>"",SQRT(4*(C16-dD)^2+(D16-dP)^2+(E16-dH)^2),0) -> 4.8168629 | N16: =IF(L16=1,IF(M16<R_,1,EXP(R_-M16)),IF(L16<>"",IF(M16<R_,EXP(M16-R_),1),1)) -> 1 | O16: =IF(L16=1,M16, "") -> 4.8168629 | AT16: 65 | AU16: =RADIANS(Tabla9[[#This Row],[Angle º]]) -> 1.134464 | AV16: =$F$3*SIN(AU16)+ dD -> 24.232886 | AW16: =$F$3*COS(AU16)+ dP -> 12.746893 | AX16: =$F$3*SIN(AU16)+ dH -> 14.474454 | AY16: =$F$3*COS(AU16)+ dD -> 20.813868
A17: 75-05-8 | B17: =VLOOKUP(Tabla4[[#This Row],[CAS]],Tabla1[],2,FALSE) -> Acetonitrile | C17: =VLOOKUP(Tabla4[[#This Row],[CAS]],Tabla1[],3,FALSE) -> 15.3 | D17: =VLOOKUP(Tabla4[[#This Row],[CAS]],Tabla1[],4,FALSE) -> 18 | E17: =VLOOKUP(Tabla4[[#This Row],[CAS]],Tabla1[],5,FALSE) -> 6.1 | F17: =VLOOKUP(Tabla4[[#This Row],[CAS]],Tabla1[],6,FALSE) -> 52.9 | G17: =IF(L17=1,IF(J17<=1,"","WO"),IF(L17<>"",IF(J17>1,"","WI"),"")) | H17: =ISNUMBER(SEARCH("w",Tabla4[[#This Row],[WI / WO]])) -> FALSE | I17: =L17 -> 0 | J17: =IF(L17<>"",M17/R_,"") -> 1.3955589 | L17: 0 | M17: =IF(L17<>"",SQRT(4*(C17-dD)^2+(D17-dP)^2+(E17-dH)^2),0) -> 9.8646768 | N17: =IF(L17=1,IF(M17<R_,1,EXP(R_-M17)),IF(L17<>"",IF(M17<R_,EXP(M17-R_),1),1)) -> 1 | O17: =IF(L17=1,M17, "") | AT17: 70 | AU17: =RADIANS(Tabla9[[#This Row],[Angle º]]) -> 1.2217305 | AV17: =$F$3*SIN(AU17)+ dD -> 24.468871 | AW17: =$F$3*COS(AU17)+ dP -> 12.177175 | AX17: =$F$3*SIN(AU17)+ dH -> 14.710439 | AY17: =$F$3*COS(AU17)+ dD -> 20.244151
A18: 71-43-2 | B18: =VLOOKUP(Tabla4[[#This Row],[CAS]],Tabla1[],2,FALSE) -> Benzene | C18: =VLOOKUP(Tabla4[[#This Row],[CAS]],Tabla1[],3,FALSE) -> 18.4 | D18: =VLOOKUP(Tabla4[[#This Row],[CAS]],Tabla1[],4,FALSE) -> 0 | E18: =VLOOKUP(Tabla4[[#This Row],[CAS]],Tabla1[],5,FALSE) -> 2 | F18: =VLOOKUP(Tabla4[[#This Row],[CAS]],Tabla1[],6,FALSE) -> 52.9 | G18: =IF(L18=1,IF(J18<=1,"","WO"),IF(L18<>"",IF(J18>1,"","WI"),"")) | H18: =ISNUMBER(SEARCH("w",Tabla4[[#This Row],[WI / WO]])) -> FALSE | I18: =L18 -> 0 | J18: =IF(L18<>"",M18/R_,"") -> 1.6338838 | L18: 0 | M18: =IF(L18<>"",SQRT(4*(C18-dD)^2+(D18-dP)^2+(E18-dH)^2),0) -> 11.549305 | N18: =IF(L18=1,IF(M18<R_,1,EXP(R_-M18)),IF(L18<>"",IF(M18<R_,EXP(M18-R_),1),1)) -> 1 | O18: =IF(L18=1,M18, "") | AT18: 75 | AU18: =RADIANS(Tabla9[[#This Row],[Angle º]]) -> 1.3089969 | AV18: =$F$3*SIN(AU18)+ dD -> 24.654304 | AW18: =$F$3*COS(AU18)+ dP -> 11.589058 | AX18: =$F$3*SIN(AU18)+ dH -> 14.895871 | AY18: =$F$3*COS(AU18)+ dD -> 19.656034
A19: 67-66-3 | B19: =VLOOKUP(Tabla4[[#This Row],[CAS]],Tabla1[],2,FALSE) -> Chloroform | C19: =VLOOKUP(Tabla4[[#This Row],[CAS]],Tabla1[],3,FALSE) -> 17.8 | D19: =VLOOKUP(Tabla4[[#This Row],[CAS]],Tabla1[],4,FALSE) -> 3.1 | E19: =VLOOKUP(Tabla4[[#This Row],[CAS]],Tabla1[],5,FALSE) -> 5.7 | F19: =VLOOKUP(Tabla4[[#This Row],[CAS]],Tabla1[],6,FALSE) -> 80.5 | G19: =IF(L19=1,IF(J19<=1,"","WO"),IF(L19<>"",IF(J19>1,"","WI"),"")) | H19: =ISNUMBER(SEARCH("w",Tabla4[[#This Row],[WI / WO]])) -> FALSE | I19: =L19 -> 1 | J19: =IF(L19<>"",M19/R_,"") -> 0.99995143 | L19: 1 | M19: =IF(L19<>"",SQRT(4*(C19-dD)^2+(D19-dP)^2+(E19-dH)^2),0) -> 7.0682776 | N19: =IF(L19=1,IF(M19<R_,1,EXP(R_-M19)),IF(L19<>"",IF(M19<R_,EXP(M19-R_),1),1)) -> 1 | O19: =IF(L19=1,M19, "") -> 7.0682776 | AT19: 80 | AU19: =RADIANS(Tabla9[[#This Row],[Angle º]]) -> 1.3962634 | AV19: =$F$3*SIN(AU19)+ dD -> 24.787773 | AW19: =$F$3*COS(AU19)+ dP -> 10.987017 | AX19: =$F$3*SIN(AU19)+ dH -> 15.02934 | AY19: =$F$3*COS(AU19)+ dD -> 19.053993
A20: 108-39-4 | B20: =VLOOKUP(Tabla4[[#This Row],[CAS]],Tabla1[],2,FALSE) -> m-Cresol | C20: =VLOOKUP(Tabla4[[#This Row],[CAS]],Tabla1[],3,FALSE) -> 18.5 | D20: =VLOOKUP(Tabla4[[#This Row],[CAS]],Tabla1[],4,FALSE) -> 6.5 | E20: =VLOOKUP(Tabla4[[#This Row],[CAS]],Tabla1[],5,FALSE) -> 13.7 | F20: =VLOOKUP(Tabla4[[#This Row],[CAS]],Tabla1[],6,FALSE) -> 105 | G20: =IF(L20=1,IF(J20<=1,"","WO"),IF(L20<>"",IF(J20>1,"","WI"),"")) | H20: =ISNUMBER(SEARCH("w",Tabla4[[#This Row],[WI / WO]])) -> FALSE | I20: =L20 -> 1 | J20: =IF(L20<>"",M20/R_,"") -> 0.94008234 | L20: 1 | M20: =IF(L20<>"",SQRT(4*(C20-dD)^2+(D20-dP)^2+(E20-dH)^2),0) -> 6.6450857 | N20: =IF(L20=1,IF(M20<R_,1,EXP(R_-M20)),IF(L20<>"",IF(M20<R_,EXP(M20-R_),1),1)) -> 1 | O20: =IF(L20=1,M20, "") -> 6.6450857 | AT20: 85 | AU20: =RADIANS(Tabla9[[#This Row],[Angle º]]) -> 1.4835299 | AV20: =$F$3*SIN(AU20)+ dD -> 24.868263 | AW20: =$F$3*COS(AU20)+ dP -> 10.375635 | AX20: =$F$3*SIN(AU20)+ dH -> 15.10983 | AY20: =$F$3*COS(AU20)+ dD -> 18.442611
A21: 110-82-7 | B21: =VLOOKUP(Tabla4[[#This Row],[CAS]],Tabla1[],2,FALSE) -> Cyclohexane | C21: =VLOOKUP(Tabla4[[#This Row],[CAS]],Tabla1[],3,FALSE) -> 16.8 | D21: =VLOOKUP(Tabla4[[#This Row],[CAS]],Tabla1[],4,FALSE) -> 0 | E21: =VLOOKUP(Tabla4[[#This Row],[CAS]],Tabla1[],5,FALSE) -> 0.2 | F21: =VLOOKUP(Tabla4[[#This Row],[CAS]],Tabla1[],6,FALSE) -> 108.9 | G21: =IF(L21=1,IF(J21<=1,"","WO"),IF(L21<>"",IF(J21>1,"","WI"),"")) | H21: =ISNUMBER(SEARCH("w",Tabla4[[#This Row],[WI / WO]])) -> FALSE | I21: =L21 -> 0 | J21: =IF(L21<>"",M21/R_,"") -> 1.797126 | L21: 0 | M21: =IF(L21<>"",SQRT(4*(C21-dD)^2+(D21-dP)^2+(E21-dH)^2),0) -> 12.703202 | N21: =IF(L21=1,IF(M21<R_,1,EXP(R_-M21)),IF(L21<>"",IF(M21<R_,EXP(M21-R_),1),1)) -> 1 | O21: =IF(L21=1,M21, "") | AT21: 90 | AU21: =RADIANS(Tabla9[[#This Row],[Angle º]]) -> 1.5707963 | AV21: =$F$3*SIN(AU21)+ dD -> 24.895161 | AW21: =$F$3*COS(AU21)+ dP -> 9.7595643 | AX21: =$F$3*SIN(AU21)+ dH -> 15.136729 | AY21: =$F$3*COS(AU21)+ dD -> 17.82654
A22: 60-29-7 | B22: =VLOOKUP(Tabla4[[#This Row],[CAS]],Tabla1[],2,FALSE) -> Diethyl Ether | C22: =VLOOKUP(Tabla4[[#This Row],[CAS]],Tabla1[],3,FALSE) -> 14.5 | D22: =VLOOKUP(Tabla4[[#This Row],[CAS]],Tabla1[],4,FALSE) -> 2.9 | E22: =VLOOKUP(Tabla4[[#This Row],[CAS]],Tabla1[],5,FALSE) -> 4.6 | F22: =VLOOKUP(Tabla4[[#This Row],[CAS]],Tabla1[],6,FALSE) -> 104.7 | G22: =IF(L22=1,IF(J22<=1,"","WO"),IF(L22<>"",IF(J22>1,"","WI"),"")) | H22: =ISNUMBER(SEARCH("w",Tabla4[[#This Row],[WI / WO]])) -> FALSE | I22: =L22 -> 0 | J22: =IF(L22<>"",M22/R_,"") -> 1.4381685 | L22: 0 | M22: =IF(L22<>"",SQRT(4*(C22-dD)^2+(D22-dP)^2+(E22-dH)^2),0) -> 10.165868 | N22: =IF(L22=1,IF(M22<R_,1,EXP(R_-M22)),IF(L22<>"",IF(M22<R_,EXP(M22-R_),1),1)) -> 1 | O22: =IF(L22=1,M22, "") | AT22: 95 | AU22: =RADIANS(Tabla9[[#This Row],[Angle º]]) -> 1.6580628 | AV22: =$F$3*SIN(AU22)+ dD -> 24.868263 | AW22: =$F$3*COS(AU22)+ dP -> 9.1434934 | AX22: =$F$3*SIN(AU22)+ dH -> 15.10983 | AY22: =$F$3*COS(AU22)+ dD -> 17.210469
A23: 67-68-5 | B23: =VLOOKUP(Tabla4[[#This Row],[CAS]],Tabla1[],2,FALSE) -> Dimethyl Sulfoxide (DMSO) | C23: =VLOOKUP(Tabla4[[#This Row],[CAS]],Tabla1[],3,FALSE) -> 18.4 | D23: =VLOOKUP(Tabla4[[#This Row],[CAS]],Tabla1[],4,FALSE) -> 16.4 | E23: =VLOOKUP(Tabla4[[#This Row],[CAS]],Tabla1[],5,FALSE) -> 10.2 | F23: =VLOOKUP(Tabla4[[#This Row],[CAS]],Tabla1[],6,FALSE) -> 71.3 | G23: =IF(L23=1,IF(J23<=1,"","WO"),IF(L23<>"",IF(J23>1,"","WI"),"")) | H23: =ISNUMBER(SEARCH("w",Tabla4[[#This Row],[WI / WO]])) -> FALSE | I23: =L23 -> 1 | J23: =IF(L23<>"",M23/R_,"") -> 0.99990368 | L23: 1 | M23: =IF(L23<>"",SQRT(4*(C23-dD)^2+(D23-dP)^2+(E23-dH)^2),0) -> 7.06794 | N23: =IF(L23=1,IF(M23<R_,1,EXP(R_-M23)),IF(L23<>"",IF(M23<R_,EXP(M23-R_),1),1)) -> 1 | O23: =IF(L23=1,M23, "") -> 7.06794 | AT23: 100 | AU23: =RADIANS(Tabla9[[#This Row],[Angle º]]) -> 1.7453293 | AV23: =$F$3*SIN(AU23)+ dD -> 24.787773 | AW23: =$F$3*COS(AU23)+ dP -> 8.5321112 | AX23: =$F$3*SIN(AU23)+ dH -> 15.02934 | AY23: =$F$3*COS(AU23)+ dD -> 16.599087
A24: 123-91-1 | B24: =VLOOKUP(Tabla4[[#This Row],[CAS]],Tabla1[],2,FALSE) -> 1,4-Dioxane | C24: =VLOOKUP(Tabla4[[#This Row],[CAS]],Tabla1[],3,FALSE) -> 17.5 | D24: =VLOOKUP(Tabla4[[#This Row],[CAS]],Tabla1[],4,FALSE) -> 1.8 | E24: =VLOOKUP(Tabla4[[#This Row],[CAS]],Tabla1[],5,FALSE) -> 9 | F24: =VLOOKUP(Tabla4[[#This Row],[CAS]],Tabla1[],6,FALSE) -> 85.7 | G24: =IF(L24=1,IF(J24<=1,"","WO"),IF(L24<>"",IF(J24>1,"","WI"),"")) | H24: =ISNUMBER(SEARCH("w",Tabla4[[#This Row],[WI / WO]])) -> FALSE | I24: =L24 -> 0 | J24: =IF(L24<>"",M24/R_,"") -> 1.1374917 | L24: 0 | M24: =IF(L24<>"",SQRT(4*(C24-dD)^2+(D24-dP)^2+(E24-dH)^2),0) -> 8.0404976 | N24: =IF(L24=1,IF(M24<R_,1,EXP(R_-M24)),IF(L24<>"",IF(M24<R_,EXP(M24-R_),1),1)) -> 1 | O24: =IF(L24=1,M24, "") | AT24: 105 | AU24: =RADIANS(Tabla9[[#This Row],[Angle º]]) -> 1.8325957 | AV24: =$F$3*SIN(AU24)+ dD -> 24.654304 | AW24: =$F$3*COS(AU24)+ dP -> 7.9300706 | AX24: =$F$3*SIN(AU24)+ dH -> 14.895871 | AY24: =$F$3*COS(AU24)+ dD -> 15.997046
A25: 646-06-0 | B25: =VLOOKUP(Tabla4[[#This Row],[CAS]],Tabla1[],2,FALSE) -> 1,3-Dioxolane | C25: =VLOOKUP(Tabla4[[#This Row],[CAS]],Tabla1[],3,FALSE) -> 18.1 | D25: =VLOOKUP(Tabla4[[#This Row],[CAS]],Tabla1[],4,FALSE) -> 6.6 | E25: =VLOOKUP(Tabla4[[#This Row],[CAS]],Tabla1[],5,FALSE) -> 9.3 | F25: =VLOOKUP(Tabla4[[#This Row],[CAS]],Tabla1[],6,FALSE) -> 69.9 | G25: =IF(L25=1,IF(J25<=1,"","WO"),IF(L25<>"",IF(J25>1,"","WI"),"")) | H25: =ISNUMBER(SEARCH("w",Tabla4[[#This Row],[WI / WO]])) -> FALSE | I25: =L25 -> 1 | J25: =IF(L25<>"",M25/R_,"") -> 0.48595673 | L25: 1 | M25: =IF(L25<>"",SQRT(4*(C25-dD)^2+(D25-dP)^2+(E25-dH)^2),0) -> 3.4350439 | N25: =IF(L25=1,IF(M25<R_,1,EXP(R_-M25)),IF(L25<>"",IF(M25<R_,EXP(M25-R_),1),1)) -> 1 | O25: =IF(L25=1,M25, "") -> 3.4350439 | AT25: 110 | AU25: =RADIANS(Tabla9[[#This Row],[Angle º]]) -> 1.9198622 | AV25: =$F$3*SIN(AU25)+ dD -> 24.468871 | AW25: =$F$3*COS(AU25)+ dP -> 7.3419536 | AX25: =$F$3*SIN(AU25)+ dH -> 14.710439 | AY25: =$F$3*COS(AU25)+ dD -> 15.408929
A26: 64-17-5 | B26: =VLOOKUP(Tabla4[[#This Row],[CAS]],Tabla1[],2,FALSE) -> Ethanol | C26: =VLOOKUP(Tabla4[[#This Row],[CAS]],Tabla1[],3,FALSE) -> 15.8 | D26: =VLOOKUP(Tabla4[[#This Row],[CAS]],Tabla1[],4,FALSE) -> 8.8 | E26: =VLOOKUP(Tabla4[[#This Row],[CAS]],Tabla1[],5,FALSE) -> 19.4 | F26: =VLOOKUP(Tabla4[[#This Row],[CAS]],Tabla1[],6,FALSE) -> 58.6 | G26: =IF(L26=1,IF(J26<=1,"","WO"),IF(L26<>"",IF(J26>1,"","WI"),"")) | H26: =ISNUMBER(SEARCH("w",Tabla4[[#This Row],[WI / WO]])) -> FALSE | I26: =L26 -> 0 | J26: =IF(L26<>"",M26/R_,"") -> 1.7079868 | L26: 0 | M26: =IF(L26<>"",SQRT(4*(C26-dD)^2+(D26-dP)^2+(E26-dH)^2),0) -> 12.073111 | N26: =IF(L26=1,IF(M26<R_,1,EXP(R_-M26)),IF(L26<>"",IF(M26<R_,EXP(M26-R_),1),1)) -> 1 | O26: =IF(L26=1,M26, "") | AT26: 115 | AU26: =RADIANS(Tabla9[[#This Row],[Angle º]]) -> 2.0071286 | AV26: =$F$3*SIN(AU26)+ dD -> 24.232886 | AW26: =$F$3*COS(AU26)+ dP -> 6.772236 | AX26: =$F$3*SIN(AU26)+ dH -> 14.474454 | AY26: =$F$3*COS(AU26)+ dD -> 14.839212
A27: 141-78-6 | B27: =VLOOKUP(Tabla4[[#This Row],[CAS]],Tabla1[],2,FALSE) -> Ethyl Acetate | C27: =VLOOKUP(Tabla4[[#This Row],[CAS]],Tabla1[],3,FALSE) -> 15.8 | D27: =VLOOKUP(Tabla4[[#This Row],[CAS]],Tabla1[],4,FALSE) -> 5.3 | E27: =VLOOKUP(Tabla4[[#This Row],[CAS]],Tabla1[],5,FALSE) -> 7.2 | F27: =VLOOKUP(Tabla4[[#This Row],[CAS]],Tabla1[],6,FALSE) -> 98.6 | G27: =IF(L27=1,IF(J27<=1,"","WO"),IF(L27<>"",IF(J27>1,"","WI"),"")) | H27: =ISNUMBER(SEARCH("w",Tabla4[[#This Row],[WI / WO]])) -> FALSE | I27: =L27 -> 1 | J27: =IF(L27<>"",M27/R_,"") -> 0.86132982 | L27: 1 | M27: =IF(L27<>"",SQRT(4*(C27-dD)^2+(D27-dP)^2+(E27-dH)^2),0) -> 6.0884139 | N27: =IF(L27=1,IF(M27<R_,1,EXP(R_-M27)),IF(L27<>"",IF(M27<R_,EXP(M27-R_),1),1)) -> 1 | O27: =IF(L27=1,M27, "") -> 6.0884139 | AT27: 120 | AU27: =RADIANS(Tabla9[[#This Row],[Angle º]]) -> 2.0943951 | AV27: =$F$3*SIN(AU27)+ dD -> 23.948145 | AW27: =$F$3*COS(AU27)+ dP -> 6.2252538 | AX27: =$F$3*SIN(AU27)+ dH -> 14.189713 | AY27: =$F$3*COS(AU27)+ dD -> 14.29223
... A37: 106-42-3 | B37: =VLOOKUP(Tabla4[[#This Row],[CAS]],Tabla1[],2,FALSE) -> Xylene | C37: =VLOOKUP(Tabla4[[#This Row],[CAS]],Tabla1[],3,FALSE) -> 17.8 | D37: =VLOOKUP(Tabla4[[#This Row],[CAS]],Tabla1[],4,FALSE) -> 1 | E37: =VLOOKUP(Tabla4[[#This Row],[CAS]],Tabla1[],5,FALSE) -> 3.1 | F37: =VLOOKUP(Tabla4[[#This Row],[CAS]],Tabla1[],6,FALSE) -> 123.9 | G37: =IF(L37=1,IF(J37<=1,"","WO"),IF(L37<>"",IF(J37>1,"","WI"),"")) | H37: =ISNUMBER(SEARCH("w",Tabla4[[#This Row],[WI / WO]])) -> FALSE | I37: =L37 -> 0 | J37: =IF(L37<>"",M37/R_,"") -> 1.4246761 | L37: 0 | M37: =IF(L37<>"",SQRT(4*(C37-dD)^2+(D37-dP)^2+(E37-dH)^2),0) -> 10.070495 | N37: =IF(L37=1,IF(M37<R_,1,EXP(R_-M37)),IF(L37<>"",IF(M37<R_,EXP(M37-R_),1),1)) -> 1 | O37: =IF(L37=1,M37, "") | AT37: 170 | AU37: =RADIANS(Tabla9[[#This Row],[Angle º]]) -> 2.9670597 | AV37: =$F$3*SIN(AU37)+ dD -> 19.053993 | AW37: =$F$3*COS(AU37)+ dP -> 2.7983316 | AX37: =$F$3*SIN(AU37)+ dH -> 9.2955608 | AY37: =$F$3*COS(AU37)+ dD -> 10.865307
M38: =IF(L38<>"",SQRT(4*(C38-dD)^2+(D38-dP)^2+(E38-dH)^2),0) -> 0 | N38: =IF(L38=1,IF(M38<R_,1,EXP(R_-M38)),IF(L38<>"",IF(M38<R_,EXP(M38-R_),1),1)) -> 1 | O38: =IF(L38=1,M38, "") | AT38: 175 | AU38: =RADIANS(Tabla9[[#This Row],[Angle º]]) -> 3.0543262 | AV38: =$F$3*SIN(AU38)+ dD -> 18.442611 | AW38: =$F$3*COS(AU38)+ dP -> 2.7178416 | AX38: =$F$3*SIN(AU38)+ dH -> 8.6841785 | AY38: =$F$3*COS(AU38)+ dD -> 10.784817
M39: =IF(L39<>"",SQRT(4*(C39-dD)^2+(D39-dP)^2+(E39-dH)^2),0) -> 0 | N39: =IF(L39=1,IF(M39<R_,1,EXP(R_-M39)),IF(L39<>"",IF(M39<R_,EXP(M39-R_),1),1)) -> 1 | O39: =IF(L39=1,M39, "") | AT39: 180 | AU39: =RADIANS(Tabla9[[#This Row],[Angle º]]) -> 3.1415927 | AV39: =$F$3*SIN(AU39)+ dD -> 17.82654 | AW39: =$F$3*COS(AU39)+ dP -> 2.6909434 | AX39: =$F$3*SIN(AU39)+ dH -> 8.0681076 | AY39: =$F$3*COS(AU39)+ dD -> 10.757919
M40: =IF(L40<>"",SQRT(4*(C40-dD)^2+(D40-dP)^2+(E40-dH)^2),0) -> 0 | N40: =IF(L40=1,IF(M40<R_,1,EXP(R_-M40)),IF(L40<>"",IF(M40<R_,EXP(M40-R_),1),1)) -> 1 | O40: =IF(L40=1,M40, "") | AT40: 185 | AU40: =RADIANS(Tabla9[[#This Row],[Angle º]]) -> 3.2288591 | AV40: =$F$3*SIN(AU40)+ dD -> 17.210469 | AW40: =$F$3*COS(AU40)+ dP -> 2.7178416 | AX40: =$F$3*SIN(AU40)+ dH -> 7.4520367 | AY40: =$F$3*COS(AU40)+ dD -> 10.784817
M41: =IF(L41<>"",SQRT(4*(C41-dD)^2+(D41-dP)^2+(E41-dH)^2),0) -> 0 | N41: =IF(L41=1,IF(M41<R_,1,EXP(R_-M41)),IF(L41<>"",IF(M41<R_,EXP(M41-R_),1),1)) -> 1 | O41: =IF(L41=1,M41, "") | AT41: 190 | AU41: =RADIANS(Tabla9[[#This Row],[Angle º]]) -> 3.3161256 | AV41: =$F$3*SIN(AU41)+ dD -> 16.599087 | AW41: =$F$3*COS(AU41)+ dP -> 2.7983316 | AX41: =$F$3*SIN(AU41)+ dH -> 6.8406545 | AY41: =$F$3*COS(AU41)+ dD -> 10.865307
M42: =IF(L42<>"",SQRT(4*(C42-dD)^2+(D42-dP)^2+(E42-dH)^2),0) -> 0 | N42: =IF(L42=1,IF(M42<R_,1,EXP(R_-M42)),IF(L42<>"",IF(M42<R_,EXP(M42-R_),1),1)) -> 1 | O42: =IF(L42=1,M42, "") | AT42: 195 | AU42: =RADIANS(Tabla9[[#This Row],[Angle º]]) -> 3.403392 | AV42: =$F$3*SIN(AU42)+ dD -> 15.997046 | AW42: =$F$3*COS(AU42)+ dP -> 2.9318008 | AX42: =$F$3*SIN(AU42)+ dH -> 6.2386139 | AY42: =$F$3*COS(AU42)+ dD -> 10.998777
M43: =IF(L43<>"",SQRT(4*(C43-dD)^2+(D43-dP)^2+(E43-dH)^2),0) -> 0 | N43: =IF(L43=1,IF(M43<R_,1,EXP(R_-M43)),IF(L43<>"",IF(M43<R_,EXP(M43-R_),1),1)) -> 1 | O43: =IF(L43=1,M43, "") | AT43: 200 | AU43: =RADIANS(Tabla9[[#This Row],[Angle º]]) -> 3.4906585 | AV43: =$F$3*SIN(AU43)+ dD -> 15.408929 | AW43: =$F$3*COS(AU43)+ dP -> 3.1172334 | AX43: =$F$3*SIN(AU43)+ dH -> 5.6504969 | AY43: =$F$3*COS(AU43)+ dD -> 11.184209
M44: =IF(L44<>"",SQRT(4*(C44-dD)^2+(D44-dP)^2+(E44-dH)^2),0) -> 0 | N44: =IF(L44=1,IF(M44<R_,1,EXP(R_-M44)),IF(L44<>"",IF(M44<R_,EXP(M44-R_),1),1)) -> 1 | O44: =IF(L44=1,M44, "") | AT44: 205 | AU44: =RADIANS(Tabla9[[#This Row],[Angle º]]) -> 3.577925 | AV44: =$F$3*SIN(AU44)+ dD -> 14.839212 | AW44: =$F$3*COS(AU44)+ dP -> 3.3532181 | AX44: =$F$3*SIN(AU44)+ dH -> 5.0807793 | AY44: =$F$3*COS(AU44)+ dD -> 11.420194
M45: =IF(L45<>"",SQRT(4*(C45-dD)^2+(D45-dP)^2+(E45-dH)^2),0) -> 0 | N45: =IF(L45=1,IF(M45<R_,1,EXP(R_-M45)),IF(L45<>"",IF(M45<R_,EXP(M45-R_),1),1)) -> 1 | O45: =IF(L45=1,M45, "") | AT45: 210 | AU45: =RADIANS(Tabla9[[#This Row],[Angle º]]) -> 3.6651914 | AV45: =$F$3*SIN(AU45)+ dD -> 14.29223 | AW45: =$F$3*COS(AU45)+ dP -> 3.637959 | AX45: =$F$3*SIN(AU45)+ dH -> 4.5337972 | AY45: =$F$3*COS(AU45)+ dD -> 11.704935
M46: =IF(L46<>"",SQRT(4*(C46-dD)^2+(D46-dP)^2+(E46-dH)^2),0) -> 0 | N46: =IF(L46=1,IF(M46<R_,1,EXP(R_-M46)),IF(L46<>"",IF(M46<R_,EXP(M46-R_),1),1)) -> 1 | O46: =IF(L46=1,M46, "") | AT46: 215 | AU46: =RADIANS(Tabla9[[#This Row],[Angle º]]) -> 3.7524579 | AV46: =$F$3*SIN(AU46)+ dD -> 13.772146 | AW46: =$F$3*COS(AU46)+ dP -> 3.969289 | AX46: =$F$3*SIN(AU46)+ dH -> 4.0137132 | AY46: =$F$3*COS(AU46)+ dD -> 12.036265
M47: =IF(L47<>"",SQRT(4*(C47-dD)^2+(D47-dP)^2+(E47-dH)^2),0) -> 0 | N47: =IF(L47=1,IF(M47<R_,1,EXP(R_-M47)),IF(L47<>"",IF(M47<R_,EXP(M47-R_),1),1)) -> 1 | O47: =IF(L47=1,M47, "") | AT47: 220 | AU47: =RADIANS(Tabla9[[#This Row],[Angle º]]) -> 3.8397244 | AV47: =$F$3*SIN(AU47)+ dD -> 13.282918 | AW47: =$F$3*COS(AU47)+ dP -> 4.3446865 | AX47: =$F$3*SIN(AU47)+ dH -> 3.5244857 | AY47: =$F$3*COS(AU47)+ dD -> 12.411662
M48: =IF(L48<>"",SQRT(4*(C48-dD)^2+(D48-dP)^2+(E48-dH)^2),0) -> 0 | N48: =IF(L48=1,IF(M48<R_,1,EXP(R_-M48)),IF(L48<>"",IF(M48<R_,EXP(M48-R_),1),1)) -> 1 | O48: =IF(L48=1,M48, "") | AT48: 225 | AU48: =RADIANS(Tabla9[[#This Row],[Angle º]]) -> 3.9269908 | AV48: =$F$3*SIN(AU48)+ dD -> 12.82827 | AW48: =$F$3*COS(AU48)+ dP -> 4.7612945 | AX48: =$F$3*SIN(AU48)+ dH -> 3.0698378 | AY48: =$F$3*COS(AU48)+ dD -> 12.82827
M49: =IF(L49<>"",SQRT(4*(C49-dD)^2+(D49-dP)^2+(E49-dH)^2),0) -> 0 | N49: =IF(L49=1,IF(M49<R_,1,EXP(R_-M49)),IF(L49<>"",IF(M49<R_,EXP(M49-R_),1),1)) -> 1 | O49: =IF(L49=1,M49, "") | AT49: 230 | AU49: =RADIANS(Tabla9[[#This Row],[Angle º]]) -> 4.0142573 | AV49: =$F$3*SIN(AU49)+ dD -> 12.411662 | AW49: =$F$3*COS(AU49)+ dP -> 5.2159424 | AX49: =$F$3*SIN(AU49)+ dH -> 2.6532299 | AY49: =$F$3*COS(AU49)+ dD -> 13.282918
...

Sheet HSP 2 Spheres
D1: HSP Sphere | K1: Scaling | L1: 1000000 | O1: Good | P1: =COUNTIF(L19:L113,1) -> 26 | BE1: Outliers | BJ1: Good Solv | BO1: Bad Solv
C2: dD | D2: dP | E2: dH | F2: R | K2: Fit | L2: =R105*L1 -> 898457.22 | O2: Bad | P2: =COUNTIF(L19:L113,0) -> 23 | AT2: Angle º | AU2: Rad | AV2: dD (y) | AW2: dP (x) | AX2: dH (y) | AY2: dD (x) | AZ2: dD (y)2 | BA2: dP (x)3 | BB2: dH (y)4 | BC2: dD (x)5 | BF2: dD | BG2: dP | BH2: dH | BK2: dD | BL2: dP | BM2: dH | BP2: dD | BQ2: dP | BR2: dH
B3: Esfera 1 | C3: 15.153332 | D3: 3.8117289 | E3: 8.7640384 | F3: 5.8241036 | K3: Fit % | L3: =L2/L1 -> 0.89845722 | O3: Total | P3: =P1+P2 -> 49 | AT3: 0 | AU3: =RADIANS(Tabla911[[#This Row],[Angle º]]) -> 0 | AV3: =$F$3*SIN(AU3)+ dD -> 15.153332 | AW3: =$F$3*COS(AU3)+ dP -> 9.6358325 | AX3: =$F$3*SIN(AU3)+ dH -> 8.7640384 | AY3: =$F$3*COS(AU3)+ dD -> 20.977435 | AZ3: =$F$4*SIN(AU3)+ $C$4 -> 17.755701 | BA3: =$F$4*COS(AU3)+ $D$4 -> 16.681514 | BB3: =$F$4*SIN(AU3)+ $E$4 -> 8.1717074 | BC3: =$F$4*COS(AU3)+ $C$4 -> 23.013728 | BE3: {=_xlfn._xlws.FILTER(Tabla48[[Solvents]:[dH]],Tabla48[AUX], "TODOS SON FALSOS")} -> Ethylenediamine | BF3: 16.6 | BG3: 8.8 | BH3: 17 | BJ3: {=_xlfn._xlws.FILTER(Tabla48[[Solvents]:[dH]],Tabla48[AUX2]=1, "TODOS SON FALSOS")} -> Acetic Anhydride | BK3: 16 | BL3: 11.7 | BM3: 10.2 | BO3: {=_xlfn._xlws.FILTER(Tabla48[[Solvents]:[dH]],Tabla48[AUX2]=0, "TODOS SON FALSOS")} -> Aniline | BP3: 20.1 | BQ3: 5.8 | BR3: 11.2
B4: Esfera 2 | C4: 17.755701 | D4: 11.423488 | E4: 8.1717074 | F4: 5.2580269 | AT4: 5 | AU4: =RADIANS(Tabla911[[#This Row],[Angle º]]) -> 0.087266463 | AV4: =$F$3*SIN(AU4)+ dD -> 15.660936 | AW4: =$F$3*COS(AU4)+ dP -> 9.61367 | AX4: =$F$3*SIN(AU4)+ dH -> 9.2716424 | AY4: =$F$3*COS(AU4)+ dD -> 20.955273 | AZ4: =$F$4*SIN(AU4)+ $C$4 -> 18.213969 | BA4: =$F$4*COS(AU4)+ $D$4 -> 16.661506 | BB4: =$F$4*SIN(AU4)+ $E$4 -> 8.6299746 | BC4: =$F$4*COS(AU4)+ $C$4 -> 22.99372 | BE4: Furfural | BF4: 18.6 | BG4: 14.9 | BH4: 5.1 | BJ4: Acetone | BK4: 15.5 | BL4: 10.4 | BM4: 7 | BO4: Benzene | BP4: 18.4 | BQ4: 0 | BR4: 2
K5: Use Excel Solver to Maximise K6 | O5: Wrong Out | P5: =COUNTIF(Tabla48[WI/WO],"WO") -> 1 | AT5: 10 | AU5: =RADIANS(Tabla911[[#This Row],[Angle º]]) -> 0.17453293 | AV5: =$F$3*SIN(AU5)+ dD -> 16.164677 | AW5: =$F$3*COS(AU5)+ dP -> 9.5473513 | AX5: =$F$3*SIN(AU5)+ dH -> 9.7753833 | AY5: =$F$3*COS(AU5)+ dD -> 20.888954 | AZ5: =$F$4*SIN(AU5)+ $C$4 -> 18.668748 | BA5: =$F$4*COS(AU5)+ $D$4 -> 16.601633 | BB5: =$F$4*SIN(AU5)+ $E$4 -> 9.0847542 | BC5: =$F$4*COS(AU5)+ $C$4 -> 22.933847 | BE5: Dimethyl Maleate | BF5: 16.3 | BG5: 8.3 | BH5: 9.8 | BJ5: Acetophenone | BK5: 18.8 | BL5: 9 | BM5: 4 | BO5: Carbon Tetrachloride (0 Dipole Moment) | BP5: 17.8 | BQ5: 0 | BR5: 0.6
C6: Solvents used: | E6: =COUNT(L19:L104) -> 49 | K6: Function | L6: =(R_^(-1/E6))*(F4^(-1/E6))*R105 -> 0.83785683 | O6: Wrong In | P6: =COUNTIF(Tabla48[WI/WO],"WI") -> 2 | AT6: 15 | AU6: =RADIANS(Tabla911[[#This Row],[Angle º]]) -> 0.26179939 | AV6: =$F$3*SIN(AU6)+ dD -> 16.660721 | AW6: =$F$3*COS(AU6)+ dP -> 9.437381 | AX6: =$F$3*SIN(AU6)+ dH -> 10.271427 | AY6: =$F$3*COS(AU6)+ dD -> 20.778984 | AZ6: =$F$4*SIN(AU6)+ $C$4 -> 19.116579 | BA6: =$F$4*COS(AU6)+ $D$4 -> 16.502351 | BB6: =$F$4*SIN(AU6)+ $E$4 -> 9.5325849 | BC6: =$F$4*COS(AU6)+ $C$4 -> 22.834565 | BJ6: Acetylacetone | BK6: 16.1 | BL6: 10 | BM6: 6.2 | BO6: Chloroform | BP6: 17.8 | BQ6: 3.1 | BR6: 5.7
AT7: 20 | AU7: =RADIANS(Tabla911[[#This Row],[Angle º]]) -> 0.34906585 | AV7: =$F$3*SIN(AU7)+ dD -> 17.145292 | AW7: =$F$3*COS(AU7)+ dP -> 9.2845961 | AX7: =$F$3*SIN(AU7)+ dH -> 10.755999 | AY7: =$F$3*COS(AU7)+ dD -> 20.626199 | AZ7: =$F$4*SIN(AU7)+ $C$4 -> 19.554052 | BA7: =$F$4*COS(AU7)+ $D$4 -> 16.364417 | BB7: =$F$4*SIN(AU7)+ $E$4 -> 9.9700585 | BC7: =$F$4*COS(AU7)+ $C$4 -> 22.69663 | BJ7: Acrylonitrile | BK7: 16 | BL7: 12.8 | BM7: 6.8 | BO7: Cyclohexane | BP7: 16.8 | BQ7: 0 | BR7: 0.2
AT8: 25 | AU8: =RADIANS(Tabla911[[#This Row],[Angle º]]) -> 0.43633231 | AV8: =$F$3*SIN(AU8)+ dD -> 17.614704 | AW8: =$F$3*COS(AU8)+ dP -> 9.0901593 | AX8: =$F$3*SIN(AU8)+ dH -> 11.225411 | AY8: =$F$3*COS(AU8)+ dD -> 20.431762 | AZ8: =$F$4*SIN(AU8)+ $C$4 -> 19.97784 | BA8: =$F$4*COS(AU8)+ $D$4 -> 16.188878 | BB8: =$F$4*SIN(AU8)+ $E$4 -> 10.393846 | BC8: =$F$4*COS(AU8)+ $C$4 -> 22.521092 | BJ8: γ-Butyrolactone (GBL) | BK8: 18 | BL8: 16.6 | BM8: 7.4 | BO8: Cyclohexanol | BP8: 17.4 | BQ8: 4.1 | BR8: 13.5
B9: Solvents | C9: dD | D9: dP | E9: dH | L9: Score | AT9: 30 | AU9: =RADIANS(Tabla911[[#This Row],[Angle º]]) -> 0.52359878 | AV9: =$F$3*SIN(AU9)+ dD -> 18.065383 | AW9: =$F$3*COS(AU9)+ dP -> 8.8555505 | AX9: =$F$3*SIN(AU9)+ dH -> 11.67609 | AY9: =$F$3*COS(AU9)+ dD -> 20.197153 | AZ9: =$F$4*SIN(AU9)+ $C$4 -> 20.384715 | BA9: =$F$4*COS(AU9)+ $D$4 -> 15.977072 | BB9: =$F$4*SIN(AU9)+ $E$4 -> 10.800721 | BC9: =$F$4*COS(AU9)+ $C$4 -> 22.309286 | BJ9: Diacetone Alcohol | BK9: 15.8 | BL9: 8.2 | BM9: 10.8 | BO9: Trans-Decahydronaphthalene | BP9: 18 | BQ9: 0 | BR9: 0
L10: 1 | AT10: 35 | AU10: =RADIANS(Tabla911[[#This Row],[Angle º]]) -> 0.61086524 | AV10: =$F$3*SIN(AU10)+ dD -> 18.4939 | AW10: =$F$3*COS(AU10)+ dP -> 8.5825552 | AX10: =$F$3*SIN(AU10)+ dH -> 12.104607 | AY10: =$F$3*COS(AU10)+ dD -> 19.924158 | AZ10: =$F$4*SIN(AU10)+ $C$4 -> 20.771582 | BA10: =$F$4*COS(AU10)+ $D$4 -> 15.730611 | BB10: =$F$4*SIN(AU10)+ $E$4 -> 11.187588 | BC10: =$F$4*COS(AU10)+ $C$4 -> 22.062825 | BJ10: Diethyl Carbonate | BK10: 15.1 | BL10: 6.3 | BM10: 3.5 | BO10: Diethylene Glycol Monomethyl Ether | BP10: 16.2 | BQ10: 7.8 | BR10: 12.6
B11: Max | C11: =DMAX(A18:L104,"dD",$B$9:$L$10) -> 19 | D11: =DMAX(B18:M104,"dP",$B$9:$L$10) -> 16.6 | E11: =DMAX(C18:N104,"dH",$B$9:$L$10) -> 17 | AT11: 40 | AU11: =RADIANS(Tabla911[[#This Row],[Angle º]]) -> 0.6981317 | AV11: =$F$3*SIN(AU11)+ dD -> 18.896993 | AW11: =$F$3*COS(AU11)+ dP -> 8.2732511 | AX11: =$F$3*SIN(AU11)+ dH -> 12.5077 | AY11: =$F$3*COS(AU11)+ dD -> 19.614854 | AZ11: =$F$4*SIN(AU11)+ $C$4 -> 21.135496 | BA11: =$F$4*COS(AU11)+ $D$4 -> 15.45137 | BB11: =$F$4*SIN(AU11)+ $E$4 -> 11.551502 | BC11: =$F$4*COS(AU11)+ $C$4 -> 21.783584 | BJ11: N,N-Dimethyl Acetamide | BK11: 16.8 | BL11: 11.5 | BM11: 9.4 | BO11: Ethanol | BP11: 15.8 | BQ11: 8.8 | BR11: 19.4
B12: Min | C12: =DMIN(A18:L104,"dD",$B$9:$L$10) -> 15.1 | D12: =DMIN(B18:M104,"dP",$B$9:$L$10) -> 1.8 | E12: =DMIN(C18:N104,"dH",$B$9:$L$10) -> 3.5 | AT12: 45 | AU12: =RADIANS(Tabla911[[#This Row],[Angle º]]) -> 0.78539816 | AV12: =$F$3*SIN(AU12)+ dD -> 19.271595 | AW12: =$F$3*COS(AU12)+ dP -> 7.929992 | AX12: =$F$3*SIN(AU12)+ dH -> 12.882302 | AY12: =$F$3*COS(AU12)+ dD -> 19.271595 | AZ12: =$F$4*SIN(AU12)+ $C$4 -> 21.473688 | BA12: =$F$4*COS(AU12)+ $D$4 -> 15.141474 | BB12: =$F$4*SIN(AU12)+ $E$4 -> 11.889694 | BC12: =$F$4*COS(AU12)+ $C$4 -> 21.473688 | BJ12: Dimethyl Formamide (DMF) | BK12: 17.4 | BL12: 13.7 | BM12: 11.3 | BO12: Ethyl Benzene | BP12: 17.8 | BQ12: 0.6 | BR12: 1.4
B13: Delta | C13: =C11-C12 -> 3.9 | D13: =D11-D12 -> 14.8 | E13: =E11-E12 -> 13.5 | AT13: 50 | AU13: =RADIANS(Tabla911[[#This Row],[Angle º]]) -> 0.87266463 | AV13: =$F$3*SIN(AU13)+ dD -> 19.614854 | AW13: =$F$3*COS(AU13)+ dP -> 7.5553905 | AX13: =$F$3*SIN(AU13)+ dH -> 13.225561 | AY13: =$F$3*COS(AU13)+ dD -> 18.896993 | AZ13: =$F$4*SIN(AU13)+ $C$4 -> 21.783584 | BA13: =$F$4*COS(AU13)+ $D$4 -> 14.803282 | BB13: =$F$4*SIN(AU13)+ $E$4 -> 12.19959 | BC13: =$F$4*COS(AU13)+ $C$4 -> 21.135496 | BJ13: 1,4-Dioxane | BK13: 17.5 | BL13: 1.8 | BM13: 9 | BO13: 1,2-Dibromoethylene | BP13: 17 | BQ13: 4.9 | BR13: 3
B14: Substance Coordinates | C14: =C11-C13/2 -> 17.05 | D14: =D11-D13/2 -> 9.2 | E14: =E11-E13/2 -> 10.25 | AT14: 55 | AU14: =RADIANS(Tabla911[[#This Row],[Angle º]]) -> 0.95993109 | AV14: =$F$3*SIN(AU14)+ dD -> 19.924158 | AW14: =$F$3*COS(AU14)+ dP -> 7.1522975 | AX14: =$F$3*SIN(AU14)+ dH -> 13.534865 | AY14: =$F$3*COS(AU14)+ dD -> 18.4939 | AZ14: =$F$4*SIN(AU14)+ $C$4 -> 22.062825 | BA14: =$F$4*COS(AU14)+ $D$4 -> 14.439368 | BB14: =$F$4*SIN(AU14)+ $E$4 -> 12.478831 | BC14: =$F$4*COS(AU14)+ $C$4 -> 20.771582 | BJ14: Ethyl Acetate | BK14: 15.8 | BL14: 5.3 | BM14: 7.2 | BO14: Formaldehyde | BP14: 12.8 | BQ14: 14.4 | BR14: 15.4
AT15: 60 | AU15: =RADIANS(Tabla911[[#This Row],[Angle º]]) -> 1.0471976 | AV15: =$F$3*SIN(AU15)+ dD -> 20.197153 | AW15: =$F$3*COS(AU15)+ dP -> 6.7237807 | AX15: =$F$3*SIN(AU15)+ dH -> 13.80786 | AY15: =$F$3*COS(AU15)+ dD -> 18.065383 | AZ15: =$F$4*SIN(AU15)+ $C$4 -> 22.309286 | BA15: =$F$4*COS(AU15)+ $D$4 -> 14.052501 | BB15: =$F$4*SIN(AU15)+ $E$4 -> 12.725292 | BC15: =$F$4*COS(AU15)+ $C$4 -> 20.384715 | BJ15: Ethylenediamine | BK15: 16.6 | BL15: 8.8 | BM15: 17 | BO15: Formic Acid | BP15: 14.6 | BQ15: 10 | BR15: 14
AT16: 65 | AU16: =RADIANS(Tabla911[[#This Row],[Angle º]]) -> 1.134464 | AV16: =$F$3*SIN(AU16)+ dD -> 20.431762 | AW16: =$F$3*COS(AU16)+ dP -> 6.2731014 | AX16: =$F$3*SIN(AU16)+ dH -> 14.042469 | AY16: =$F$3*COS(AU16)+ dD -> 17.614704 | AZ16: =$F$4*SIN(AU16)+ $C$4 -> 22.521092 | BA16: =$F$4*COS(AU16)+ $D$4 -> 13.645626 | BB16: =$F$4*SIN(AU16)+ $E$4 -> 12.937098 | BC16: =$F$4*COS(AU16)+ $C$4 -> 19.97784 | BJ16: Isoamyl Acetate | BK16: 15.3 | BL16: 3.1 | BM16: 7 | BO16: Furfural | BP16: 18.6 | BQ16: 14.9 | BR16: 5.1
M17: Sphere 1 | O17: Sphere 2 | AT17: 70 | AU17: =RADIANS(Tabla911[[#This Row],[Angle º]]) -> 1.2217305 | AV17: =$F$3*SIN(AU17)+ dD -> 20.626199 | AW17: =$F$3*COS(AU17)+ dP -> 5.8036896 | AX17: =$F$3*SIN(AU17)+ dH -> 14.236906 | AY17: =$F$3*COS(AU17)+ dD -> 17.145292 | AZ17: =$F$4*SIN(AU17)+ $C$4 -> 22.69663 | BA17: =$F$4*COS(AU17)+ $D$4 -> 13.221839 | BB17: =$F$4*SIN(AU17)+ $E$4 -> 13.112636 | BC17: =$F$4*COS(AU17)+ $C$4 -> 19.554052 | BJ17: Isophorone | BK17: 17 | BL17: 8 | BM17: 5 | BO17: Hexane | BP17: 14.9 | BQ17: 0 | BR17: 0
A18: CAS | B18: Solvents | C18: dD | D18: dP | E18: dH | F18: MVol | G18: WI/WO | H18: AUX | I18: AUX2 | J18: RED | K18: RED 2 | L18: Score | M18: Distance | N18: Error | O18: Distance | P18: Error | R18: Error Total | AT18: 75 | AU18: =RADIANS(Tabla911[[#This Row],[Angle º]]) -> 1.3089969 | AV18: =$F$3*SIN(AU18)+ dD -> 20.778984 | AW18: =$F$3*COS(AU18)+ dP -> 5.3191178 | AX18: =$F$3*SIN(AU18)+ dH -> 14.38969 | AY18: =$F$3*COS(AU18)+ dD -> 16.660721 | AZ18: =$F$4*SIN(AU18)+ $C$4 -> 22.834565 | BA18: =$F$4*COS(AU18)+ $D$4 -> 12.784365 | BB18: =$F$4*SIN(AU18)+ $E$4 -> 13.250571 | BC18: =$F$4*COS(AU18)+ $C$4 -> 19.116579 | BJ18: Methyl Acetate | BK18: 15.5 | BL18: 7.2 | BM18: 7.6 | BO18: Methanol | BP18: 14.7 | BQ18: 12.3 | BR18: 22.3
A19: 108-24-7 | B19: =VLOOKUP(Tabla48[[#This Row],[CAS]],Tabla1[],2,FALSE) -> Acetic Anhydride | C19: =VLOOKUP(Tabla48[[#This Row],[CAS]],Tabla1[],3,FALSE) -> 16 | D19: =VLOOKUP(Tabla48[[#This Row],[CAS]],Tabla1[],4,FALSE) -> 11.7 | E19: =VLOOKUP(Tabla48[[#This Row],[CAS]],Tabla1[],5,FALSE) -> 10.2 | F19: =VLOOKUP(Tabla48[[#This Row],[CAS]],Tabla1[],6,FALSE) | G19: =IF(L19=1,IF(OR(J19<=1,K19<=1),"","WO"),IF(L19=0,IF(OR(J19<1,K19<1),"WI",""),"")) | H19: =ISNUMBER(SEARCH("w",Tabla48[[#This Row],[WI/WO]])) -> FALSE | I19: =L19 -> 1 | J19: =IF(L19<>"",M19/R_,"") -> 1.4070434 | K19: =IF(L19<>"",O19/$F$4,"") -> 0.77301371 | L19: 1 | M19: =IF(L19<>"",SQRT(4*(C19-dD)^2+(D19-dP)^2+(E19-dH)^2),0) -> 8.1947664 | N19: =IF(L19=1,IF(M19<R_,1,EXP(R_-M19)),IF(L19<>"",IF(M19<R_,EXP(M19-R_),1),1)) -> 0.093418785 | O19: =IF(L19<>"",SQRT(4*(C19-$C$4)^2+(D19-$D$4)^2+(E19-$E$4)^2),0) -> 4.0645269 | P19: =IF(L19=1,IF(O19<$F$4,1,EXP($F$4-O19)),IF(L19<>"",IF(O19<$F$4,EXP(O19-$F$4),1),1)) -> 1 | R19: =IF(L19="",1,IF(AND(L19=1,OR(N19=1,P19=1)),1,MIN((N19), (P19)))) -> 1 | AT19: 80 | AU19: =RADIANS(Tabla911[[#This Row],[Angle º]]) -> 1.3962634 | AV19: =$F$3*SIN(AU19)+ dD -> 20.888954 | AW19: =$F$3*COS(AU19)+ dP -> 4.8230739 | AX19: =$F$3*SIN(AU19)+ dH -> 14.499661 | AY19: =$F$3*COS(AU19)+ dD -> 16.164677 | AZ19: =$F$4*SIN(AU19)+ $C$4 -> 22.933847 | BA19: =$F$4*COS(AU19)+ $D$4 -> 12.336534 | BB19: =$F$4*SIN(AU19)+ $E$4 -> 13.349853 | BC19: =$F$4*COS(AU19)+ $C$4 -> 18.668748 | BJ19: Methyl Acrylate | BK19: 15.3 | BL19: 6.7 | BM19: 9.4 | BO19: Nitrobenzene | BP19: 20 | BQ19: 10.6 | BR19: 3.1
A20: 67-64-1 | B20: =VLOOKUP(Tabla48[[#This Row],[CAS]],Tabla1[],2,FALSE) -> Acetone | C20: =VLOOKUP(Tabla48[[#This Row],[CAS]],Tabla1[],3,FALSE) -> 15.5 | D20: =VLOOKUP(Tabla48[[#This Row],[CAS]],Tabla1[],4,FALSE) -> 10.4 | E20: =VLOOKUP(Tabla48[[#This Row],[CAS]],Tabla1[],5,FALSE) -> 7 | F20: =VLOOKUP(Tabla48[[#This Row],[CAS]],Tabla1[],6,FALSE) -> 73.8 | G20: =IF(L20=1,IF(OR(J20<=1,K20<=1),"","WO"),IF(L20=0,IF(OR(J20<1,K20<1),"WI",""),"")) | H20: =ISNUMBER(SEARCH("w",Tabla48[[#This Row],[WI/WO]])) -> FALSE | I20: =L20 -> 1 | J20: =IF(L20<>"",M20/R_,"") -> 1.1770908 | K20: =IF(L20<>"",O20/$F$4,"") -> 0.90758859 | L20: 1 | M20: =IF(L20<>"",SQRT(4*(C20-dD)^2+(D20-dP)^2+(E20-dH)^2),0) -> 6.8554988 | N20: =IF(L20=1,IF(M20<R_,1,EXP(R_-M20)),IF(L20<>"",IF(M20<R_,EXP(M20-R_),1),1)) -> 0.35650921 | O20: =IF(L20<>"",SQRT(4*(C20-$C$4)^2+(D20-$D$4)^2+(E20-$E$4)^2),0) -> 4.7721252 | P20: =IF(L20=1,IF(O20<$F$4,1,EXP($F$4-O20)),IF(L20<>"",IF(O20<$F$4,EXP(O20-$F$4),1),1)) -> 1 | R20: =IF(L20="",1,IF(AND(L20=1,OR(N20=1,P20=1)),1,MIN((N20), (P20)))) -> 1 | AT20: 85 | AU20: =RADIANS(Tabla911[[#This Row],[Angle º]]) -> 1.4835299 | AV20: =$F$3*SIN(AU20)+ dD -> 20.955273 | AW20: =$F$3*COS(AU20)+ dP -> 4.319333 | AX20: =$F$3*SIN(AU20)+ dH -> 14.565979 | AY20: =$F$3*COS(AU20)+ dD -> 15.660936 | AZ20: =$F$4*SIN(AU20)+ $C$4 -> 22.99372 | BA20: =$F$4*COS(AU20)+ $D$4 -> 11.881755 | BB20: =$F$4*SIN(AU20)+ $E$4 -> 13.409726 | BC20: =$F$4*COS(AU20)+ $C$4 -> 18.213969 | BJ20: Methyl Ethyl Ketone (MEK) | BK20: 16 | BL20: 9 | BM20: 5.1 | BO20: Toluene | BP20: 18 | BQ20: 1.4 | BR20: 2
A21: 98-86-2 | B21: =VLOOKUP(Tabla48[[#This Row],[CAS]],Tabla1[],2,FALSE) -> Acetophenone | C21: =VLOOKUP(Tabla48[[#This Row],[CAS]],Tabla1[],3,FALSE) -> 18.8 | D21: =VLOOKUP(Tabla48[[#This Row],[CAS]],Tabla1[],4,FALSE) -> 9 | E21: =VLOOKUP(Tabla48[[#This Row],[CAS]],Tabla1[],5,FALSE) -> 4 | F21: =VLOOKUP(Tabla48[[#This Row],[CAS]],Tabla1[],6,FALSE) | G21: =IF(L21=1,IF(OR(J21<=1,K21<=1),"","WO"),IF(L21=0,IF(OR(J21<1,K21<1),"WI",""),"")) | H21: =ISNUMBER(SEARCH("w",Tabla48[[#This Row],[WI/WO]])) -> FALSE | I21: =L21 -> 1 | J21: =IF(L21<>"",M21/R_,"") -> 1.7409336 | K21: =IF(L21<>"",O21/$F$4,"") -> 0.99985217 | L21: 1 | M21: =IF(L21<>"",SQRT(4*(C21-dD)^2+(D21-dP)^2+(E21-dH)^2),0) -> 10.139378 | N21: =IF(L21=1,IF(M21<R_,1,EXP(R_-M21)),IF(L21<>"",IF(M21<R_,EXP(M21-R_),1),1)) -> 0.013362885 | O21: =IF(L21<>"",SQRT(4*(C21-$C$4)^2+(D21-$D$4)^2+(E21-$E$4)^2),0) -> 5.2572496 | P21: =IF(L21=1,IF(O21<$F$4,1,EXP($F$4-O21)),IF(L21<>"",IF(O21<$F$4,EXP(O21-$F$4),1),1)) -> 1 | R21: =IF(L21="",1,IF(AND(L21=1,OR(N21=1,P21=1)),1,MIN((N21), (P21)))) -> 1 | AT21: 90 | AU21: =RADIANS(Tabla911[[#This Row],[Angle º]]) -> 1.5707963 | AV21: =$F$3*SIN(AU21)+ dD -> 20.977435 | AW21: =$F$3*COS(AU21)+ dP -> 3.8117289 | AX21: =$F$3*SIN(AU21)+ dH -> 14.588142 | AY21: =$F$3*COS(AU21)+ dD -> 15.153332 | AZ21: =$F$4*SIN(AU21)+ $C$4 -> 23.013728 | BA21: =$F$4*COS(AU21)+ $D$4 -> 11.423488 | BB21: =$F$4*SIN(AU21)+ $E$4 -> 13.429734 | BC21: =$F$4*COS(AU21)+ $C$4 -> 17.755701 | BJ21: Methyl Isobutyl Ketone (MIBK) | BK21: 15.3 | BL21: 6.1 | BM21: 4.1 | BO21: Trichloroethylene | BP21: 18 | BQ21: 3.1 | BR21: 5.3
A22: 123-54-6 | B22: =VLOOKUP(Tabla48[[#This Row],[CAS]],Tabla1[],2,FALSE) -> Acetylacetone | C22: =VLOOKUP(Tabla48[[#This Row],[CAS]],Tabla1[],3,FALSE) -> 16.1 | D22: =VLOOKUP(Tabla48[[#This Row],[CAS]],Tabla1[],4,FALSE) -> 10 | E22: =VLOOKUP(Tabla48[[#This Row],[CAS]],Tabla1[],5,FALSE) -> 6.2 | F22: =VLOOKUP(Tabla48[[#This Row],[CAS]],Tabla1[],6,FALSE) | G22: =IF(L22=1,IF(OR(J22<=1,K22<=1),"","WO"),IF(L22=0,IF(OR(J22<1,K22<1),"WI",""),"")) | H22: =ISNUMBER(SEARCH("w",Tabla48[[#This Row],[WI/WO]])) -> FALSE | I22: =L22 -> 1 | J22: =IF(L22<>"",M22/R_,"") -> 1.1951831 | K22: =IF(L22<>"",O22/$F$4,"") -> 0.78136662 | L22: 1 | M22: =IF(L22<>"",SQRT(4*(C22-dD)^2+(D22-dP)^2+(E22-dH)^2),0) -> 6.9608704 | N22: =IF(L22=1,IF(M22<R_,1,EXP(R_-M22)),IF(L22<>"",IF(M22<R_,EXP(M22-R_),1),1)) -> 0.32085473 | O22: =IF(L22<>"",SQRT(4*(C22-$C$4)^2+(D22-$D$4)^2+(E22-$E$4)^2),0) -> 4.1084467 | P22: =IF(L22=1,IF(O22<$F$4,1,EXP($F$4-O22)),IF(L22<>"",IF(O22<$F$4,EXP(O22-$F$4),1),1)) -> 1 | R22: =IF(L22="",1,IF(AND(L22=1,OR(N22=1,P22=1)),1,MIN((N22), (P22)))) -> 1 | AT22: 95 | AU22: =RADIANS(Tabla911[[#This Row],[Angle º]]) -> 1.6580628 | AV22: =$F$3*SIN(AU22)+ dD -> 20.955273 | AW22: =$F$3*COS(AU22)+ dP -> 3.3041248 | AX22: =$F$3*SIN(AU22)+ dH -> 14.565979 | AY22: =$F$3*COS(AU22)+ dD -> 14.645728 | AZ22: =$F$4*SIN(AU22)+ $C$4 -> 22.99372 | BA22: =$F$4*COS(AU22)+ $D$4 -> 10.96522 | BB22: =$F$4*SIN(AU22)+ $E$4 -> 13.409726 | BC22: =$F$4*COS(AU22)+ $C$4 -> 17.297434 | BJ22: Pyridine | BK22: 19 | BL22: 8.8 | BM22: 5.9 | BO22: 2,2,4-Trimethylpentane | BP22: 14.1 | BQ22: 0 | BR22: 0
