Workbook

Sheet Theory
A1: Solvents are represented as points in a three dimensional space called HSP space. This is because there are three parameters (δD, δP, and δH) that are required to describe where they like - or dislike - being found. What they dissolve, or like to be together with, will have similar HSP. It has been found that perfect HSP matches are not required for complete solubility, however.
A2: The HSP Distance between two molecules, conventionally called Ra, is the measure of how alike they are. The smaller Ra, the more likely they are to be compatible. The famous formula, used for nearly 50 years is:
A3: Ra² = 4(δD1-δD2)² + (δP1-δP2)² + (δH1-δH2)²
A4: If from measurements of "good" and "bad" solvents you can define a sphere of radius Ro which contains all the good solvents, then you can define a Relative Energy Difference, RED, which tells you where you are in solubility space:
A5: RED = Ra/Ro
A6: If:
A7: - RED < 1 the molecules are alike and will dissolve
A8: - RED = 1 the system will partially dissolve
A9: - RED > 1 the system will not dissolve
A11: References:
A12: Official site of HSP
A13: Wikipedia

Sheet HSP
A1: NXTLEVVEL SOLVENTS* | B1: DISPERSION | C1: POLAR | D1: HYDROGEN | E1: Ro
A2: Ethyl levulinate | B2: 14.6 | C2: 10.46 | D2: 6.98 | E2: 16.3
A3: Butyl levulinate | B3: 15.69 | C3: 9.66 | D3: 5.82 | E3: 13.5
A4: EtLPK | B4: 15.17 | C4: 4.68 | D4: 6.8 | E4: 15.9
A5: EtLGK | B5: 15.27 | C5: 12.72 | D5: 10.93 | E5: 13.7
A6: EHL | B6: 15.27 | C6: 6.43 | D6: 3.85 | E6: 14.8
A7: *Values by VLCI

Sheet API + Cosmetic Actives
A1: ACTIVE INGREDIENT | B1: HSP | E1: Ro | F1: Mvol | G1: DISTANCE TO | L1: RED TO (BASED ON Ro OF THE ACTIVE INGREDIENT) | Q1: RED TO (BASED ON Ro OF NXTLEVVEL SOLVENT)
B2: D | C2: P | D2: H | G2: ETHYL LEVULINATE | H2: BUTYL LEVULINATE | I2: EtLPK | J2: EtLGK | K2: EHL | L2: ETHYL LEVULINATE | M2: BUTYL LEVULINATE | N2: EtLPK | O2: EtLGK | P2: EHL | Q2: ETHYL LEVULINATE | R2: BUTYL LEVULINATE | S2: EtLPK | T2: EtLGK | U2: EHL
A3: Aspirin | B3: 19 | C3: 6.7 | D3: 10.1 | E3: - | F3: 139.6 | G3: =SQRT((4*(HSP!$B$2-$B3)^2+(HSP!$C$2-$C3)^2+(HSP!$D$2-$D3)^2)) -> 10.065386 | H3: =SQRT((4*(HSP!$B$3-$B3)^2+(HSP!$C$3-$C3)^2+(HSP!$D$3-$D3)^2)) -> 8.420475 | I3: =SQRT((4*(HSP!$B$4-$B3)^2+(HSP!$C$4-$C3)^2+(HSP!$D$4-$D3)^2)) -> 8.5817248 | J3: =SQRT((4*(HSP!$B$5-$B3)^2+(HSP!$C$5-$C3)^2+(HSP!$D$5-$D3)^2)) -> 9.6218969 | K3: =SQRT((4*(HSP!$B$6-$B3)^2+(HSP!$C$6-$C3)^2+(HSP!$D$6-$D3)^2)) -> 9.7358615 | L3: - | M3: - | N3: - | O3: - | P3: - | Q3: =$G3/HSP!$E$2 -> 0.61750836 | R3: =$H3/HSP!$E$3 -> 0.62373889 | S3: =$I3/HSP!$E$4 -> 0.53973112 | T3: =$J3/HSP!$E$5 -> 0.70232824 | U3: =$K3/HSP!$E$6 -> 0.65782848
A4: Benzophenone | B4: 19.5 | C4: 7.2 | D4: 5.1 | E4: - | F4: 167.9 | G4: =SQRT((4*(HSP!$B$2-$B4)^2+(HSP!$C$2-$C4)^2+(HSP!$D$2-$D4)^2)) -> 10.497714 | H4: =SQRT((4*(HSP!$B$3-$B4)^2+(HSP!$C$3-$C4)^2+(HSP!$D$3-$D4)^2)) -> 8.0395522 | I4: =SQRT((4*(HSP!$B$4-$B4)^2+(HSP!$C$4-$C4)^2+(HSP!$D$4-$D4)^2)) -> 9.1780172 | J4: =SQRT((4*(HSP!$B$5-$B4)^2+(HSP!$C$5-$C4)^2+(HSP!$D$5-$D4)^2)) -> 11.663229 | K4: =SQRT((4*(HSP!$B$6-$B4)^2+(HSP!$C$6-$C4)^2+(HSP!$D$6-$D4)^2)) -> 8.5864428 | L4: - | M4: - | N4: - | O4: - | P4: - | Q4: =$G4/HSP!$E$2 -> 0.64403154 | R4: =$H4/HSP!$E$3 -> 0.59552239 | S4: =$I4/HSP!$E$4 -> 0.57723379 | T4: =$J4/HSP!$E$5 -> 0.85133055 | U4: =$K4/HSP!$E$6 -> 0.58016505
A5: Benzophenone-1 | B5: 20.5 | C5: 9.9 | D5: 15.4 | E5: - | F5: 172 | G5: =SQRT((4*(HSP!$B$2-$B5)^2+(HSP!$C$2-$C5)^2+(HSP!$D$2-$D5)^2)) -> 14.506895 | H5: =SQRT((4*(HSP!$B$3-$B5)^2+(HSP!$C$3-$C5)^2+(HSP!$D$3-$D5)^2)) -> 13.578601 | I5: =SQRT((4*(HSP!$B$4-$B5)^2+(HSP!$C$4-$C5)^2+(HSP!$D$4-$D5)^2)) -> 14.657558 | J5: =SQRT((4*(HSP!$B$5-$B5)^2+(HSP!$C$5-$C5)^2+(HSP!$D$5-$D5)^2)) -> 11.719424 | K5: =SQRT((4*(HSP!$B$6-$B5)^2+(HSP!$C$6-$C5)^2+(HSP!$D$6-$D5)^2)) -> 15.964179 | L5: - | M5: - | N5: - | O5: - | P5: - | Q5: =$G5/HSP!$E$2 -> 0.88999355 | R5: =$H5/HSP!$E$3 -> 1.0058223 | S5: =$I5/HSP!$E$4 -> 0.92185898 | T5: =$J5/HSP!$E$5 -> 0.85543241 | U5: =$K5/HSP!$E$6 -> 1.0786607
A6: Benzophenone-12 | B6: 18.7 | C6: 6.4 | D6: 7.6 | E6: - | F6: 307.3 | G6: =SQRT((4*(HSP!$B$2-$B6)^2+(HSP!$C$2-$C6)^2+(HSP!$D$2-$D6)^2)) -> 9.1710414 | H6: =SQRT((4*(HSP!$B$3-$B6)^2+(HSP!$C$3-$C6)^2+(HSP!$D$3-$D6)^2)) -> 7.0736412 | I6: =SQRT((4*(HSP!$B$4-$B6)^2+(HSP!$C$4-$C6)^2+(HSP!$D$4-$D6)^2)) -> 7.3104035 | J6: =SQRT((4*(HSP!$B$5-$B6)^2+(HSP!$C$5-$C6)^2+(HSP!$D$5-$D6)^2)) -> 9.904085 | K6: =SQRT((4*(HSP!$B$6-$B6)^2+(HSP!$C$6-$C6)^2+(HSP!$D$6-$D6)^2)) -> 7.81812 | L6: - | M6: - | N6: - | O6: - | P6: - | Q6: =$G6/HSP!$E$2 -> 0.56264058 | R6: =$H6/HSP!$E$3 -> 0.52397342 | S6: =$I6/HSP!$E$4 -> 0.45977381 | T6: =$J6/HSP!$E$5 -> 0.72292591 | U6: =$K6/HSP!$E$6 -> 0.52825135
A7: Benzophenone-2 | B7: 20.5 | C7: 12.1 | D7: 25.3 | E7: - | F7: 179.7 | G7: =SQRT((4*(HSP!$B$2-$B7)^2+(HSP!$C$2-$C7)^2+(HSP!$D$2-$D7)^2)) -> 21.852963 | H7: =SQRT((4*(HSP!$B$3-$B7)^2+(HSP!$C$3-$C7)^2+(HSP!$D$3-$D7)^2)) -> 21.862488 | I7: =SQRT((4*(HSP!$B$4-$B7)^2+(HSP!$C$4-$C7)^2+(HSP!$D$4-$D7)^2)) -> 22.604026 | J7: =SQRT((4*(HSP!$B$5-$B7)^2+(HSP!$C$5-$C7)^2+(HSP!$D$5-$D7)^2)) -> 17.784625 | K7: =SQRT((4*(HSP!$B$6-$B7)^2+(HSP!$C$6-$C7)^2+(HSP!$D$6-$D7)^2)) -> 24.52882 | L7: - | M7: - | N7: - | O7: - | P7: - | Q7: =$G7/HSP!$E$2 -> 1.3406726 | R7: =$H7/HSP!$E$3 -> 1.6194436 | S7: =$I7/HSP!$E$4 -> 1.4216369 | T7: =$J7/HSP!$E$5 -> 1.2981478 | U7: =$K7/HSP!$E$6 -> 1.6573527
A8: Benzophenone-3 | B8: 20.3 | C8: 9.3 | D8: 10.9 | E8: - | F8: 189.9 | G8: =SQRT((4*(HSP!$B$2-$B8)^2+(HSP!$C$2-$C8)^2+(HSP!$D$2-$D8)^2)) -> 12.110822 | H8: =SQRT((4*(HSP!$B$3-$B8)^2+(HSP!$C$3-$C8)^2+(HSP!$D$3-$D8)^2)) -> 10.533015 | I8: =SQRT((4*(HSP!$B$4-$B8)^2+(HSP!$C$4-$C8)^2+(HSP!$D$4-$D8)^2)) -> 11.975892 | J8: =SQRT((4*(HSP!$B$5-$B8)^2+(HSP!$C$5-$C8)^2+(HSP!$D$5-$D8)^2)) -> 10.625484 | K8: =SQRT((4*(HSP!$B$6-$B8)^2+(HSP!$C$6-$C8)^2+(HSP!$D$6-$D8)^2)) -> 12.615189 | L8: - | M8: - | N8: - | O8: - | P8: - | Q8: =$G8/HSP!$E$2 -> 0.74299519 | R8: =$H8/HSP!$E$3 -> 0.78022332 | S8: =$I8/HSP!$E$4 -> 0.75320078 | T8: =$J8/HSP!$E$5 -> 0.77558274 | U8: =$K8/HSP!$E$6 -> 0.85237765
A9: Benzophenone-6 | B9: 20.2 | C9: 10.6 | D9: 15.8 | E9: - | F9: 215.7 | G9: =SQRT((4*(HSP!$B$2-$B9)^2+(HSP!$C$2-$C9)^2+(HSP!$D$2-$D9)^2)) -> 14.256648 | H9: =SQRT((4*(HSP!$B$3-$B9)^2+(HSP!$C$3-$C9)^2+(HSP!$D$3-$D9)^2)) -> 13.484969 | I9: =SQRT((4*(HSP!$B$4-$B9)^2+(HSP!$C$4-$C9)^2+(HSP!$D$4-$D9)^2)) -> 14.739403 | J9: =SQRT((4*(HSP!$B$5-$B9)^2+(HSP!$C$5-$C9)^2+(HSP!$D$5-$D9)^2)) -> 11.199594 | K9: =SQRT((4*(HSP!$B$6-$B9)^2+(HSP!$C$6-$C9)^2+(HSP!$D$6-$D9)^2)) -> 16.044033 | L9: - | M9: - | N9: - | O9: - | P9: - | Q9: =$G9/HSP!$E$2 -> 0.87464096 | R9: =$H9/HSP!$E$3 -> 0.99888662 | S9: =$I9/HSP!$E$4 -> 0.92700648 | T9: =$J9/HSP!$E$5 -> 0.81748859 | U9: =$K9/HSP!$E$6 -> 1.0840563
A10: Benzophenone-7 | B10: 20.8 | C10: 9.3 | D10: 9.8 | E10: - | F10: 180.3 | G10: =SQRT((4*(HSP!$B$2-$B10)^2+(HSP!$C$2-$C10)^2+(HSP!$D$2-$D10)^2)) -> 12.769417 | H10: =SQRT((4*(HSP!$B$3-$B10)^2+(HSP!$C$3-$C10)^2+(HSP!$D$3-$D10)^2)) -> 10.973532 | I10: =SQRT((4*(HSP!$B$4-$B10)^2+(HSP!$C$4-$C10)^2+(HSP!$D$4-$D10)^2)) -> 12.53523 | J10: =SQRT((4*(HSP!$B$5-$B10)^2+(HSP!$C$5-$C10)^2+(HSP!$D$5-$D10)^2)) -> 11.63172 | K10: =SQRT((4*(HSP!$B$6-$B10)^2+(HSP!$C$6-$C10)^2+(HSP!$D$6-$D10)^2)) -> 12.882663 | L10: - | M10: - | N10: - | O10: - | P10: - | Q10: =$G10/HSP!$E$2 -> 0.78339979 | R10: =$H10/HSP!$E$3 -> 0.81285421 | S10: =$I10/HSP!$E$4 -> 0.78837927 | T10: =$J10/HSP!$E$5 -> 0.84903063 | U10: =$K10/HSP!$E$6 -> 0.87045019
A11: Benzophenone-8 | B11: 20.1 | C11: 10.7 | D11: 15.8 | E11: - | F11: 194.1 | G11: =SQRT((4*(HSP!$B$2-$B11)^2+(HSP!$C$2-$C11)^2+(HSP!$D$2-$D11)^2)) -> 14.101418 | H11: =SQRT((4*(HSP!$B$3-$B11)^2+(HSP!$C$3-$C11)^2+(HSP!$D$3-$D11)^2)) -> 13.359431 | I11: =SQRT((4*(HSP!$B$4-$B11)^2+(HSP!$C$4-$C11)^2+(HSP!$D$4-$D11)^2)) -> 14.644453 | J11: =SQRT((4*(HSP!$B$5-$B11)^2+(HSP!$C$5-$C11)^2+(HSP!$D$5-$D11)^2)) -> 11.005131 | K11: =SQRT((4*(HSP!$B$6-$B11)^2+(HSP!$C$6-$C11)^2+(HSP!$D$6-$D11)^2)) -> 15.948385 | L11: - | M11: - | N11: - | O11: - | P11: - | Q11: =$G11/HSP!$E$2 -> 0.86511769 | R11: =$H11/HSP!$E$3 -> 0.98958749 | S11: =$I11/HSP!$E$4 -> 0.92103477 | T11: =$J11/HSP!$E$5 -> 0.80329421 | U11: =$K11/HSP!$E$6 -> 1.0775936
A12: Carbamazepine* | B12: 23.6 | C12: 7.41 | D12: 9.79 | E12: - | F12: - | G12: =SQRT((4*(HSP!$B$2-$B12)^2+(HSP!$C$2-$C12)^2+(HSP!$D$2-$D12)^2)) -> 18.471562 | H12: =SQRT((4*(HSP!$B$3-$B12)^2+(HSP!$C$3-$C12)^2+(HSP!$D$3-$D12)^2)) -> 16.464987 | I12: =SQRT((4*(HSP!$B$4-$B12)^2+(HSP!$C$4-$C12)^2+(HSP!$D$4-$D12)^2)) -> 17.339337 | J12: =SQRT((4*(HSP!$B$5-$B12)^2+(HSP!$C$5-$C12)^2+(HSP!$D$5-$D12)^2)) -> 17.522879 | K12: =SQRT((4*(HSP!$B$6-$B12)^2+(HSP!$C$6-$C12)^2+(HSP!$D$6-$D12)^2)) -> 17.71439 | L12: - | M12: - | N12: - | O12: - | P12: - | Q12: =$G12/HSP!$E$2 -> 1.1332247 | R12: =$H12/HSP!$E$3 -> 1.2196287 | S12: =$I12/HSP!$E$4 -> 1.0905243 | T12: =$J12/HSP!$E$5 -> 1.2790423 | U12: =$K12/HSP!$E$6 -> 1.1969182
A13: Folic Acid | B13: 20.7 | C13: 13.5 | D13: 13.7 | E13: - | F13: 292.7 | G13: =SQRT((4*(HSP!$B$2-$B13)^2+(HSP!$C$2-$C13)^2+(HSP!$D$2-$D13)^2)) -> 14.256227 | H13: =SQRT((4*(HSP!$B$3-$B13)^2+(HSP!$C$3-$C13)^2+(HSP!$D$3-$D13)^2)) -> 13.313166 | I13: =SQRT((4*(HSP!$B$4-$B13)^2+(HSP!$C$4-$C13)^2+(HSP!$D$4-$D13)^2)) -> 15.739314 | J13: =SQRT((4*(HSP!$B$5-$B13)^2+(HSP!$C$5-$C13)^2+(HSP!$D$5-$D13)^2)) -> 11.234808 | K13: =SQRT((4*(HSP!$B$6-$B13)^2+(HSP!$C$6-$C13)^2+(HSP!$D$6-$D13)^2)) -> 16.277193 | L13: - | M13: - | N13: - | O13: - | P13: - | Q13: =$G13/HSP!$E$2 -> 0.87461514 | R13: =$H13/HSP!$E$3 -> 0.98616048 | S13: =$I13/HSP!$E$4 -> 0.98989395 | T13: =$J13/HSP!$E$5 -> 0.82005894 | U13: =$K13/HSP!$E$6 -> 1.0998103
A14: Griseofulvin* | B14: 22.24 | C14: 6.52 | D14: 8.56 | E14: - | F14: - | G14: =SQRT((4*(HSP!$B$2-$B14)^2+(HSP!$C$2-$C14)^2+(HSP!$D$2-$D14)^2)) -> 15.858701 | H14: =SQRT((4*(HSP!$B$3-$B14)^2+(HSP!$C$3-$C14)^2+(HSP!$D$3-$D14)^2)) -> 13.746898 | I14: =SQRT((4*(HSP!$B$4-$B14)^2+(HSP!$C$4-$C14)^2+(HSP!$D$4-$D14)^2)) -> 14.367421 | J14: =SQRT((4*(HSP!$B$5-$B14)^2+(HSP!$C$5-$C14)^2+(HSP!$D$5-$D14)^2)) -> 15.439576 | K14: =SQRT((4*(HSP!$B$6-$B14)^2+(HSP!$C$6-$C14)^2+(HSP!$D$6-$D14)^2)) -> 14.714476 | L14: - | M14: - | N14: - | O14: - | P14: - | Q14: =$G14/HSP!$E$2 -> 0.97292645 | R14: =$H14/HSP!$E$3 -> 1.0182887 | S14: =$I14/HSP!$E$4 -> 0.90361141 | T14: =$J14/HSP!$E$5 -> 1.1269763 | U14: =$K14/HSP!$E$6 -> 0.99422134
A15: Henna | B15: 19 | C15: 16 | D15: 14.6 | E15: - | F15: 117.3 | G15: =SQRT((4*(HSP!$B$2-$B15)^2+(HSP!$C$2-$C15)^2+(HSP!$D$2-$D15)^2)) -> 12.891703 | H15: =SQRT((4*(HSP!$B$3-$B15)^2+(HSP!$C$3-$C15)^2+(HSP!$D$3-$D15)^2)) -> 12.692848 | I15: =SQRT((4*(HSP!$B$4-$B15)^2+(HSP!$C$4-$C15)^2+(HSP!$D$4-$D15)^2)) -> 15.737153 | J15: =SQRT((4*(HSP!$B$5-$B15)^2+(HSP!$C$5-$C15)^2+(HSP!$D$5-$D15)^2)) -> 8.9374997 | K15: =SQRT((4*(HSP!$B$6-$B15)^2+(HSP!$C$6-$C15)^2+(HSP!$D$6-$D15)^2)) -> 16.211076 | L15: - | M15: - | N15: - | O15: - | P15: - | Q15: =$G15/HSP!$E$2 -> 0.79090201 | R15: =$H15/HSP!$E$3 -> 0.94021099 | S15: =$I15/HSP!$E$4 -> 0.98975808 | T15: =$J15/HSP!$E$5 -> 0.65237224 | U15: =$K15/HSP!$E$6 -> 1.095343
A16: Ibuprofen | B16: 17.6 | C16: 2.5 | D16: 7.6 | E16: - | F16: 206.8 | G16: =SQRT((4*(HSP!$B$2-$B16)^2+(HSP!$C$2-$C16)^2+(HSP!$D$2-$D16)^2)) -> 9.9872919 | H16: =SQRT((4*(HSP!$B$3-$B16)^2+(HSP!$C$3-$C16)^2+(HSP!$D$3-$D16)^2)) -> 8.3082128 | I16: =SQRT((4*(HSP!$B$4-$B16)^2+(HSP!$C$4-$C16)^2+(HSP!$D$4-$D16)^2)) -> 5.3862789 | J16: =SQRT((4*(HSP!$B$5-$B16)^2+(HSP!$C$5-$C16)^2+(HSP!$D$5-$D16)^2)) -> 11.715498 | K16: =SQRT((4*(HSP!$B$6-$B16)^2+(HSP!$C$6-$C16)^2+(HSP!$D$6-$D16)^2)) -> 7.1570245 | L16: - | M16: - | N16: - | O16: - | P16: - | Q16: =$G16/HSP!$E$2 -> 0.6127173 | R16: =$H16/HSP!$E$3 -> 0.61542317 | S16: =$I16/HSP!$E$4 -> 0.33875968 | T16: =$J16/HSP!$E$5 -> 0.85514586 | U16: =$K16/HSP!$E$6 -> 0.48358274
A17: Indomethacin* | B17: 23.06 | C17: 5.98 | D17: 9.42 | E17: - | F17: - | G17: =SQRT((4*(HSP!$B$2-$B17)^2+(HSP!$C$2-$C17)^2+(HSP!$D$2-$D17)^2)) -> 17.672306 | H17: =SQRT((4*(HSP!$B$3-$B17)^2+(HSP!$C$3-$C17)^2+(HSP!$D$3-$D17)^2)) -> 15.613135 | I17: =SQRT((4*(HSP!$B$4-$B17)^2+(HSP!$C$4-$C17)^2+(HSP!$D$4-$D17)^2)) -> 16.048763 | J17: =SQRT((4*(HSP!$B$5-$B17)^2+(HSP!$C$5-$C17)^2+(HSP!$D$5-$D17)^2)) -> 17.042421 | K17: =SQRT((4*(HSP!$B$6-$B17)^2+(HSP!$C$6-$C17)^2+(HSP!$D$6-$D17)^2)) -> 16.551852 | L17: - | M17: - | N17: - | O17: - | P17: - | Q17: =$G17/HSP!$E$2 -> 1.0841906 | R17: =$H17/HSP!$E$3 -> 1.1565286 | S17: =$I17/HSP!$E$4 -> 1.0093562 | T17: =$J17/HSP!$E$5 -> 1.2439723 | U17: =$K17/HSP!$E$6 -> 1.1183684
A18: Intraconazole* | B18: 21.76 | C18: 6.55 | D18: 11.4 | E18: - | F18: - | G18: =SQRT((4*(HSP!$B$2-$B18)^2+(HSP!$C$2-$C18)^2+(HSP!$D$2-$D18)^2)) -> 15.488283 | H18: =SQRT((4*(HSP!$B$3-$B18)^2+(HSP!$C$3-$C18)^2+(HSP!$D$3-$D18)^2)) -> 13.718167 | I18: =SQRT((4*(HSP!$B$4-$B18)^2+(HSP!$C$4-$C18)^2+(HSP!$D$4-$D18)^2)) -> 14.084364 | J18: =SQRT((4*(HSP!$B$5-$B18)^2+(HSP!$C$5-$C18)^2+(HSP!$D$5-$D18)^2)) -> 14.379506 | K18: =SQRT((4*(HSP!$B$6-$B18)^2+(HSP!$C$6-$C18)^2+(HSP!$D$6-$D18)^2)) -> 15.016568 | L18: - | M18: - | N18: - | O18: - | P18: - | Q18: =$G18/HSP!$E$2 -> 0.95020139 | R18: =$H18/HSP!$E$3 -> 1.0161605 | S18: =$I18/HSP!$E$4 -> 0.88580904 | T18: =$J18/HSP!$E$5 -> 1.049599 | U18: =$K18/HSP!$E$6 -> 1.0146329
A19: Ketaconazole* | B19: 22.03 | C19: 6 | D19: 9.61 | E19: - | F19: - | G19: =SQRT((4*(HSP!$B$2-$B19)^2+(HSP!$C$2-$C19)^2+(HSP!$D$2-$D19)^2)) -> 15.736203 | H19: =SQRT((4*(HSP!$B$3-$B19)^2+(HSP!$C$3-$C19)^2+(HSP!$D$3-$D19)^2)) -> 13.731063 | I19: =SQRT((4*(HSP!$B$4-$B19)^2+(HSP!$C$4-$C19)^2+(HSP!$D$4-$D19)^2)) -> 14.066872 | J19: =SQRT((4*(HSP!$B$5-$B19)^2+(HSP!$C$5-$C19)^2+(HSP!$D$5-$D19)^2)) -> 15.155567 | K19: =SQRT((4*(HSP!$B$6-$B19)^2+(HSP!$C$6-$C19)^2+(HSP!$D$6-$D19)^2)) -> 14.702139 | L19: - | M19: - | N19: - | O19: - | P19: - | Q19: =$G19/HSP!$E$2 -> 0.96541126 | R19: =$H19/HSP!$E$3 -> 1.0171158 | S19: =$I19/HSP!$E$4 -> 0.88470896 | T19: =$J19/HSP!$E$5 -> 1.1062457 | U19: =$K19/HSP!$E$6 -> 0.99338779
A20: Lycosol** | B20: 17.57 | C20: 2.48 | D20: 11.4 | E20: - | F20: - | G20: =SQRT((4*(HSP!$B$2-$B20)^2+(HSP!$C$2-$C20)^2+(HSP!$D$2-$D20)^2)) -> 10.885789 | H20: =SQRT((4*(HSP!$B$3-$B20)^2+(HSP!$C$3-$C20)^2+(HSP!$D$3-$D20)^2)) -> 9.8400407 | I20: =SQRT((4*(HSP!$B$4-$B20)^2+(HSP!$C$4-$C20)^2+(HSP!$D$4-$D20)^2)) -> 7.0028566 | J20: =SQRT((4*(HSP!$B$5-$B20)^2+(HSP!$C$5-$C20)^2+(HSP!$D$5-$D20)^2)) -> 11.235591 | K20: =SQRT((4*(HSP!$B$6-$B20)^2+(HSP!$C$6-$C20)^2+(HSP!$D$6-$D20)^2)) -> 9.6832329 | L20: - | M20: - | N20: - | O20: - | P20: - | Q20: =$G20/HSP!$E$2 -> 0.66783981 | R20: =$H20/HSP!$E$3 -> 0.7288919 | S20: =$I20/HSP!$E$4 -> 0.44043123 | T20: =$J20/HSP!$E$5 -> 0.82011611 | U20: =$K20/HSP!$E$6 -> 0.6542725
A21: Matrixyl 3000** | B21: 19.66 | C21: 13.95 | D21: 17.55 | E21: - | F21: - | G21: =SQRT((4*(HSP!$B$2-$B21)^2+(HSP!$C$2-$C21)^2+(HSP!$D$2-$D21)^2)) -> 15.043916 | H21: =SQRT((4*(HSP!$B$3-$B21)^2+(HSP!$C$3-$C21)^2+(HSP!$D$3-$D21)^2)) -> 14.80002 | I21: =SQRT((4*(HSP!$B$4-$B21)^2+(HSP!$C$4-$C21)^2+(HSP!$D$4-$D21)^2)) -> 16.796899 | J21: =SQRT((4*(HSP!$B$5-$B21)^2+(HSP!$C$5-$C21)^2+(HSP!$D$5-$D21)^2)) -> 11.064615 | K21: =SQRT((4*(HSP!$B$6-$B21)^2+(HSP!$C$6-$C21)^2+(HSP!$D$6-$D21)^2)) -> 17.925646 | L21: - | M21: - | N21: - | O21: - | P21: - | Q21: =$G21/HSP!$E$2 -> 0.92293961 | R21: =$H21/HSP!$E$3 -> 1.0962978 | S21: =$I21/HSP!$E$4 -> 1.0564087 | T21: =$J21/HSP!$E$5 -> 0.80763611 | U21: =$K21/HSP!$E$6 -> 1.2111923
A22: Nicotine | B22: 18.5 | C22: 7.8 | D22: 6.5 | E22: - | F22: 160.7 | G22: =SQRT((4*(HSP!$B$2-$B22)^2+(HSP!$C$2-$C22)^2+(HSP!$D$2-$D22)^2)) -> 8.2550591 | H22: =SQRT((4*(HSP!$B$3-$B22)^2+(HSP!$C$3-$C22)^2+(HSP!$D$3-$D22)^2)) -> 5.9587247 | I22: =SQRT((4*(HSP!$B$4-$B22)^2+(HSP!$C$4-$C22)^2+(HSP!$D$4-$D22)^2)) -> 7.3607065 | J22: =SQRT((4*(HSP!$B$5-$B22)^2+(HSP!$C$5-$C22)^2+(HSP!$D$5-$D22)^2)) -> 9.2500216 | K22: =SQRT((4*(HSP!$B$6-$B22)^2+(HSP!$C$6-$C22)^2+(HSP!$D$6-$D22)^2)) -> 7.1155464 | L22: - | M22: - | N22: - | O22: - | P22: - | Q22: =$G22/HSP!$E$2 -> 0.50644534 | R22: =$H22/HSP!$E$3 -> 0.44138701 | S22: =$I22/HSP!$E$4 -> 0.46293751 | T22: =$J22/HSP!$E$5 -> 0.67518406 | U22: =$K22/HSP!$E$6 -> 0.48078016
A23: Paracetamol | B23: 20.2 | C23: 13.3 | D23: 14.4 | E23: - | F23: 125.3 | G23: =SQRT((4*(HSP!$B$2-$B23)^2+(HSP!$C$2-$C23)^2+(HSP!$D$2-$D23)^2)) -> 13.731788 | H23: =SQRT((4*(HSP!$B$3-$B23)^2+(HSP!$C$3-$C23)^2+(HSP!$D$3-$D23)^2)) -> 12.970212 | I23: =SQRT((4*(HSP!$B$4-$B23)^2+(HSP!$C$4-$C23)^2+(HSP!$D$4-$D23)^2)) -> 15.273114 | J23: =SQRT((4*(HSP!$B$5-$B23)^2+(HSP!$C$5-$C23)^2+(HSP!$D$5-$D23)^2)) -> 10.468854 | K23: =SQRT((4*(HSP!$B$6-$B23)^2+(HSP!$C$6-$C23)^2+(HSP!$D$6-$D23)^2)) -> 15.991216 | L23: - | M23: - | N23: - | O23: - | P23: - | Q23: =$G23/HSP!$E$2 -> 0.84244098 | R23: =$H23/HSP!$E$3 -> 0.96075645 | S23: =$I23/HSP!$E$4 -> 0.96057318 | T23: =$J23/HSP!$E$5 -> 0.76414991 | U23: =$K23/HSP!$E$6 -> 1.0804876
A24: Salicylic Acid | B24: 19 | C24: 9 | D24: 13.7 | E24: - | F24: 119.6 | G24: =SQRT((4*(HSP!$B$2-$B24)^2+(HSP!$C$2-$C24)^2+(HSP!$D$2-$D24)^2)) -> 11.168259 | H24: =SQRT((4*(HSP!$B$3-$B24)^2+(HSP!$C$3-$C24)^2+(HSP!$D$3-$D24)^2)) -> 10.312827 | I24: =SQRT((4*(HSP!$B$4-$B24)^2+(HSP!$C$4-$C24)^2+(HSP!$D$4-$D24)^2)) -> 11.178014 | J24: =SQRT((4*(HSP!$B$5-$B24)^2+(HSP!$C$5-$C24)^2+(HSP!$D$5-$D24)^2)) -> 8.7842416 | K24: =SQRT((4*(HSP!$B$6-$B24)^2+(HSP!$C$6-$C24)^2+(HSP!$D$6-$D24)^2)) -> 12.620578 | L24: - | M24: - | N24: - | O24: - | P24: - | Q24: =$G24/HSP!$E$2 -> 0.68516924 | R24: =$H24/HSP!$E$3 -> 0.76391311 | S24: =$I24/HSP!$E$4 -> 0.70301976 | T24: =$J24/HSP!$E$5 -> 0.64118552 | U24: =$K24/HSP!$E$6 -> 0.85274179
A25: UREA | B25: 17.4 | C25: 23.8 | D25: 28.2 | E25: - | F25: 46.5 | G25: =SQRT((4*(HSP!$B$2-$B25)^2+(HSP!$C$2-$C25)^2+(HSP!$D$2-$D25)^2)) -> 25.682757 | H25: =SQRT((4*(HSP!$B$3-$B25)^2+(HSP!$C$3-$C25)^2+(HSP!$D$3-$D25)^2)) -> 26.692703 | I25: =SQRT((4*(HSP!$B$4-$B25)^2+(HSP!$C$4-$C25)^2+(HSP!$D$4-$D25)^2)) -> 29.041797 | J25: =SQRT((4*(HSP!$B$5-$B25)^2+(HSP!$C$5-$C25)^2+(HSP!$D$5-$D25)^2)) -> 20.956309 | K25: =SQRT((4*(HSP!$B$6-$B25)^2+(HSP!$C$6-$C25)^2+(HSP!$D$6-$D25)^2)) -> 30.212365 | L25: - | M25: - | N25: - | O25: - | P25: - | Q25: =$G25/HSP!$E$2 -> 1.5756293 | R25: =$H25/HSP!$E$3 -> 1.9772373 | S25: =$I25/HSP!$E$4 -> 1.8265281 | T25: =$J25/HSP!$E$5 -> 1.5296576 | U25: =$K25/HSP!$E$6 -> 2.041376
A26: Vitamin d-2 | B26: 17.2 | C26: 3 | D26: 6.4 | E26: - | F26: 413.5 | G26: =SQRT((4*(HSP!$B$2-$B26)^2+(HSP!$C$2-$C26)^2+(HSP!$D$2-$D26)^2)) -> 9.1119701 | H26: =SQRT((4*(HSP!$B$3-$B26)^2+(HSP!$C$3-$C26)^2+(HSP!$D$3-$D26)^2)) -> 7.3356936 | I26: =SQRT((4*(HSP!$B$4-$B26)^2+(HSP!$C$4-$C26)^2+(HSP!$D$4-$D26)^2)) -> 4.412029 | J26: =SQRT((4*(HSP!$B$5-$B26)^2+(HSP!$C$5-$C26)^2+(HSP!$D$5-$D26)^2)) -> 11.39732 | K26: =SQRT((4*(HSP!$B$6-$B26)^2+(HSP!$C$6-$C26)^2+(HSP!$D$6-$D26)^2)) -> 5.7590798 | L26: - | M26: - | N26: - | O26: - | P26: - | Q26: =$G26/HSP!$E$2 -> 0.55901657 | R26: =$H26/HSP!$E$3 -> 0.54338471 | S26: =$I26/HSP!$E$4 -> 0.2774861 | T26: =$J26/HSP!$E$5 -> 0.83192116 | U26: =$K26/HSP!$E$6 -> 0.38912701
A27: Vitamin d-3 | B27: 17.1 | C27: 2.9 | D27: 6.1 | E27: - | F27: 404.4 | G27: =SQRT((4*(HSP!$B$2-$B27)^2+(HSP!$C$2-$C27)^2+(HSP!$D$2-$D27)^2)) -> 9.1064812 | H27: =SQRT((4*(HSP!$B$3-$B27)^2+(HSP!$C$3-$C27)^2+(HSP!$D$3-$D27)^2)) -> 7.3299659 | I27: =SQRT((4*(HSP!$B$4-$B27)^2+(HSP!$C$4-$C27)^2+(HSP!$D$4-$D27)^2)) -> 4.3078997 | J27: =SQRT((4*(HSP!$B$5-$B27)^2+(HSP!$C$5-$C27)^2+(HSP!$D$5-$D27)^2)) -> 11.539363 | K27: =SQRT((4*(HSP!$B$6-$B27)^2+(HSP!$C$6-$C27)^2+(HSP!$D$6-$D27)^2)) -> 5.5604856 | L27: - | M27: - | N27: - | O27: - | P27: - | Q27: =$G27/HSP!$E$2 -> 0.55867983 | R27: =$H27/HSP!$E$3 -> 0.54296044 | S27: =$I27/HSP!$E$4 -> 0.27093709 | T27: =$J27/HSP!$E$5 -> 0.84228927 | U27: =$K27/HSP!$E$6 -> 0.37570849
A29: *Ghent University
A30: **VLCI

Sheet Cosmetics
A1: SOLVENT | B1: HSP | E1: Ro | F1: Mvol | G1: DISTANCE TO | L1: RED TO (BASED ON Ro OF THE SOLVENT) | Q1: RED TO (BASED ON Ro OF NXTLEVVEL SOLVENT)
B2: D | C2: P | D2: H | G2: ETHYL LEVULINATE | H2: BUTYL LEVULINATE | I2: EtLPK | J2: EtLGK | K2: EHL | L2: ETHYL LEVULINATE | M2: BUTYL LEVULINATE | N2: EtLPK | O2: EtLGK | P2: EHL | Q2: ETHYL LEVULINATE | R2: BUTYL LEVULINATE | S2: EtLPK | T2: EtLGK | U2: EHL
A3: Apg Surfactant (Typical) | B3: 16 | C3: 7.7 | D3: 12.5 | E3: - | F3: 340 | G3: =SQRT((4*(HSP!$B$2-$B3)^2+(HSP!$C$2-$C3)^2+(HSP!$D$2-$D3)^2)) -> 6.77702 | H3: =SQRT((4*(HSP!$B$3-$B3)^2+(HSP!$C$3-$C3)^2+(HSP!$D$3-$D3)^2)) -> 6.989163 | I3: =SQRT((4*(HSP!$B$4-$B3)^2+(HSP!$C$4-$C3)^2+(HSP!$D$4-$D3)^2)) -> 6.6607807 | J3: =SQRT((4*(HSP!$B$5-$B3)^2+(HSP!$C$5-$C3)^2+(HSP!$D$5-$D3)^2)) -> 5.4586537 | K3: =SQRT((4*(HSP!$B$6-$B3)^2+(HSP!$C$6-$C3)^2+(HSP!$D$6-$D3)^2)) -> 8.8638028 | L3: - | M3: - | N3: - | O3: - | P3: - | Q3: =$G3/HSP!$E$2 -> 0.4157681 | R3: =$H3/HSP!$E$3 -> 0.51771578 | S3: =$I3/HSP!$E$4 -> 0.41891703 | T3: =$J3/HSP!$E$5 -> 0.39844187 | U3: =$K3/HSP!$E$6 -> 0.59890559
A4: Butylene Glycol | B4: 16.1 | C4: 9.4 | D4: 24.2 | E4: - | F4: 106.3 | G4: =SQRT((4*(HSP!$B$2-$B4)^2+(HSP!$C$2-$C4)^2+(HSP!$D$2-$D4)^2)) -> 17.511482 | H4: =SQRT((4*(HSP!$B$3-$B4)^2+(HSP!$C$3-$C4)^2+(HSP!$D$3-$D4)^2)) -> 18.40012 | I4: =SQRT((4*(HSP!$B$4-$B4)^2+(HSP!$C$4-$C4)^2+(HSP!$D$4-$D4)^2)) -> 18.124514 | J4: =SQRT((4*(HSP!$B$5-$B4)^2+(HSP!$C$5-$C4)^2+(HSP!$D$5-$D4)^2)) -> 13.779365 | K4: =SQRT((4*(HSP!$B$6-$B4)^2+(HSP!$C$6-$C4)^2+(HSP!$D$6-$D4)^2)) -> 20.632474 | L4: - | M4: - | N4: - | O4: - | P4: - | Q4: =$G4/HSP!$E$2 -> 1.074324 | R4: =$H4/HSP!$E$3 -> 1.3629718 | S4: =$I4/HSP!$E$4 -> 1.1399065 | T4: =$J4/HSP!$E$5 -> 1.0057931 | U4: =$K4/HSP!$E$6 -> 1.3940861
A5: Butylene Glycol Caprylate/Caprate | B5: 16.3 | C5: 3.8 | D5: 5.9 | E5: - | F5: 396.2 | G5: =SQRT((4*(HSP!$B$2-$B5)^2+(HSP!$C$2-$C5)^2+(HSP!$D$2-$D5)^2)) -> 7.5552631 | H5: =SQRT((4*(HSP!$B$3-$B5)^2+(HSP!$C$3-$C5)^2+(HSP!$D$3-$D5)^2)) -> 5.9861841 | I5: =SQRT((4*(HSP!$B$4-$B5)^2+(HSP!$C$4-$C5)^2+(HSP!$D$4-$D5)^2)) -> 2.58689 | J5: =SQRT((4*(HSP!$B$5-$B5)^2+(HSP!$C$5-$C5)^2+(HSP!$D$5-$D5)^2)) -> 10.445616 | K5: =SQRT((4*(HSP!$B$6-$B5)^2+(HSP!$C$6-$C5)^2+(HSP!$D$6-$D5)^2)) -> 3.9195663 | L5: - | M5: - | N5: - | O5: - | P5: - | Q5: =$G5/HSP!$E$2 -> 0.46351307 | R5: =$H5/HSP!$E$3 -> 0.44342104 | S5: =$I5/HSP!$E$4 -> 0.16269749 | T5: =$J5/HSP!$E$5 -> 0.76245374 | U5: =$K5/HSP!$E$6 -> 0.26483556
A6: C12-15 Alkyl Lactate | B6: 16.5 | C6: 6 | D6: 9.6 | E6: - | F6: 304.5 | G6: =SQRT((4*(HSP!$B$2-$B6)^2+(HSP!$C$2-$C6)^2+(HSP!$D$2-$D6)^2)) -> 6.418411 | H6: =SQRT((4*(HSP!$B$3-$B6)^2+(HSP!$C$3-$C6)^2+(HSP!$D$3-$D6)^2)) -> 5.5053065 | I6: =SQRT((4*(HSP!$B$4-$B6)^2+(HSP!$C$4-$C6)^2+(HSP!$D$4-$D6)^2)) -> 4.0814213 | J6: =SQRT((4*(HSP!$B$5-$B6)^2+(HSP!$C$5-$C6)^2+(HSP!$D$5-$D6)^2)) -> 7.2786606 | K6: =SQRT((4*(HSP!$B$6-$B6)^2+(HSP!$C$6-$C6)^2+(HSP!$D$6-$D6)^2)) -> 6.2688914 | L6: - | M6: - | N6: - | O6: - | P6: - | Q6: =$G6/HSP!$E$2 -> 0.39376755 | R6: =$H6/HSP!$E$3 -> 0.40780048 | S6: =$I6/HSP!$E$4 -> 0.25669316 | T6: =$J6/HSP!$E$5 -> 0.53128909 | U6: =$K6/HSP!$E$6 -> 0.42357375
A7: Caprylyl Glycol | B7: 16.1 | C7: 5.8 | D7: 13.9 | E7: - | F7: 156.9 | G7: =SQRT((4*(HSP!$B$2-$B7)^2+(HSP!$C$2-$C7)^2+(HSP!$D$2-$D7)^2)) -> 8.8657769 | H7: =SQRT((4*(HSP!$B$3-$B7)^2+(HSP!$C$3-$C7)^2+(HSP!$D$3-$D7)^2)) -> 8.9921299 | I7: =SQRT((4*(HSP!$B$4-$B7)^2+(HSP!$C$4-$C7)^2+(HSP!$D$4-$D7)^2)) -> 7.4245539 | J7: =SQRT((4*(HSP!$B$5-$B7)^2+(HSP!$C$5-$C7)^2+(HSP!$D$5-$D7)^2)) -> 7.7112191 | K7: =SQRT((4*(HSP!$B$6-$B7)^2+(HSP!$C$6-$C7)^2+(HSP!$D$6-$D7)^2)) -> 10.205636 | L7: - | M7: - | N7: - | O7: - | P7: - | Q7: =$G7/HSP!$E$2 -> 0.54391269 | R7: =$H7/HSP!$E$3 -> 0.6660837 | S7: =$I7/HSP!$E$4 -> 0.46695307 | T7: =$J7/HSP!$E$5 -> 0.56286271 | U7: =$K7/HSP!$E$6 -> 0.68956998
A8: Cetearyl Alcohol | B8: 16.3 | C8: 2.8 | D8: 7.9 | E8: - | F8: 306.7 | G8: =SQRT((4*(HSP!$B$2-$B8)^2+(HSP!$C$2-$C8)^2+(HSP!$D$2-$D8)^2)) -> 8.4310142 | H8: =SQRT((4*(HSP!$B$3-$B8)^2+(HSP!$C$3-$C8)^2+(HSP!$D$3-$D8)^2)) -> 7.2714785 | I8: =SQRT((4*(HSP!$B$4-$B8)^2+(HSP!$C$4-$C8)^2+(HSP!$D$4-$D8)^2)) -> 3.1387896 | J8: =SQRT((4*(HSP!$B$5-$B8)^2+(HSP!$C$5-$C8)^2+(HSP!$D$5-$D8)^2)) -> 10.575013 | K8: =SQRT((4*(HSP!$B$6-$B8)^2+(HSP!$C$6-$C8)^2+(HSP!$D$6-$D8)^2)) -> 5.8157545 | L8: - | M8: - | N8: - | O8: - | P8: - | Q8: =$G8/HSP!$E$2 -> 0.51724013 | R8: =$H8/HSP!$E$3 -> 0.53862804 | S8: =$I8/HSP!$E$4 -> 0.19740815 | T8: =$J8/HSP!$E$5 -> 0.77189876 | U8: =$K8/HSP!$E$6 -> 0.39295638
A9: Cetearyl Ethylhexanoate | B9: 16.4 | C9: 3.5 | D9: 6.4 | E9: - | F9: 447.3 | G9: =SQRT((4*(HSP!$B$2-$B9)^2+(HSP!$C$2-$C9)^2+(HSP!$D$2-$D9)^2)) -> 7.8573532 | H9: =SQRT((4*(HSP!$B$3-$B9)^2+(HSP!$C$3-$C9)^2+(HSP!$D$3-$D9)^2)) -> 6.3481021 | I9: =SQRT((4*(HSP!$B$4-$B9)^2+(HSP!$C$4-$C9)^2+(HSP!$D$4-$D9)^2)) -> 2.7575351 | J9: =SQRT((4*(HSP!$B$5-$B9)^2+(HSP!$C$5-$C9)^2+(HSP!$D$5-$D9)^2)) -> 10.518408 | K9: =SQRT((4*(HSP!$B$6-$B9)^2+(HSP!$C$6-$C9)^2+(HSP!$D$6-$D9)^2)) -> 4.4938847 | L9: - | M9: - | N9: - | O9: - | P9: - | Q9: =$G9/HSP!$E$2 -> 0.48204621 | R9: =$H9/HSP!$E$3 -> 0.47022978 | S9: =$I9/HSP!$E$4 -> 0.17342988 | T9: =$J9/HSP!$E$5 -> 0.76776698 | U9: =$K9/HSP!$E$6 -> 0.30364086
A10: Cetearyl Isononanoate | B10: 16.2 | C10: 3.1 | D10: 6 | E10: - | F10: 463.2 | G10: =SQRT((4*(HSP!$B$2-$B10)^2+(HSP!$C$2-$C10)^2+(HSP!$D$2-$D10)^2)) -> 8.0851716 | H10: =SQRT((4*(HSP!$B$3-$B10)^2+(HSP!$C$3-$C10)^2+(HSP!$D$3-$D10)^2)) -> 6.6412649 | I10: =SQRT((4*(HSP!$B$4-$B10)^2+(HSP!$C$4-$C10)^2+(HSP!$D$4-$D10)^2)) -> 2.7166155 | J10: =SQRT((4*(HSP!$B$5-$B10)^2+(HSP!$C$5-$C10)^2+(HSP!$D$5-$D10)^2)) -> 10.968541 | K10: =SQRT((4*(HSP!$B$6-$B10)^2+(HSP!$C$6-$C10)^2+(HSP!$D$6-$D10)^2)) -> 4.3784701 | L10: - | M10: - | N10: - | O10: - | P10: - | Q10: =$G10/HSP!$E$2 -> 0.4960228 | R10: =$H10/HSP!$E$3 -> 0.49194555 | S10: =$I10/HSP!$E$4 -> 0.17085632 | T10: =$J10/HSP!$E$5 -> 0.80062346 | U10: =$K10/HSP!$E$6 -> 0.29584257
A11: Cocamidopropyl Betaine (Capb) | B11: 16.5 | C11: 6.2 | D11: 7.5 | E11: - | F11: 340 | G11: =SQRT((4*(HSP!$B$2-$B11)^2+(HSP!$C$2-$C11)^2+(HSP!$D$2-$D11)^2)) -> 5.7321898 | H11: =SQRT((4*(HSP!$B$3-$B11)^2+(HSP!$C$3-$C11)^2+(HSP!$D$3-$D11)^2)) -> 4.1735357 | I11: =SQRT((4*(HSP!$B$4-$B11)^2+(HSP!$C$4-$C11)^2+(HSP!$D$4-$D11)^2)) -> 3.1426104 | J11: =SQRT((4*(HSP!$B$5-$B11)^2+(HSP!$C$5-$C11)^2+(HSP!$D$5-$D11)^2)) -> 7.7670393 | K11: =SQRT((4*(HSP!$B$6-$B11)^2+(HSP!$C$6-$C11)^2+(HSP!$D$6-$D11)^2)) -> 4.4076071 | L11: - | M11: - | N11: - | O11: - | P11: - | Q11: =$G11/HSP!$E$2 -> 0.35166809 | R11: =$H11/HSP!$E$3 -> 0.30915079 | S11: =$I11/HSP!$E$4 -> 0.19764845 | T11: =$J11/HSP!$E$5 -> 0.56693718 | U11: =$K11/HSP!$E$6 -> 0.29781129
A12: Dibutyl Adipate | B12: 16.4 | C12: 4.3 | D12: 5.9 | E12: - | F12: 271.6 | G12: =SQRT((4*(HSP!$B$2-$B12)^2+(HSP!$C$2-$C12)^2+(HSP!$D$2-$D12)^2)) -> 7.2160931 | H12: =SQRT((4*(HSP!$B$3-$B12)^2+(HSP!$C$3-$C12)^2+(HSP!$D$3-$D12)^2)) -> 5.5454846 | I12: =SQRT((4*(HSP!$B$4-$B12)^2+(HSP!$C$4-$C12)^2+(HSP!$D$4-$D12)^2)) -> 2.646885 | J12: =SQRT((4*(HSP!$B$5-$B12)^2+(HSP!$C$5-$C12)^2+(HSP!$D$5-$D12)^2)) -> 10.065034 | K12: =SQRT((4*(HSP!$B$6-$B12)^2+(HSP!$C$6-$C12)^2+(HSP!$D$6-$D12)^2)) -> 3.7211557 | L12: - | M12: - | N12: - | O12: - | P12: - | Q12: =$G12/HSP!$E$2 -> 0.4427051 | R12: =$H12/HSP!$E$3 -> 0.41077664 | S12: =$I12/HSP!$E$4 -> 0.16647075 | T12: =$J12/HSP!$E$5 -> 0.73467398 | U12: =$K12/HSP!$E$6 -> 0.25142944
A13: Diisopropyl Adipate | B13: 16 | C13: 4.2 | D13: 6 | E13: - | F13: 237.7 | G13: =SQRT((4*(HSP!$B$2-$B13)^2+(HSP!$C$2-$C13)^2+(HSP!$D$2-$D13)^2)) -> 6.9273372 | H13: =SQRT((4*(HSP!$B$3-$B13)^2+(HSP!$C$3-$C13)^2+(HSP!$D$3-$D13)^2)) -> 5.498036 | I13: =SQRT((4*(HSP!$B$4-$B13)^2+(HSP!$C$4-$C13)^2+(HSP!$D$4-$D13)^2)) -> 1.9042059 | J13: =SQRT((4*(HSP!$B$5-$B13)^2+(HSP!$C$5-$C13)^2+(HSP!$D$5-$D13)^2)) -> 9.9512261 | K13: =SQRT((4*(HSP!$B$6-$B13)^2+(HSP!$C$6-$C13)^2+(HSP!$D$6-$D13)^2)) -> 3.4244708 | L13: - | M13: - | N13: - | O13: - | P13: - | Q13: =$G13/HSP!$E$2 -> 0.42499001 | R13: =$H13/HSP!$E$3 -> 0.40726193 | S13: =$I13/HSP!$E$4 -> 0.11976138 | T13: =$J13/HSP!$E$5 -> 0.72636687 | U13: =$K13/HSP!$E$6 -> 0.23138316
A14: Diisopropyl Dimer Dilinoleate | B14: 16.1 | C14: 5.4 | D14: 5.6 | E14: - | F14: 705 | G14: =SQRT((4*(HSP!$B$2-$B14)^2+(HSP!$C$2-$C14)^2+(HSP!$D$2-$D14)^2)) -> 6.042185 | H14: =SQRT((4*(HSP!$B$3-$B14)^2+(HSP!$C$3-$C14)^2+(HSP!$D$3-$D14)^2)) -> 4.3437772 | I14: =SQRT((4*(HSP!$B$4-$B14)^2+(HSP!$C$4-$C14)^2+(HSP!$D$4-$D14)^2)) -> 2.3276598 | J14: =SQRT((4*(HSP!$B$5-$B14)^2+(HSP!$C$5-$C14)^2+(HSP!$D$5-$D14)^2)) -> 9.2058079 | K14: =SQRT((4*(HSP!$B$6-$B14)^2+(HSP!$C$6-$C14)^2+(HSP!$D$6-$D14)^2)) -> 2.6227848 | L14: - | M14: - | N14: - | O14: - | P14: - | Q14: =$G14/HSP!$E$2 -> 0.3706862 | R14: =$H14/HSP!$E$3 -> 0.32176127 | S14: =$I14/HSP!$E$4 -> 0.1463937 | T14: =$J14/HSP!$E$5 -> 0.67195678 | U14: =$K14/HSP!$E$6 -> 0.17721519
... A65: Tween 80 | B65: 16.2 | C65: 6.6 | D65: 9.6 | E65: - | F65: 1265 | G65: =SQRT((4*(HSP!$B$2-$B65)^2+(HSP!$C$2-$C65)^2+(HSP!$D$2-$D65)^2)) -> 5.6572078 | H65: =SQRT((4*(HSP!$B$3-$B65)^2+(HSP!$C$3-$C65)^2+(HSP!$D$3-$D65)^2)) -> 4.9691448 | I65: =SQRT((4*(HSP!$B$4-$B65)^2+(HSP!$C$4-$C65)^2+(HSP!$D$4-$D65)^2)) -> 3.9711459 | J65: =SQRT((4*(HSP!$B$5-$B65)^2+(HSP!$C$5-$C65)^2+(HSP!$D$5-$D65)^2)) -> 6.5332151 | K65: =SQRT((4*(HSP!$B$6-$B65)^2+(HSP!$C$6-$C65)^2+(HSP!$D$6-$D65)^2)) -> 6.0457423 | L65: - | M65: - | N65: - | O65: - | P65: - | Q65: =$G65/HSP!$E$2 -> 0.34706796 | R65: =$H65/HSP!$E$3 -> 0.3680848 | S65: =$I65/HSP!$E$4 -> 0.24975761 | T65: =$J65/HSP!$E$5 -> 0.47687702 | U65: =$K65/HSP!$E$6 -> 0.4084961

Sheet Fatty esters
A1: FATTY ESTER | B1: HSP | E1: Ro | F1: Mvol | G1: DISTANCE TO | L1: RED TO (BASED ON Ro OF THE FATTY ESTER) | Q1: RED TO (BASED ON Ro OF NXTLEVVEL SOLVENT)
B2: D | C2: P | D2: H | G2: ETHYL LEVULINATE | H2: BUTYL LEVULINATE | I2: EtLPK | J2: EtLGK | K2: EHL | L2: ETHYL LEVULINATE | M2: BUTYL LEVULINATE | N2: EtLPK | O2: EtLGK | P2: EHL | Q2: ETHYL LEVULINATE | R2: BUTYL LEVULINATE | S2: EtLPK | T2: EtLGK | U2: EHL
A3: Coconut oil | B3: 14.95 | C3: 4.63 | D3: 6.98 | E3: 9.8 | F3: - | G3: =SQRT((4*(HSP!$B$2-$B3)^2+(HSP!$C$2-$C3)^2+(HSP!$D$2-$D3)^2)) -> 5.8718736 | H3: =SQRT((4*(HSP!$B$3-$B3)^2+(HSP!$C$3-$C3)^2+(HSP!$D$3-$D3)^2)) -> 5.37 | I3: =SQRT((4*(HSP!$B$4-$B3)^2+(HSP!$C$4-$C3)^2+(HSP!$D$4-$D3)^2)) -> 0.47801674 | J3: =SQRT((4*(HSP!$B$5-$B3)^2+(HSP!$C$5-$C3)^2+(HSP!$D$5-$D3)^2)) -> 9.0255305 | K3: =SQRT((4*(HSP!$B$6-$B3)^2+(HSP!$C$6-$C3)^2+(HSP!$D$6-$D3)^2)) -> 3.666947 | L3: =$G3/$E3 -> 0.59917078 | M3: =$H3/$E3 -> 0.54795918 | N3: =$I3/$E3 -> 0.048777218 | O3: =$J3/$E3 -> 0.9209725 | P3: =$K3/$E3 -> 0.37417826 | Q3: =$G3/HSP!$E$2 -> 0.36023765 | R3: =$H3/HSP!$E$3 -> 0.39777778 | S3: =$I3/HSP!$E$4 -> 0.030063946 | T3: =$J3/HSP!$E$5 -> 0.65879784 | U3: =$K3/HSP!$E$6 -> 0.24776669
A4: Methyl caprylate | B4: 16.58 | C4: 2.4 | D4: 5.85 | E4: - | F4: - | G4: =SQRT((4*(HSP!$B$2-$B4)^2+(HSP!$C$2-$C4)^2+(HSP!$D$2-$D4)^2)) -> 9.0510828 | H4: =SQRT((4*(HSP!$B$3-$B4)^2+(HSP!$C$3-$C4)^2+(HSP!$D$3-$D4)^2)) -> 7.4750853 | I4: =SQRT((4*(HSP!$B$4-$B4)^2+(HSP!$C$4-$C4)^2+(HSP!$D$4-$D4)^2)) -> 3.7487731 | J4: =SQRT((4*(HSP!$B$5-$B4)^2+(HSP!$C$5-$C4)^2+(HSP!$D$5-$D4)^2)) -> 11.797169 | K4: =SQRT((4*(HSP!$B$6-$B4)^2+(HSP!$C$6-$C4)^2+(HSP!$D$6-$D4)^2)) -> 5.2062751 | L4: - | M4: - | N4: - | O4: - | P4: - | Q4: =$G4/HSP!$E$2 -> 0.55528115 | R4: =$H4/HSP!$E$3 -> 0.55371002 | S4: =$I4/HSP!$E$4 -> 0.2357719 | T4: =$J4/HSP!$E$5 -> 0.86110724 | U4: =$K4/HSP!$E$6 -> 0.35177534
A5: Methyl laurate | B5: 16.54 | C5: 2.06 | D5: 5.43 | E5: - | F5: - | G5: =SQRT((4*(HSP!$B$2-$B5)^2+(HSP!$C$2-$C5)^2+(HSP!$D$2-$D5)^2)) -> 9.3817322 | H5: =SQRT((4*(HSP!$B$3-$B5)^2+(HSP!$C$3-$C5)^2+(HSP!$D$3-$D5)^2)) -> 7.7975701 | I5: =SQRT((4*(HSP!$B$4-$B5)^2+(HSP!$C$4-$C5)^2+(HSP!$D$4-$D5)^2)) -> 4.0309924 | J5: =SQRT((4*(HSP!$B$5-$B5)^2+(HSP!$C$5-$C5)^2+(HSP!$D$5-$D5)^2)) -> 12.261207 | K5: =SQRT((4*(HSP!$B$6-$B5)^2+(HSP!$C$6-$C5)^2+(HSP!$D$6-$D5)^2)) -> 5.2957436 | L5: - | M5: - | N5: - | O5: - | P5: - | Q5: =$G5/HSP!$E$2 -> 0.5755664 | R5: =$H5/HSP!$E$3 -> 0.57759779 | S5: =$I5/HSP!$E$4 -> 0.25352154 | T5: =$J5/HSP!$E$5 -> 0.89497862 | U5: =$K5/HSP!$E$6 -> 0.35782051
A6: Methyl linoleate | B6: 16.45 | C6: 1.53 | D6: 4.67 | E6: - | F6: - | G6: =SQRT((4*(HSP!$B$2-$B6)^2+(HSP!$C$2-$C6)^2+(HSP!$D$2-$D6)^2)) -> 9.93836 | H6: =SQRT((4*(HSP!$B$3-$B6)^2+(HSP!$C$3-$C6)^2+(HSP!$D$3-$D6)^2)) -> 8.3504371 | I6: =SQRT((4*(HSP!$B$4-$B6)^2+(HSP!$C$4-$C6)^2+(HSP!$D$4-$D6)^2)) -> 4.5839939 | J6: =SQRT((4*(HSP!$B$5-$B6)^2+(HSP!$C$5-$C6)^2+(HSP!$D$5-$D6)^2)) -> 13.037381 | K6: =SQRT((4*(HSP!$B$6-$B6)^2+(HSP!$C$6-$C6)^2+(HSP!$D$6-$D6)^2)) -> 5.5001818 | L6: - | M6: - | N6: - | O6: - | P6: - | Q6: =$G6/HSP!$E$2 -> 0.60971534 | R6: =$H6/HSP!$E$3 -> 0.6185509 | S6: =$I6/HSP!$E$4 -> 0.2883015 | T6: =$J6/HSP!$E$5 -> 0.95163364 | U6: =$K6/HSP!$E$6 -> 0.37163391
A7: Methyl myristate | B7: 16.51 | C7: 1.81 | D7: 5.08 | E7: - | F7: - | G7: =SQRT((4*(HSP!$B$2-$B7)^2+(HSP!$C$2-$C7)^2+(HSP!$D$2-$D7)^2)) -> 9.6449417 | H7: =SQRT((4*(HSP!$B$3-$B7)^2+(HSP!$C$3-$C7)^2+(HSP!$D$3-$D7)^2)) -> 8.053552 | I7: =SQRT((4*(HSP!$B$4-$B7)^2+(HSP!$C$4-$C7)^2+(HSP!$D$4-$D7)^2)) -> 4.286922 | J7: =SQRT((4*(HSP!$B$5-$B7)^2+(HSP!$C$5-$C7)^2+(HSP!$D$5-$D7)^2)) -> 12.625411 | K7: =SQRT((4*(HSP!$B$6-$B7)^2+(HSP!$C$6-$C7)^2+(HSP!$D$6-$D7)^2)) -> 5.3858797 | L7: - | M7: - | N7: - | O7: - | P7: - | Q7: =$G7/HSP!$E$2 -> 0.59171421 | R7: =$H7/HSP!$E$3 -> 0.59655941 | S7: =$I7/HSP!$E$4 -> 0.26961773 | T7: =$J7/HSP!$E$5 -> 0.92156284 | U7: =$K7/HSP!$E$6 -> 0.36391079
A8: Methyl oleate | B8: 16.45 | C8: 1.49 | D8: 4.61 | E8: - | F8: - | G8: =SQRT((4*(HSP!$B$2-$B8)^2+(HSP!$C$2-$C8)^2+(HSP!$D$2-$D8)^2)) -> 9.9883833 | H8: =SQRT((4*(HSP!$B$3-$B8)^2+(HSP!$C$3-$C8)^2+(HSP!$D$3-$D8)^2)) -> 8.3978211 | I8: =SQRT((4*(HSP!$B$4-$B8)^2+(HSP!$C$4-$C8)^2+(HSP!$D$4-$D8)^2)) -> 4.6395905 | J8: =SQRT((4*(HSP!$B$5-$B8)^2+(HSP!$C$5-$C8)^2+(HSP!$D$5-$D8)^2)) -> 13.100569 | K8: =SQRT((4*(HSP!$B$6-$B8)^2+(HSP!$C$6-$C8)^2+(HSP!$D$6-$D8)^2)) -> 5.5272778 | L8: - | M8: - | N8: - | O8: - | P8: - | Q8: =$G8/HSP!$E$2 -> 0.61278425 | R8: =$H8/HSP!$E$3 -> 0.62206083 | S8: =$I8/HSP!$E$4 -> 0.29179814 | T8: =$J8/HSP!$E$5 -> 0.95624589 | U8: =$K8/HSP!$E$6 -> 0.37346472
A9: Methyl palmitate | B9: 16.48 | C9: 1.61 | D9: 4.8 | E9: - | F9: - | G9: =SQRT((4*(HSP!$B$2-$B9)^2+(HSP!$C$2-$C9)^2+(HSP!$D$2-$D9)^2)) -> 9.85964 | H9: =SQRT((4*(HSP!$B$3-$B9)^2+(HSP!$C$3-$C9)^2+(HSP!$D$3-$D9)^2)) -> 8.2667587 | I9: =SQRT((4*(HSP!$B$4-$B9)^2+(HSP!$C$4-$C9)^2+(HSP!$D$4-$D9)^2)) -> 4.5043646 | J9: =SQRT((4*(HSP!$B$5-$B9)^2+(HSP!$C$5-$C9)^2+(HSP!$D$5-$D9)^2)) -> 12.917639 | K9: =SQRT((4*(HSP!$B$6-$B9)^2+(HSP!$C$6-$C9)^2+(HSP!$D$6-$D9)^2)) -> 5.4764313 | L9: - | M9: - | N9: - | O9: - | P9: - | Q9: =$G9/HSP!$E$2 -> 0.60488589 | R9: =$H9/HSP!$E$3 -> 0.6123525 | S9: =$I9/HSP!$E$4 -> 0.28329337 | T9: =$J9/HSP!$E$5 -> 0.94289337 | U9: =$K9/HSP!$E$6 -> 0.37002914
A10: Methyl stearate | B10: 16.46 | C10: 1.45 | D10: 4.56 | E10: - | F10: - | G10: =SQRT((4*(HSP!$B$2-$B10)^2+(HSP!$C$2-$C10)^2+(HSP!$D$2-$D10)^2)) -> 10.04365 | H10: =SQRT((4*(HSP!$B$3-$B10)^2+(HSP!$C$3-$C10)^2+(HSP!$D$3-$D10)^2)) -> 8.4476802 | I10: =SQRT((4*(HSP!$B$4-$B10)^2+(HSP!$C$4-$C10)^2+(HSP!$D$4-$D10)^2)) -> 4.7017975 | J10: =SQRT((4*(HSP!$B$5-$B10)^2+(HSP!$C$5-$C10)^2+(HSP!$D$5-$D10)^2)) -> 13.162606 | K10: =SQRT((4*(HSP!$B$6-$B10)^2+(HSP!$C$6-$C10)^2+(HSP!$D$6-$D10)^2)) -> 5.5649708 | L10: - | M10: - | N10: - | O10: - | P10: - | Q10: =$G10/HSP!$E$2 -> 0.61617483 | R10: =$H10/HSP!$E$3 -> 0.62575409 | S10: =$I10/HSP!$E$4 -> 0.29571054 | T10: =$J10/HSP!$E$5 -> 0.96077417 | U10: =$K10/HSP!$E$6 -> 0.37601154
A11: Palm oil | B11: 17.54 | C11: 3.34 | D11: 4.08 | E11: 7.48 | F11: - | G11: =SQRT((4*(HSP!$B$2-$B11)^2+(HSP!$C$2-$C11)^2+(HSP!$D$2-$D11)^2)) -> 9.6787809 | H11: =SQRT((4*(HSP!$B$3-$B11)^2+(HSP!$C$3-$C11)^2+(HSP!$D$3-$D11)^2)) -> 7.5272837 | I11: =SQRT((4*(HSP!$B$4-$B11)^2+(HSP!$C$4-$C11)^2+(HSP!$D$4-$D11)^2)) -> 5.6268641 | J11: =SQRT((4*(HSP!$B$5-$B11)^2+(HSP!$C$5-$C11)^2+(HSP!$D$5-$D11)^2)) -> 12.470706 | K11: =SQRT((4*(HSP!$B$6-$B11)^2+(HSP!$C$6-$C11)^2+(HSP!$D$6-$D11)^2)) -> 5.4965989 | L11: =$G11/$E11 -> 1.2939547 | M11: =$H11/$E11 -> 1.0063214 | N11: =$I11/$E11 -> 0.75225456 | O11: =$J11/$E11 -> 1.6672066 | P11: =$K11/$E11 -> 0.73483943 | Q11: =$G11/HSP!$E$2 -> 0.59379024 | R11: =$H11/HSP!$E$3 -> 0.55757657 | S11: =$I11/HSP!$E$4 -> 0.35389083 | T11: =$J11/HSP!$E$5 -> 0.91027049 | U11: =$K11/HSP!$E$6 -> 0.37139182
A12: Used frying oil | B12: 15.35 | C12: 3.77 | D12: 6.87 | E12: 9.57 | F12: - | G12: =SQRT((4*(HSP!$B$2-$B12)^2+(HSP!$C$2-$C12)^2+(HSP!$D$2-$D12)^2)) -> 6.8569818 | H12: =SQRT((4*(HSP!$B$3-$B12)^2+(HSP!$C$3-$C12)^2+(HSP!$D$3-$D12)^2)) -> 6.0213786 | I12: =SQRT((4*(HSP!$B$4-$B12)^2+(HSP!$C$4-$C12)^2+(HSP!$D$4-$D12)^2)) -> 0.98112181 | J12: =SQRT((4*(HSP!$B$5-$B12)^2+(HSP!$C$5-$C12)^2+(HSP!$D$5-$D12)^2)) -> 9.8291251 | K12: =SQRT((4*(HSP!$B$6-$B12)^2+(HSP!$C$6-$C12)^2+(HSP!$D$6-$D12)^2)) -> 4.0276047 | L12: =$G12/$E12 -> 0.71650803 | M12: =$H12/$E12 -> 0.62919316 | N12: =$I12/$E12 -> 0.10252056 | O12: =$J12/$E12 -> 1.0270768 | P12: =$K12/$E12 -> 0.42085734 | Q12: =$G12/HSP!$E$2 -> 0.42067373 | R12: =$H12/HSP!$E$3 -> 0.44602804 | S12: =$I12/HSP!$E$4 -> 0.061705774 | T12: =$J12/HSP!$E$5 -> 0.71745439 | U12: =$K12/HSP!$E$6 -> 0.27213546

Sheet Fragrances
A1: FRAGRANCE | B1: HSP | E1: Ro | F1: Mvol | G1: DISTANCE TO | L1: RED TO (BASED ON Ro OF THE FRAGRANCE) | Q1: RED TO (BASED ON Ro OF NXTLEVVEL SOLVENT)
B2: D | C2: P | D2: H | G2: ETHYL LEVULINATE | H2: BUTYL LEVULINATE | I2: EtLPK | J2: EtLGK | K2: EHL | L2: ETHYL LEVULINATE | M2: BUTYL LEVULINATE | N2: EtLPK | O2: EtLGK | P2: EHL | Q2: ETHYL LEVULINATE | R2: BUTYL LEVULINATE | S2: EtLPK | T2: EtLGK | U2: EHL
A3: 1,13-Tridecanoic Acid, Diethyl Ester | B3: 16 | C3: 3.3 | D3: 7.6 | E3: - | F3: 317 | G3: =SQRT((4*(HSP!$B$2-$B3)^2+(HSP!$C$2-$C3)^2+(HSP!$D$2-$D3)^2)) -> 7.7129761 | H3: =SQRT((4*(HSP!$B$3-$B3)^2+(HSP!$C$3-$C3)^2+(HSP!$D$3-$D3)^2)) -> 6.6334305 | I3: =SQRT((4*(HSP!$B$4-$B3)^2+(HSP!$C$4-$C3)^2+(HSP!$D$4-$D3)^2)) -> 2.3021729 | J3: =SQRT((4*(HSP!$B$5-$B3)^2+(HSP!$C$5-$C3)^2+(HSP!$D$5-$D3)^2)) -> 10.097371 | K3: =SQRT((4*(HSP!$B$6-$B3)^2+(HSP!$C$6-$C3)^2+(HSP!$D$6-$D3)^2)) -> 5.0981369 | L3: - | M3: - | N3: - | O3: - | P3: - | Q3: =$G3/HSP!$E$2 -> 0.47318872 | R3: =$H3/HSP!$E$3 -> 0.49136522 | S3: =$I3/HSP!$E$4 -> 0.14479075 | T3: =$J3/HSP!$E$5 -> 0.73703438 | U3: =$K3/HSP!$E$6 -> 0.34446871
A4: 2,6-Dimethyl-5-Heptenal | B4: 15.7 | C4: 6.4 | D4: 4.7 | E4: - | F4: 224.7 | G4: =SQRT((4*(HSP!$B$2-$B4)^2+(HSP!$C$2-$C4)^2+(HSP!$D$2-$D4)^2)) -> 5.1499515 | H4: =SQRT((4*(HSP!$B$3-$B4)^2+(HSP!$C$3-$C4)^2+(HSP!$D$3-$D4)^2)) -> 3.4470857 | I4: =SQRT((4*(HSP!$B$4-$B4)^2+(HSP!$C$4-$C4)^2+(HSP!$D$4-$D4)^2)) -> 2.9141036 | J4: =SQRT((4*(HSP!$B$5-$B4)^2+(HSP!$C$5-$C4)^2+(HSP!$D$5-$D4)^2)) -> 8.9159913 | K4: =SQRT((4*(HSP!$B$6-$B4)^2+(HSP!$C$6-$C4)^2+(HSP!$D$6-$D4)^2)) -> 1.2095454 | L4: - | M4: - | N4: - | O4: - | P4: - | Q4: =$G4/HSP!$E$2 -> 0.31594794 | R4: =$H4/HSP!$E$3 -> 0.25533968 | S4: =$I4/HSP!$E$4 -> 0.18327696 | T4: =$J4/HSP!$E$5 -> 0.65080228 | U4: =$K4/HSP!$E$6 -> 0.081726038
A5: 2-Methoxy Naphthalene | B5: 19.2 | C5: 3.6 | D5: 5.9 | E5: - | F5: 145.1 | G5: =SQRT((4*(HSP!$B$2-$B5)^2+(HSP!$C$2-$C5)^2+(HSP!$D$2-$D5)^2)) -> 11.526751 | H5: =SQRT((4*(HSP!$B$3-$B5)^2+(HSP!$C$3-$C5)^2+(HSP!$D$3-$D5)^2)) -> 9.2741792 | I5: =SQRT((4*(HSP!$B$4-$B5)^2+(HSP!$C$4-$C5)^2+(HSP!$D$4-$D5)^2)) -> 8.1816869 | J5: =SQRT((4*(HSP!$B$5-$B5)^2+(HSP!$C$5-$C5)^2+(HSP!$D$5-$D5)^2)) -> 13.048176 | K5: =SQRT((4*(HSP!$B$6-$B5)^2+(HSP!$C$6-$C5)^2+(HSP!$D$6-$D5)^2)) -> 8.6018021 | L5: - | M5: - | N5: - | O5: - | P5: - | Q5: =$G5/HSP!$E$2 -> 0.70716267 | R5: =$H5/HSP!$E$3 -> 0.68697624 | S5: =$I5/HSP!$E$4 -> 0.5145715 | T5: =$J5/HSP!$E$5 -> 0.95242161 | U5: =$K5/HSP!$E$6 -> 0.58120285
A6: 3-Methyl-2-Butenyl Acetate | B6: 15.6 | C6: 4 | D6: 7 | E6: - | F6: 138.2 | G6: =SQRT((4*(HSP!$B$2-$B6)^2+(HSP!$C$2-$C6)^2+(HSP!$D$2-$D6)^2)) -> 6.7625439 | H6: =SQRT((4*(HSP!$B$3-$B6)^2+(HSP!$C$3-$C6)^2+(HSP!$D$3-$D6)^2)) -> 5.7844965 | I6: =SQRT((4*(HSP!$B$4-$B6)^2+(HSP!$C$4-$C6)^2+(HSP!$D$4-$D6)^2)) -> 1.1144505 | J6: =SQRT((4*(HSP!$B$5-$B6)^2+(HSP!$C$5-$C6)^2+(HSP!$D$5-$D6)^2)) -> 9.5874345 | K6: =SQRT((4*(HSP!$B$6-$B6)^2+(HSP!$C$6-$C6)^2+(HSP!$D$6-$D6)^2)) -> 4.032741 | L6: - | M6: - | N6: - | O6: - | P6: - | Q6: =$G6/HSP!$E$2 -> 0.41487999 | R6: =$H6/HSP!$E$3 -> 0.42848122 | S6: =$I6/HSP!$E$4 -> 0.070091229 | T6: =$J6/HSP!$E$5 -> 0.69981274 | U6: =$K6/HSP!$E$6 -> 0.2724825
A7: Acetic Acid Hexyl Ester | B7: 15.8 | C7: 2.9 | D7: 5.9 | E7: - | F7: 165 | G7: =SQRT((4*(HSP!$B$2-$B7)^2+(HSP!$C$2-$C7)^2+(HSP!$D$2-$D7)^2)) -> 8.0049984 | H7: =SQRT((4*(HSP!$B$3-$B7)^2+(HSP!$C$3-$C7)^2+(HSP!$D$3-$D7)^2)) -> 6.764052 | I7: =SQRT((4*(HSP!$B$4-$B7)^2+(HSP!$C$4-$C7)^2+(HSP!$D$4-$D7)^2)) -> 2.3592372 | J7: =SQRT((4*(HSP!$B$5-$B7)^2+(HSP!$C$5-$C7)^2+(HSP!$D$5-$D7)^2)) -> 11.084083 | K7: =SQRT((4*(HSP!$B$6-$B7)^2+(HSP!$C$6-$C7)^2+(HSP!$D$6-$D7)^2)) -> 4.2174637 | L7: - | M7: - | N7: - | O7: - | P7: - | Q7: =$G7/HSP!$E$2 -> 0.4911042 | R7: =$H7/HSP!$E$3 -> 0.50104089 | S7: =$I7/HSP!$E$4 -> 0.1483797 | T7: =$J7/HSP!$E$5 -> 0.80905717 | U7: =$K7/HSP!$E$6 -> 0.28496376
A8: Adoxal | B8: 16 | C8: 6 | D8: 4.5 | E8: - | F8: 256.1 | G8: =SQRT((4*(HSP!$B$2-$B8)^2+(HSP!$C$2-$C8)^2+(HSP!$D$2-$D8)^2)) -> 5.8208247 | H8: =SQRT((4*(HSP!$B$3-$B8)^2+(HSP!$C$3-$C8)^2+(HSP!$D$3-$D8)^2)) -> 3.9398477 | I8: =SQRT((4*(HSP!$B$4-$B8)^2+(HSP!$C$4-$C8)^2+(HSP!$D$4-$D8)^2)) -> 3.128578 | J8: =SQRT((4*(HSP!$B$5-$B8)^2+(HSP!$C$5-$C8)^2+(HSP!$D$5-$D8)^2)) -> 9.414611 | K8: =SQRT((4*(HSP!$B$6-$B8)^2+(HSP!$C$6-$C8)^2+(HSP!$D$6-$D8)^2)) -> 1.6549924 | L8: - | M8: - | N8: - | O8: - | P8: - | Q8: =$G8/HSP!$E$2 -> 0.35710581 | R8: =$H8/HSP!$E$3 -> 0.29184057 | S8: =$I8/HSP!$E$4 -> 0.19676591 | T8: =$J8/HSP!$E$5 -> 0.68719788 | U8: =$K8/HSP!$E$6 -> 0.11182381
A9: Aldehyde Mna | B9: 16 | C9: 6.8 | D9: 4.3 | E9: - | F9: 188.3 | G9: =SQRT((4*(HSP!$B$2-$B9)^2+(HSP!$C$2-$C9)^2+(HSP!$D$2-$D9)^2)) -> 5.3308536 | H9: =SQRT((4*(HSP!$B$3-$B9)^2+(HSP!$C$3-$C9)^2+(HSP!$D$3-$D9)^2)) -> 3.2976355 | I9: =SQRT((4*(HSP!$B$4-$B9)^2+(HSP!$C$4-$C9)^2+(HSP!$D$4-$D9)^2)) -> 3.6742346 | J9: =SQRT((4*(HSP!$B$5-$B9)^2+(HSP!$C$5-$C9)^2+(HSP!$D$5-$D9)^2)) -> 9.0074913 | K9: =SQRT((4*(HSP!$B$6-$B9)^2+(HSP!$C$6-$C9)^2+(HSP!$D$6-$D9)^2)) -> 1.5719415 | L9: - | M9: - | N9: - | O9: - | P9: - | Q9: =$G9/HSP!$E$2 -> 0.32704623 | R9: =$H9/HSP!$E$3 -> 0.2442693 | S9: =$I9/HSP!$E$4 -> 0.23108394 | T9: =$J9/HSP!$E$5 -> 0.65748112 | U9: =$K9/HSP!$E$6 -> 0.10621226
A10: Allo-Ocimene | B10: 15.6 | C10: 1.2 | D10: 5.2 | E10: - | F10: 170.3 | G10: =SQRT((4*(HSP!$B$2-$B10)^2+(HSP!$C$2-$C10)^2+(HSP!$D$2-$D10)^2)) -> 9.6392946 | H10: =SQRT((4*(HSP!$B$3-$B10)^2+(HSP!$C$3-$C10)^2+(HSP!$D$3-$D10)^2)) -> 8.4845978 | I10: =SQRT((4*(HSP!$B$4-$B10)^2+(HSP!$C$4-$C10)^2+(HSP!$D$4-$D10)^2)) -> 3.9255573 | J10: =SQRT((4*(HSP!$B$5-$B10)^2+(HSP!$C$5-$C10)^2+(HSP!$D$5-$D10)^2)) -> 12.88328 | K10: =SQRT((4*(HSP!$B$6-$B10)^2+(HSP!$C$6-$C10)^2+(HSP!$D$6-$D10)^2)) -> 5.441599 | L10: - | M10: - | N10: - | O10: - | P10: - | Q10: =$G10/HSP!$E$2 -> 0.59136777 | R10: =$H10/HSP!$E$3 -> 0.62848873 | S10: =$I10/HSP!$E$4 -> 0.2468904 | T10: =$J10/HSP!$E$5 -> 0.94038539 | U10: =$K10/HSP!$E$6 -> 0.36767561
A11: Allyl Amyl Glycolate | B11: 16 | C11: 4.4 | D11: 6.8 | E11: - | F11: 186 | G11: =SQRT((4*(HSP!$B$2-$B11)^2+(HSP!$C$2-$C11)^2+(HSP!$D$2-$D11)^2)) -> 6.6780237 | H11: =SQRT((4*(HSP!$B$3-$B11)^2+(HSP!$C$3-$C11)^2+(HSP!$D$3-$D11)^2)) -> 5.386316 | I11: =SQRT((4*(HSP!$B$4-$B11)^2+(HSP!$C$4-$C11)^2+(HSP!$D$4-$D11)^2)) -> 1.6834488 | J11: =SQRT((4*(HSP!$B$5-$B11)^2+(HSP!$C$5-$C11)^2+(HSP!$D$5-$D11)^2)) -> 9.4027071 | K11: =SQRT((4*(HSP!$B$6-$B11)^2+(HSP!$C$6-$C11)^2+(HSP!$D$6-$D11)^2)) -> 3.8671695 | L11: - | M11: - | N11: - | O11: - | P11: - | Q11: =$G11/HSP!$E$2 -> 0.4096947 | R11: =$H11/HSP!$E$3 -> 0.39898637 | S11: =$I11/HSP!$E$4 -> 0.10587729 | T11: =$J11/HSP!$E$5 -> 0.68632898 | U11: =$K11/HSP!$E$6 -> 0.26129524
A12: Allyl Caproate | B12: 16 | C12: 2.4 | D12: 5.3 | E12: - | F12: 241.5 | G12: =SQRT((4*(HSP!$B$2-$B12)^2+(HSP!$C$2-$C12)^2+(HSP!$D$2-$D12)^2)) -> 8.6963211 | H12: =SQRT((4*(HSP!$B$3-$B12)^2+(HSP!$C$3-$C12)^2+(HSP!$D$3-$D12)^2)) -> 7.3049572 | I12: =SQRT((4*(HSP!$B$4-$B12)^2+(HSP!$C$4-$C12)^2+(HSP!$D$4-$D12)^2)) -> 3.19437 | J12: =SQRT((4*(HSP!$B$5-$B12)^2+(HSP!$C$5-$C12)^2+(HSP!$D$5-$D12)^2)) -> 11.846134 | K12: =SQRT((4*(HSP!$B$6-$B12)^2+(HSP!$C$6-$C12)^2+(HSP!$D$6-$D12)^2)) -> 4.5249309 | L12: - | M12: - | N12: - | O12: - | P12: - | Q12: =$G12/HSP!$E$2 -> 0.53351663 | R12: =$H12/HSP!$E$3 -> 0.54110794 | S12: =$I12/HSP!$E$4 -> 0.20090378 | T12: =$J12/HSP!$E$5 -> 0.86468134 | U12: =$K12/HSP!$E$6 -> 0.30573858
A13: Allyl Cyclohexane Propionate | B13: 17 | C13: 2.6 | D13: 5.6 | E13: - | F13: 213 | G13: =SQRT((4*(HSP!$B$2-$B13)^2+(HSP!$C$2-$C13)^2+(HSP!$D$2-$D13)^2)) -> 9.3125721 | H13: =SQRT((4*(HSP!$B$3-$B13)^2+(HSP!$C$3-$C13)^2+(HSP!$D$3-$D13)^2)) -> 7.5336844 | I13: =SQRT((4*(HSP!$B$4-$B13)^2+(HSP!$C$4-$C13)^2+(HSP!$D$4-$D13)^2)) -> 4.3774422 | J13: =SQRT((4*(HSP!$B$5-$B13)^2+(HSP!$C$5-$C13)^2+(HSP!$D$5-$D13)^2)) -> 11.949682 | K13: =SQRT((4*(HSP!$B$6-$B13)^2+(HSP!$C$6-$C13)^2+(HSP!$D$6-$D13)^2)) -> 5.4500459 | L13: - | M13: - | N13: - | O13: - | P13: - | Q13: =$G13/HSP!$E$2 -> 0.57132344 | R13: =$H13/HSP!$E$3 -> 0.55805069 | S13: =$I13/HSP!$E$4 -> 0.27531083 | T13: =$J13/HSP!$E$5 -> 0.87223956 | U13: =$K13/HSP!$E$6 -> 0.36824634
A14: Allyl Heptanoate | B14: 16 | C14: 2.7 | D14: 5.9 | E14: - | F14: 192 | G14: =SQRT((4*(HSP!$B$2-$B14)^2+(HSP!$C$2-$C14)^2+(HSP!$D$2-$D14)^2)) -> 8.3200962 | H14: =SQRT((4*(HSP!$B$3-$B14)^2+(HSP!$C$3-$C14)^2+(HSP!$D$3-$D14)^2)) -> 6.9880183 | I14: =SQRT((4*(HSP!$B$4-$B14)^2+(HSP!$C$4-$C14)^2+(HSP!$D$4-$D14)^2)) -> 2.7360556 | J14: =SQRT((4*(HSP!$B$5-$B14)^2+(HSP!$C$5-$C14)^2+(HSP!$D$5-$D14)^2)) -> 11.306321 | K14: =SQRT((4*(HSP!$B$6-$B14)^2+(HSP!$C$6-$C14)^2+(HSP!$D$6-$D14)^2)) -> 4.4996667 | L14: - | M14: - | N14: - | O14: - | P14: - | Q14: =$G14/HSP!$E$2 -> 0.51043535 | R14: =$H14/HSP!$E$3 -> 0.51763099 | S14: =$I14/HSP!$E$4 -> 0.17207897 | T14: =$J14/HSP!$E$5 -> 0.82527892 | U14: =$K14/HSP!$E$6 -> 0.30403153
... A286: γ-Undecalactone | B286: 17.4 | C286: 10.2 | D286: 4.5 | E286: - | F286: 204.8 | G286: =SQRT((4*(HSP!$B$2-$B286)^2+(HSP!$C$2-$C286)^2+(HSP!$D$2-$D286)^2)) -> 6.1300897 | H286: =SQRT((4*(HSP!$B$3-$B286)^2+(HSP!$C$3-$C286)^2+(HSP!$D$3-$D286)^2)) -> 3.7054554 | I286: =SQRT((4*(HSP!$B$4-$B286)^2+(HSP!$C$4-$C286)^2+(HSP!$D$4-$D286)^2)) -> 7.4600268 | J286: =SQRT((4*(HSP!$B$5-$B286)^2+(HSP!$C$5-$C286)^2+(HSP!$D$5-$D286)^2)) -> 8.1143638 | K286: =SQRT((4*(HSP!$B$6-$B286)^2+(HSP!$C$6-$C286)^2+(HSP!$D$6-$D286)^2)) -> 5.7256441 | L286: - | M286: - | N286: - | O286: - | P286: - | Q286: =$G286/HSP!$E$2 -> 0.37607912 | R286: =$H286/HSP!$E$3 -> 0.27447818 | S286: =$I286/HSP!$E$4 -> 0.46918408 | T286: =$J286/HSP!$E$5 -> 0.59228933 | U286: =$K286/HSP!$E$6 -> 0.38686784

Sheet Particles
A1: PARTICLE | B1: HSP | E1: Ro | F1: DISTANCE TO | K1: RED TO (BASED ON Ro OF THE PARTICLE) | P1: RED TO (BASED ON Ro OF NXTLEVVEL SOLVENT)
B2: D | C2: P | D2: H | F2: ETHYL LEVULINATE | G2: BUTYL LEVULINATE | H2: EtLPK | I2: EtLGK | J2: EHL | K2: ETHYL LEVULINATE | L2: BUTYL LEVULINATE | M2: EtLPK | N2: EtLGK | O2: EHL | P2: ETHYL LEVULINATE | Q2: BUTYL LEVULINATE | R2: EtLPK | S2: EtLGK | T2: EHL
A3: Al2O3 | B3: 17.5 | C3: 11.3 | D3: 10.6 | E3: - | F3: =SQRT((4*(HSP!$B$2-$B3)^2+(HSP!$C$2-$C3)^2+(HSP!$D$2-$D3)^2)) -> 6.888396 | G3: =SQRT((4*(HSP!$B$3-$B3)^2+(HSP!$C$3-$C3)^2+(HSP!$D$3-$D3)^2)) -> 6.2163012 | H3: =SQRT((4*(HSP!$B$4-$B3)^2+(HSP!$C$4-$C3)^2+(HSP!$D$4-$D3)^2)) -> 8.9431538 | I3: =SQRT((4*(HSP!$B$5-$B3)^2+(HSP!$C$5-$C3)^2+(HSP!$D$5-$D3)^2)) -> 4.692217 | J3: =SQRT((4*(HSP!$B$6-$B3)^2+(HSP!$C$6-$C3)^2+(HSP!$D$6-$D3)^2)) -> 9.4430398 | K3: - | L3: - | M3: - | N3: - | O3: - | P3: =$F3/HSP!$E$2 -> 0.42260098 | Q3: =$G3/HSP!$E$3 -> 0.46046675 | R3: =$H3/HSP!$E$4 -> 0.5624625 | S3: =$I3/HSP!$E$5 -> 0.34249759 | T3: =$J3/HSP!$E$6 -> 0.63804323
A4: C60 | B4: 19.7 | C4: 2.9 | D4: 2.7 | E4: - | F4: =SQRT((4*(HSP!$B$2-$B4)^2+(HSP!$C$2-$C4)^2+(HSP!$D$2-$D4)^2)) -> 13.398209 | G4: =SQRT((4*(HSP!$B$3-$B4)^2+(HSP!$C$3-$C4)^2+(HSP!$D$3-$D4)^2)) -> 10.943144 | H4: =SQRT((4*(HSP!$B$4-$B4)^2+(HSP!$C$4-$C4)^2+(HSP!$D$4-$D4)^2)) -> 10.102574 | I4: =SQRT((4*(HSP!$B$5-$B4)^2+(HSP!$C$5-$C4)^2+(HSP!$D$5-$D4)^2)) -> 15.577705 | J4: =SQRT((4*(HSP!$B$6-$B4)^2+(HSP!$C$6-$C4)^2+(HSP!$D$6-$D4)^2)) -> 9.6064041 | K4: - | L4: - | M4: - | N4: - | O4: - | P4: =$F4/HSP!$E$2 -> 0.821976 | Q4: =$G4/HSP!$E$3 -> 0.81060326 | R4: =$H4/HSP!$E$4 -> 0.63538201 | S4: =$I4/HSP!$E$5 -> 1.1370588 | T4: =$J4/HSP!$E$6 -> 0.64908136
A5: Carbon Black - High Hydrophilicity | B5: 20 | C5: 11 | D5: 12 | E5: - | F5: =SQRT((4*(HSP!$B$2-$B5)^2+(HSP!$C$2-$C5)^2+(HSP!$D$2-$D5)^2)) -> 11.921913 | G5: =SQRT((4*(HSP!$B$3-$B5)^2+(HSP!$C$3-$C5)^2+(HSP!$D$3-$D5)^2)) -> 10.690762 | H5: =SQRT((4*(HSP!$B$4-$B5)^2+(HSP!$C$4-$C5)^2+(HSP!$D$4-$D5)^2)) -> 12.660885 | I5: =SQRT((4*(HSP!$B$5-$B5)^2+(HSP!$C$5-$C5)^2+(HSP!$D$5-$D5)^2)) -> 9.6744457 | J5: =SQRT((4*(HSP!$B$6-$B5)^2+(HSP!$C$6-$C5)^2+(HSP!$D$6-$D5)^2)) -> 13.296579 | K5: - | L5: - | M5: - | N5: - | O5: - | P5: =$F5/HSP!$E$2 -> 0.73140568 | Q5: =$G5/HSP!$E$3 -> 0.79190832 | R5: =$H5/HSP!$E$4 -> 0.79628205 | S5: =$I5/HSP!$E$5 -> 0.70616392 | T5: =$J5/HSP!$E$6 -> 0.89841747
A6: Carbon Black - Low Hydrophilicity | B6: 16 | C6: 10 | D6: 7 | E6: - | F6: =SQRT((4*(HSP!$B$2-$B6)^2+(HSP!$C$2-$C6)^2+(HSP!$D$2-$D6)^2)) -> 2.8376046 | G6: =SQRT((4*(HSP!$B$3-$B6)^2+(HSP!$C$3-$C6)^2+(HSP!$D$3-$D6)^2)) -> 1.3756453 | H6: =SQRT((4*(HSP!$B$4-$B6)^2+(HSP!$C$4-$C6)^2+(HSP!$D$4-$D6)^2)) -> 5.5765581 | I6: =SQRT((4*(HSP!$B$5-$B6)^2+(HSP!$C$5-$C6)^2+(HSP!$D$5-$D6)^2)) -> 4.9974894 | J6: =SQRT((4*(HSP!$B$6-$B6)^2+(HSP!$C$6-$C6)^2+(HSP!$D$6-$D6)^2)) -> 4.9798594 | K6: - | L6: - | M6: - | N6: - | O6: - | P6: =$F6/HSP!$E$2 -> 0.17408617 | Q6: =$G6/HSP!$E$3 -> 0.10189965 | R6: =$H6/HSP!$E$4 -> 0.35072692 | S6: =$I6/HSP!$E$5 -> 0.36478025 | T6: =$J6/HSP!$E$6 -> 0.33647699
A7: Carbon Fibre (Hansen solubility parameters for a carbon fiber/epoxy composite, 2007) | B7: 21.3 | C7: 8.7 | D7: 11.5 | E7: - | F7: =SQRT((4*(HSP!$B$2-$B7)^2+(HSP!$C$2-$C7)^2+(HSP!$D$2-$D7)^2)) -> 14.250895 | G7: =SQRT((4*(HSP!$B$3-$B7)^2+(HSP!$C$3-$C7)^2+(HSP!$D$3-$D7)^2)) -> 12.612391 | H7: =SQRT((4*(HSP!$B$4-$B7)^2+(HSP!$C$4-$C7)^2+(HSP!$D$4-$D7)^2)) -> 13.731642 | I7: =SQRT((4*(HSP!$B$5-$B7)^2+(HSP!$C$5-$C7)^2+(HSP!$D$5-$D7)^2)) -> 12.725129 | J7: =SQRT((4*(HSP!$B$6-$B7)^2+(HSP!$C$6-$C7)^2+(HSP!$D$6-$D7)^2)) -> 14.460947 | K7: - | L7: - | M7: - | N7: - | O7: - | P7: =$F7/HSP!$E$2 -> 0.87428802 | Q7: =$G7/HSP!$E$3 -> 0.93425117 | R7: =$H7/HSP!$E$4 -> 0.8636253 | S7: =$I7/HSP!$E$5 -> 0.92884151 | T7: =$J7/HSP!$E$6 -> 0.97709104
A8: Carbon Nano Tubes | B8: 19 | C8: 8 | D8: 4 | E8: - | F8: =SQRT((4*(HSP!$B$2-$B8)^2+(HSP!$C$2-$C8)^2+(HSP!$D$2-$D8)^2)) -> 9.6110353 | G8: =SQRT((4*(HSP!$B$3-$B8)^2+(HSP!$C$3-$C8)^2+(HSP!$D$3-$D8)^2)) -> 7.0634552 | H8: =SQRT((4*(HSP!$B$4-$B8)^2+(HSP!$C$4-$C8)^2+(HSP!$D$4-$D8)^2)) -> 8.8055664 | I8: =SQRT((4*(HSP!$B$5-$B8)^2+(HSP!$C$5-$C8)^2+(HSP!$D$5-$D8)^2)) -> 11.222963 | J8: =SQRT((4*(HSP!$B$6-$B8)^2+(HSP!$C$6-$C8)^2+(HSP!$D$6-$D8)^2)) -> 7.6248934 | K8: - | L8: - | M8: - | N8: - | O8: - | P8: =$F8/HSP!$E$2 -> 0.58963407 | Q8: =$G8/HSP!$E$3 -> 0.52321891 | R8: =$H8/HSP!$E$4 -> 0.55380921 | S8: =$I8/HSP!$E$5 -> 0.81919438 | T8: =$J8/HSP!$E$6 -> 0.5151955
A9: Fin Talc M15* | B9: 17.89 | C9: 8.29 | D9: 10.34 | E9: - | F9: =SQRT((4*(HSP!$B$2-$B9)^2+(HSP!$C$2-$C9)^2+(HSP!$D$2-$D9)^2)) -> 7.7003182 | G9: =SQRT((4*(HSP!$B$3-$B9)^2+(HSP!$C$3-$C9)^2+(HSP!$D$3-$D9)^2)) -> 6.4550213 | H9: =SQRT((4*(HSP!$B$4-$B9)^2+(HSP!$C$4-$C9)^2+(HSP!$D$4-$D9)^2)) -> 7.4267961 | I9: =SQRT((4*(HSP!$B$5-$B9)^2+(HSP!$C$5-$C9)^2+(HSP!$D$5-$D9)^2)) -> 6.8869877 | J9: =SQRT((4*(HSP!$B$6-$B9)^2+(HSP!$C$6-$C9)^2+(HSP!$D$6-$D9)^2)) -> 8.5461863 | K9: - | L9: - | M9: - | N9: - | O9: - | P9: =$F9/HSP!$E$2 -> 0.47241216 | Q9: =$G9/HSP!$E$3 -> 0.47814973 | R9: =$H9/HSP!$E$4 -> 0.46709409 | S9: =$I9/HSP!$E$5 -> 0.50269983 | T9: =$J9/HSP!$E$6 -> 0.57744502
A10: Fumed Silica | B10: 18 | C10: 27.5 | D10: 29 | E10: - | F10: =SQRT((4*(HSP!$B$2-$B10)^2+(HSP!$C$2-$C10)^2+(HSP!$D$2-$D10)^2)) -> 28.661507 | G10: =SQRT((4*(HSP!$B$3-$B10)^2+(HSP!$C$3-$C10)^2+(HSP!$D$3-$D10)^2)) -> 29.612876 | H10: =SQRT((4*(HSP!$B$4-$B10)^2+(HSP!$C$4-$C10)^2+(HSP!$D$4-$D10)^2)) -> 32.336172 | I10: =SQRT((4*(HSP!$B$5-$B10)^2+(HSP!$C$5-$C10)^2+(HSP!$D$5-$D10)^2)) -> 23.974672 | J10: =SQRT((4*(HSP!$B$6-$B10)^2+(HSP!$C$6-$C10)^2+(HSP!$D$6-$D10)^2)) -> 33.260773 | K10: - | L10: - | M10: - | N10: - | O10: - | P10: =$F10/HSP!$E$2 -> 1.7583747 | Q10: =$G10/HSP!$E$3 -> 2.1935463 | R10: =$H10/HSP!$E$4 -> 2.0337215 | S10: =$I10/HSP!$E$5 -> 1.7499761 | T10: =$J10/HSP!$E$6 -> 2.2473495
A11: Glassy Carbon (Hansen solubility parameters for a carbon fiber/epoxy composite, 2007) | B11: 20 | C11: 10 | D11: 10 | E11: - | F11: =SQRT((4*(HSP!$B$2-$B11)^2+(HSP!$C$2-$C11)^2+(HSP!$D$2-$D11)^2)) -> 11.223725 | G11: =SQRT((4*(HSP!$B$3-$B11)^2+(HSP!$C$3-$C11)^2+(HSP!$D$3-$D11)^2)) -> 9.5860524 | H11: =SQRT((4*(HSP!$B$4-$B11)^2+(HSP!$C$4-$C11)^2+(HSP!$D$4-$D11)^2)) -> 11.482944 | I11: =SQRT((4*(HSP!$B$5-$B11)^2+(HSP!$C$5-$C11)^2+(HSP!$D$5-$D11)^2)) -> 9.8871078 | J11: =SQRT((4*(HSP!$B$6-$B11)^2+(HSP!$C$6-$C11)^2+(HSP!$D$6-$D11)^2)) -> 11.834653 | K11: - | L11: - | M11: - | N11: - | O11: - | P11: =$F11/HSP!$E$2 -> 0.68857208 | Q11: =$G11/HSP!$E$3 -> 0.71007795 | R11: =$H11/HSP!$E$4 -> 0.72219773 | S11: =$I11/HSP!$E$5 -> 0.7216867 | T11: =$J11/HSP!$E$6 -> 0.79963868
A12: Hydroxyapatite | B12: 17.6 | C12: 14 | D12: 9.4 | E12: - | F12: =SQRT((4*(HSP!$B$2-$B12)^2+(HSP!$C$2-$C12)^2+(HSP!$D$2-$D12)^2)) -> 7.374822 | G12: =SQRT((4*(HSP!$B$3-$B12)^2+(HSP!$C$3-$C12)^2+(HSP!$D$3-$D12)^2)) -> 6.8003235 | H12: =SQRT((4*(HSP!$B$4-$B12)^2+(HSP!$C$4-$C12)^2+(HSP!$D$4-$D12)^2)) -> 10.827835 | I12: =SQRT((4*(HSP!$B$5-$B12)^2+(HSP!$C$5-$C12)^2+(HSP!$D$5-$D12)^2)) -> 5.0690137 | J12: =SQRT((4*(HSP!$B$6-$B12)^2+(HSP!$C$6-$C12)^2+(HSP!$D$6-$D12)^2)) -> 10.479647 | K12: - | L12: - | M12: - | N12: - | O12: - | P12: =$F12/HSP!$E$2 -> 0.45244307 | Q12: =$G12/HSP!$E$3 -> 0.50372767 | R12: =$H12/HSP!$E$4 -> 0.68099588 | S12: =$I12/HSP!$E$5 -> 0.370001 | T12: =$J12/HSP!$E$6 -> 0.70808425
A13: TiO2 | B13: 17.5 | C13: 12.7 | D13: 8.9 | E13: - | F13: =SQRT((4*(HSP!$B$2-$B13)^2+(HSP!$C$2-$C13)^2+(HSP!$D$2-$D13)^2)) -> 6.5072268 | G13: =SQRT((4*(HSP!$B$3-$B13)^2+(HSP!$C$3-$C13)^2+(HSP!$D$3-$D13)^2)) -> 5.6420209 | H13: =SQRT((4*(HSP!$B$4-$B13)^2+(HSP!$C$4-$C13)^2+(HSP!$D$4-$D13)^2)) -> 9.5103102 | I13: =SQRT((4*(HSP!$B$5-$B13)^2+(HSP!$C$5-$C13)^2+(HSP!$D$5-$D13)^2)) -> 4.9002959 | J13: =SQRT((4*(HSP!$B$6-$B13)^2+(HSP!$C$6-$C13)^2+(HSP!$D$6-$D13)^2)) -> 9.2036406 | K13: - | L13: - | M13: - | N13: - | O13: - | P13: =$F13/HSP!$E$2 -> 0.39921637 | Q13: =$G13/HSP!$E$3 -> 0.41792748 | R13: =$H13/HSP!$E$4 -> 0.59813272 | S13: =$I13/HSP!$E$5 -> 0.35768583 | T13: =$J13/HSP!$E$6 -> 0.62186761
A14: TiO2 (Pirika) | B14: 23.6 | C14: 14.6 | D14: 19 | E14: - | F14: =SQRT((4*(HSP!$B$2-$B14)^2+(HSP!$C$2-$C14)^2+(HSP!$D$2-$D14)^2)) -> 22.036787 | G14: =SQRT((4*(HSP!$B$3-$B14)^2+(HSP!$C$3-$C14)^2+(HSP!$D$3-$D14)^2)) -> 21.175184 | H14: =SQRT((4*(HSP!$B$4-$B14)^2+(HSP!$C$4-$C14)^2+(HSP!$D$4-$D14)^2)) -> 23.054414 | I14: =SQRT((4*(HSP!$B$5-$B14)^2+(HSP!$C$5-$C14)^2+(HSP!$D$5-$D14)^2)) -> 18.606851 | J14: =SQRT((4*(HSP!$B$6-$B14)^2+(HSP!$C$6-$C14)^2+(HSP!$D$6-$D14)^2)) -> 23.954686 | K14: - | L14: - | M14: - | N14: - | O14: - | P14: =$F14/HSP!$E$2 -> 1.3519501 | Q14: =$G14/HSP!$E$3 -> 1.5685321 | R14: =$H14/HSP!$E$4 -> 1.4499631 | S14: =$I14/HSP!$E$5 -> 1.3581643 | T14: =$J14/HSP!$E$6 -> 1.6185599
... A16: ZrO2 | B16: 19.1 | C16: 11.4 | D16: 8.7 | E16: - | F16: =SQRT((4*(HSP!$B$2-$B16)^2+(HSP!$C$2-$C16)^2+(HSP!$D$2-$D16)^2)) -> 9.2109717 | G16: =SQRT((4*(HSP!$B$3-$B16)^2+(HSP!$C$3-$C16)^2+(HSP!$D$3-$D16)^2)) -> 7.6048932 | H16: =SQRT((4*(HSP!$B$4-$B16)^2+(HSP!$C$4-$C16)^2+(HSP!$D$4-$D16)^2)) -> 10.514181 | I16: =SQRT((4*(HSP!$B$5-$B16)^2+(HSP!$C$5-$C16)^2+(HSP!$D$5-$D16)^2)) -> 8.086464 | J16: =SQRT((4*(HSP!$B$6-$B16)^2+(HSP!$C$6-$C16)^2+(HSP!$D$6-$D16)^2)) -> 10.339197 | K16: - | L16: - | M16: - | N16: - | O16: - | P16: =$F16/HSP!$E$2 -> 0.56509029 | Q16: =$G16/HSP!$E$3 -> 0.56332542 | R16: =$H16/HSP!$E$4 -> 0.66126924 | S16: =$I16/HSP!$E$5 -> 0.59025285 | T16: =$J16/HSP!$E$6 -> 0.69859441
A18: *VLCI

Sheet Polymers
A1: POLYMER | B1: HSP | E1: Ro | F1: DISTANCE TO | K1: RED TO (BASED ON Ro OF THE POLYMER) | P1: RED TO (BASED ON Ro OF NXTLEVVEL SOLVENT) | U1: BASIC DESCRIPTION
B2: D | C2: P | D2: H | F2: ETHYL LEVULINATE | G2: BUTYL LEVULINATE | H2: EtLPK | I2: EtLGK | J2: EHL | K2: ETHYL LEVULINATE | L2: BUTYL LEVULINATE | M2: EtLPK | N2: EtLGK | O2: EHL | P2: ETHYL LEVULINATE | Q2: BUTYL LEVULINATE | R2: EtLPK | S2: EtLGK | T2: EHL
A3: (Lucite) 2042 PEMA | B3: 17.6 | C3: 9.66 | D3: 3.97 | E3: 10.64 | F3: =SQRT((4*(HSP!$B$2-$B3)^2+(HSP!$C$2-$C3)^2+(HSP!$D$2-$D3)^2)) -> 6.7601849 | G3: =SQRT((4*(HSP!$B$3-$B3)^2+(HSP!$C$3-$C3)^2+(HSP!$D$3-$D3)^2)) -> 4.2443963 | H3: =SQRT((4*(HSP!$B$4-$B3)^2+(HSP!$C$4-$C3)^2+(HSP!$D$4-$D3)^2)) -> 7.5119172 | I3: =SQRT((4*(HSP!$B$5-$B3)^2+(HSP!$C$5-$C3)^2+(HSP!$D$5-$D3)^2)) -> 8.9174436 | J3: =SQRT((4*(HSP!$B$6-$B3)^2+(HSP!$C$6-$C3)^2+(HSP!$D$6-$D3)^2)) -> 5.6712344 | K3: =$F3/$E3 -> 0.63535572 | L3: =$G3/$E3 -> 0.39890943 | M3: =$H3/$E3 -> 0.70600726 | N3: =$I3/$E3 -> 0.8381056 | O3: =$J3/$E3 -> 0.53301076 | P3: =$F3/HSP!$E$2 -> 0.41473527 | Q3: =$G3/HSP!$E$3 -> 0.31439973 | R3: =$H3/HSP!$E$4 -> 0.47244762 | S3: =$I3/HSP!$E$5 -> 0.65090829 | T3: =$J3/HSP!$E$6 -> 0.38319152 | U3: Polyacrylate
A4: 1% in Water +Amines | B4: 14.96 | C4: 18.33 | D4: 15.15 | E4: 16.22 | F4: =SQRT((4*(HSP!$B$2-$B4)^2+(HSP!$C$2-$C4)^2+(HSP!$D$2-$D4)^2)) -> 11.366803 | G4: =SQRT((4*(HSP!$B$3-$B4)^2+(HSP!$C$3-$C4)^2+(HSP!$D$3-$D4)^2)) -> 12.819883 | H4: =SQRT((4*(HSP!$B$4-$B4)^2+(HSP!$C$4-$C4)^2+(HSP!$D$4-$D4)^2)) -> 16.006917 | I4: =SQRT((4*(HSP!$B$5-$B4)^2+(HSP!$C$5-$C4)^2+(HSP!$D$5-$D4)^2)) -> 7.0473328 | J4: =SQRT((4*(HSP!$B$6-$B4)^2+(HSP!$C$6-$C4)^2+(HSP!$D$6-$D4)^2)) -> 16.422071 | K4: =$F4/$E4 -> 0.70078931 | L4: =$G4/$E4 -> 0.79037503 | M4: =$H4/$E4 -> 0.98686296 | N4: =$I4/$E4 -> 0.43448414 | O4: =$J4/$E4 -> 1.0124581 | P4: =$F4/HSP!$E$2 -> 0.69734985 | Q4: =$G4/HSP!$E$3 -> 0.94962096 | R4: =$H4/HSP!$E$4 -> 1.0067244 | S4: =$I4/HSP!$E$5 -> 0.51440386 | T4: =$J4/HSP!$E$6 -> 1.1095994 | U4: Biologically interesting systems
A5: 1% in Water -Amines | B5: 15.07 | C5: 20.44 | D5: 16.5 | E5: 18.12 | F5: =SQRT((4*(HSP!$B$2-$B5)^2+(HSP!$C$2-$C5)^2+(HSP!$D$2-$D5)^2)) -> 13.824413 | G5: =SQRT((4*(HSP!$B$3-$B5)^2+(HSP!$C$3-$C5)^2+(HSP!$D$3-$D5)^2)) -> 15.225255 | H5: =SQRT((4*(HSP!$B$4-$B5)^2+(HSP!$C$4-$C5)^2+(HSP!$D$4-$D5)^2)) -> 18.506961 | I5: =SQRT((4*(HSP!$B$5-$B5)^2+(HSP!$C$5-$C5)^2+(HSP!$D$5-$D5)^2)) -> 9.5280271 | J5: =SQRT((4*(HSP!$B$6-$B5)^2+(HSP!$C$6-$C5)^2+(HSP!$D$6-$D5)^2)) -> 18.880217 | K5: =$F5/$E5 -> 0.76293671 | L5: =$G5/$E5 -> 0.84024588 | M5: =$H5/$E5 -> 1.0213555 | N5: =$I5/$E5 -> 0.52582931 | O5: =$J5/$E5 -> 1.0419546 | P5: =$F5/HSP!$E$2 -> 0.84812351 | Q5: =$G5/HSP!$E$3 -> 1.1277967 | R5: =$H5/HSP!$E$4 -> 1.1639598 | S5: =$I5/HSP!$E$5 -> 0.69547643 | T5: =$J5/HSP!$E$6 -> 1.2756903 | U5: Biologically interesting systems
